[2024-06-27T02:31:05.813+0000] {taskinstance.py:1042} DEBUG - previous_execution_date was called
[2024-06-27T02:31:05.845+0000] {taskinstance.py:1042} DEBUG - previous_execution_date was called
[2024-06-27T02:31:05.860+0000] {local_task_job_runner.py:120} INFO - ::group::Pre task execution logs
[2024-06-27T02:31:05.887+0000] {taskinstance.py:2076} INFO - Dependencies all met for dep_context=non-requeueable deps ti=<TaskInstance: test_us.get_urls_task manual__2024-06-27T02:31:04.617297+00:00 [queued]>
[2024-06-27T02:31:05.900+0000] {taskinstance.py:2076} INFO - Dependencies all met for dep_context=requeueable deps ti=<TaskInstance: test_us.get_urls_task manual__2024-06-27T02:31:04.617297+00:00 [queued]>
[2024-06-27T02:31:05.901+0000] {taskinstance.py:2306} INFO - Starting attempt 1 of 1
[2024-06-27T02:31:05.919+0000] {taskinstance.py:2330} INFO - Executing <Task(PythonOperator): get_urls_task> on 2024-06-27 02:31:04.617297+00:00
[2024-06-27T02:31:05.926+0000] {warnings.py:112} WARNING - /home/***/.local/lib/python3.12/site-packages/***/task/task_runner/standard_task_runner.py:61: DeprecationWarning: This process (pid=1600) is multi-threaded, use of fork() may lead to deadlocks in the child.
  pid = os.fork()

[2024-06-27T02:31:05.928+0000] {standard_task_runner.py:63} INFO - Started process 1601 to run task
[2024-06-27T02:31:05.928+0000] {standard_task_runner.py:90} INFO - Running: ['***', 'tasks', 'run', 'test_us', 'get_urls_task', 'manual__2024-06-27T02:31:04.617297+00:00', '--job-id', '564', '--raw', '--subdir', 'DAGS_FOLDER/first_out.py', '--cfg-path', '/tmp/tmps2jyvmvc']
[2024-06-27T02:31:05.931+0000] {standard_task_runner.py:91} INFO - Job 564: Subtask get_urls_task
[2024-06-27T02:31:05.982+0000] {taskinstance.py:1042} DEBUG - previous_execution_date was called
[2024-06-27T02:31:05.990+0000] {task_command.py:426} INFO - Running <TaskInstance: test_us.get_urls_task manual__2024-06-27T02:31:04.617297+00:00 [running]> on host ccfa35e0da07
[2024-06-27T02:31:05.991+0000] {settings.py:363} DEBUG - Disposing DB connection pool (PID 1601)
[2024-06-27T02:31:05.992+0000] {settings.py:250} DEBUG - Setting up DB connection pool (PID 1601)
[2024-06-27T02:31:05.993+0000] {settings.py:298} DEBUG - settings.prepare_engine_args(): Using NullPool
[2024-06-27T02:31:06.040+0000] {taskinstance.py:1042} DEBUG - previous_execution_date was called
[2024-06-27T02:31:06.101+0000] {taskinstance.py:2648} INFO - Exporting env vars: AIRFLOW_CTX_DAG_OWNER='***' AIRFLOW_CTX_DAG_ID='test_us' AIRFLOW_CTX_TASK_ID='get_urls_task' AIRFLOW_CTX_EXECUTION_DATE='2024-06-27T02:31:04.617297+00:00' AIRFLOW_CTX_TRY_NUMBER='1' AIRFLOW_CTX_DAG_RUN_ID='manual__2024-06-27T02:31:04.617297+00:00'
[2024-06-27T02:31:06.103+0000] {taskinstance.py:430} INFO - ::endgroup::
[2024-06-27T02:31:09.239+0000] {taskinstance.py:441} INFO - ::group::Post task execution logs
[2024-06-27T02:31:09.240+0000] {taskinstance.py:2905} ERROR - Task failed with exception
Traceback (most recent call last):
  File "/home/airflow/.local/lib/python3.12/site-packages/airflow/models/taskinstance.py", line 465, in _execute_task
    result = _execute_callable(context=context, **execute_callable_kwargs)
             ^^^^^^^^^^^^^^^^^^^^^^^^^^^^^^^^^^^^^^^^^^^^^^^^^^^^^^^^^^^^^
  File "/home/airflow/.local/lib/python3.12/site-packages/airflow/models/taskinstance.py", line 432, in _execute_callable
    return execute_callable(context=context, **execute_callable_kwargs)
           ^^^^^^^^^^^^^^^^^^^^^^^^^^^^^^^^^^^^^^^^^^^^^^^^^^^^^^^^^^^^
  File "/home/airflow/.local/lib/python3.12/site-packages/airflow/models/baseoperator.py", line 401, in wrapper
    return func(self, *args, **kwargs)
           ^^^^^^^^^^^^^^^^^^^^^^^^^^^
  File "/home/airflow/.local/lib/python3.12/site-packages/airflow/operators/python.py", line 235, in execute
    return_value = self.execute_callable()
                   ^^^^^^^^^^^^^^^^^^^^^^^
  File "/home/airflow/.local/lib/python3.12/site-packages/airflow/operators/python.py", line 252, in execute_callable
    return self.python_callable(*self.op_args, **self.op_kwargs)
           ^^^^^^^^^^^^^^^^^^^^^^^^^^^^^^^^^^^^^^^^^^^^^^^^^^^^^
  File "/opt/airflow/dags/first_out.py", line 31, in run_selenium_job
    result = functions_instance.get_all_data(page_id, access_token)
             ^^^^^^^^^^^^^^^^^^^^^^^^^^^^^^^^^^^^^^^^^^^^^^^^^^^^^^
  File "/opt/airflow/dags/fun/fun_user.py", line 264, in get_all_data
    posts_dict = self.get_posts(user_id, access_token)
                 ^^^^^^^^^^^^^^^^^^^^^^^^^^^^^^^^^^^^^
  File "/opt/airflow/dags/fun/fun_user.py", line 175, in get_posts
    next_url, next_posts = self.data_handling_posts(json_dict)
                           ^^^^^^^^^^^^^^^^^^^^^^^^^^^^^^^^^^^
  File "/opt/airflow/dags/fun/fun_user.py", line 198, in data_handling_posts
    next_page = posts_next.get('paging', {})
                ^^^^^^^^^^^^^^
AttributeError: 'NoneType' object has no attribute 'get'
[2024-06-27T02:31:09.261+0000] {taskinstance.py:562} DEBUG - Task Duration set to 3.372502
[2024-06-27T02:31:09.263+0000] {taskinstance.py:584} DEBUG - Clearing next_method and next_kwargs.
[2024-06-27T02:31:09.264+0000] {taskinstance.py:1206} INFO - Marking task as FAILED. dag_id=test_us, task_id=get_urls_task, run_id=manual__2024-06-27T02:31:04.617297+00:00, execution_date=20240627T023104, start_date=20240627T023105, end_date=20240627T023109
[2024-06-27T02:31:09.279+0000] {standard_task_runner.py:110} ERROR - Failed to execute job 564 for task get_urls_task ('NoneType' object has no attribute 'get'; 1601)
[2024-06-27T02:31:09.321+0000] {local_task_job_runner.py:240} INFO - Task exited with return code 1
[2024-06-27T02:31:09.346+0000] {taskinstance.py:3503} INFO - 0 downstream tasks scheduled from follow-on schedule check
[2024-06-27T02:31:09.349+0000] {local_task_job_runner.py:222} INFO - ::endgroup::
