[2024-06-27T06:48:54.696+0000] {taskinstance.py:1042} DEBUG - previous_execution_date was called
[2024-06-27T06:48:54.741+0000] {taskinstance.py:1042} DEBUG - previous_execution_date was called
[2024-06-27T06:48:54.757+0000] {local_task_job_runner.py:120} INFO - ::group::Pre task execution logs
[2024-06-27T06:48:54.802+0000] {taskinstance.py:2076} INFO - Dependencies all met for dep_context=non-requeueable deps ti=<TaskInstance: test13.get_urls_task manual__2024-06-27T06:48:51.729587+00:00 [queued]>
[2024-06-27T06:48:54.815+0000] {taskinstance.py:2076} INFO - Dependencies all met for dep_context=requeueable deps ti=<TaskInstance: test13.get_urls_task manual__2024-06-27T06:48:51.729587+00:00 [queued]>
[2024-06-27T06:48:54.816+0000] {taskinstance.py:2306} INFO - Starting attempt 1 of 1
[2024-06-27T06:48:54.840+0000] {taskinstance.py:2330} INFO - Executing <Task(PythonOperator): get_urls_task> on 2024-06-27 06:48:51.729587+00:00
[2024-06-27T06:48:54.849+0000] {warnings.py:112} WARNING - /home/***/.local/lib/python3.12/site-packages/***/task/task_runner/standard_task_runner.py:61: DeprecationWarning: This process (pid=93) is multi-threaded, use of fork() may lead to deadlocks in the child.
  pid = os.fork()

[2024-06-27T06:48:54.852+0000] {standard_task_runner.py:63} INFO - Started process 94 to run task
[2024-06-27T06:48:54.851+0000] {standard_task_runner.py:90} INFO - Running: ['***', 'tasks', 'run', 'test13', 'get_urls_task', 'manual__2024-06-27T06:48:51.729587+00:00', '--job-id', '654', '--raw', '--subdir', 'DAGS_FOLDER/first_out.py', '--cfg-path', '/tmp/tmphdyj0go5']
[2024-06-27T06:48:54.855+0000] {standard_task_runner.py:91} INFO - Job 654: Subtask get_urls_task
[2024-06-27T06:48:54.913+0000] {taskinstance.py:1042} DEBUG - previous_execution_date was called
[2024-06-27T06:48:54.922+0000] {task_command.py:426} INFO - Running <TaskInstance: test13.get_urls_task manual__2024-06-27T06:48:51.729587+00:00 [running]> on host ccfa35e0da07
[2024-06-27T06:48:54.923+0000] {settings.py:363} DEBUG - Disposing DB connection pool (PID 94)
[2024-06-27T06:48:54.924+0000] {settings.py:250} DEBUG - Setting up DB connection pool (PID 94)
[2024-06-27T06:48:54.925+0000] {settings.py:298} DEBUG - settings.prepare_engine_args(): Using NullPool
[2024-06-27T06:48:54.976+0000] {taskinstance.py:1042} DEBUG - previous_execution_date was called
[2024-06-27T06:48:55.055+0000] {taskinstance.py:2648} INFO - Exporting env vars: AIRFLOW_CTX_DAG_OWNER='***' AIRFLOW_CTX_DAG_ID='test13' AIRFLOW_CTX_TASK_ID='get_urls_task' AIRFLOW_CTX_EXECUTION_DATE='2024-06-27T06:48:51.729587+00:00' AIRFLOW_CTX_TRY_NUMBER='1' AIRFLOW_CTX_DAG_RUN_ID='manual__2024-06-27T06:48:51.729587+00:00'
[2024-06-27T06:48:55.056+0000] {taskinstance.py:430} INFO - ::endgroup::
[2024-06-27T06:49:00.660+0000] {taskinstance.py:441} INFO - ::group::Post task execution logs
[2024-06-27T06:49:00.662+0000] {taskinstance.py:2905} ERROR - Task failed with exception
Traceback (most recent call last):
  File "/home/airflow/.local/lib/python3.12/site-packages/airflow/models/taskinstance.py", line 465, in _execute_task
    result = _execute_callable(context=context, **execute_callable_kwargs)
             ^^^^^^^^^^^^^^^^^^^^^^^^^^^^^^^^^^^^^^^^^^^^^^^^^^^^^^^^^^^^^
  File "/home/airflow/.local/lib/python3.12/site-packages/airflow/models/taskinstance.py", line 432, in _execute_callable
    return execute_callable(context=context, **execute_callable_kwargs)
           ^^^^^^^^^^^^^^^^^^^^^^^^^^^^^^^^^^^^^^^^^^^^^^^^^^^^^^^^^^^^
  File "/home/airflow/.local/lib/python3.12/site-packages/airflow/models/baseoperator.py", line 401, in wrapper
    return func(self, *args, **kwargs)
           ^^^^^^^^^^^^^^^^^^^^^^^^^^^
  File "/home/airflow/.local/lib/python3.12/site-packages/airflow/operators/python.py", line 235, in execute
    return_value = self.execute_callable()
                   ^^^^^^^^^^^^^^^^^^^^^^^
  File "/home/airflow/.local/lib/python3.12/site-packages/airflow/operators/python.py", line 252, in execute_callable
    return self.python_callable(*self.op_args, **self.op_kwargs)
           ^^^^^^^^^^^^^^^^^^^^^^^^^^^^^^^^^^^^^^^^^^^^^^^^^^^^^
  File "/opt/airflow/dags/first_out.py", line 49, in run_selenium_job
    match = re.search(r'id=(\d+)', driver)
            ^^^^^^^^^^^^^^^^^^^^^^^^^^^^^^
  File "/usr/local/lib/python3.12/re/__init__.py", line 177, in search
    return _compile(pattern, flags).search(string)
           ^^^^^^^^^^^^^^^^^^^^^^^^^^^^^^^^^^^^^^^
TypeError: expected string or bytes-like object, got 'WebDriver'
[2024-06-27T06:49:00.687+0000] {taskinstance.py:562} DEBUG - Task Duration set to 5.884144
[2024-06-27T06:49:00.689+0000] {taskinstance.py:584} DEBUG - Clearing next_method and next_kwargs.
[2024-06-27T06:49:00.690+0000] {taskinstance.py:1206} INFO - Marking task as FAILED. dag_id=test13, task_id=get_urls_task, run_id=manual__2024-06-27T06:48:51.729587+00:00, execution_date=20240627T064851, start_date=20240627T064854, end_date=20240627T064900
[2024-06-27T06:49:00.714+0000] {standard_task_runner.py:110} ERROR - Failed to execute job 654 for task get_urls_task (expected string or bytes-like object, got 'WebDriver'; 94)
[2024-06-27T06:49:00.758+0000] {local_task_job_runner.py:240} INFO - Task exited with return code 1
[2024-06-27T06:49:00.778+0000] {taskinstance.py:3503} INFO - 0 downstream tasks scheduled from follow-on schedule check
[2024-06-27T06:49:00.784+0000] {local_task_job_runner.py:222} INFO - ::endgroup::
