[2024-06-28T02:35:13.167+0000] {taskinstance.py:1042} DEBUG - previous_execution_date was called
[2024-06-28T02:35:13.210+0000] {taskinstance.py:1042} DEBUG - previous_execution_date was called
[2024-06-28T02:35:13.229+0000] {local_task_job_runner.py:120} INFO - ::group::Pre task execution logs
[2024-06-28T02:35:13.278+0000] {taskinstance.py:2076} INFO - Dependencies all met for dep_context=non-requeueable deps ti=<TaskInstance: USER1.process_link_2 manual__2024-06-28T02:35:04.172281+00:00 [queued]>
[2024-06-28T02:35:13.294+0000] {taskinstance.py:2076} INFO - Dependencies all met for dep_context=requeueable deps ti=<TaskInstance: USER1.process_link_2 manual__2024-06-28T02:35:04.172281+00:00 [queued]>
[2024-06-28T02:35:13.296+0000] {taskinstance.py:2306} INFO - Starting attempt 1 of 1
[2024-06-28T02:35:13.526+0000] {taskinstance.py:2330} INFO - Executing <Task(PythonOperator): process_link_2> on 2024-06-28 02:35:04.172281+00:00
[2024-06-28T02:35:13.539+0000] {warnings.py:112} WARNING - /home/***/.local/lib/python3.12/site-packages/***/task/task_runner/standard_task_runner.py:61: DeprecationWarning: This process (pid=1005) is multi-threaded, use of fork() may lead to deadlocks in the child.
  pid = os.fork()

[2024-06-28T02:35:13.548+0000] {standard_task_runner.py:63} INFO - Started process 1026 to run task
[2024-06-28T02:35:13.550+0000] {standard_task_runner.py:90} INFO - Running: ['***', 'tasks', 'run', 'USER1', 'process_link_2', 'manual__2024-06-28T02:35:04.172281+00:00', '--job-id', '782', '--raw', '--subdir', 'DAGS_FOLDER/user_***.py', '--cfg-path', '/tmp/tmpnl3qvgvt']
[2024-06-28T02:35:13.552+0000] {standard_task_runner.py:91} INFO - Job 782: Subtask process_link_2
[2024-06-28T02:35:13.697+0000] {taskinstance.py:1042} DEBUG - previous_execution_date was called
[2024-06-28T02:35:13.733+0000] {task_command.py:426} INFO - Running <TaskInstance: USER1.process_link_2 manual__2024-06-28T02:35:04.172281+00:00 [running]> on host ccfa35e0da07
[2024-06-28T02:35:13.734+0000] {settings.py:363} DEBUG - Disposing DB connection pool (PID 1026)
[2024-06-28T02:35:13.735+0000] {settings.py:250} DEBUG - Setting up DB connection pool (PID 1026)
[2024-06-28T02:35:13.736+0000] {settings.py:298} DEBUG - settings.prepare_engine_args(): Using NullPool
[2024-06-28T02:35:13.883+0000] {taskinstance.py:1042} DEBUG - previous_execution_date was called
[2024-06-28T02:35:13.971+0000] {taskinstance.py:2648} INFO - Exporting env vars: AIRFLOW_CTX_DAG_OWNER='***' AIRFLOW_CTX_DAG_ID='USER1' AIRFLOW_CTX_TASK_ID='process_link_2' AIRFLOW_CTX_EXECUTION_DATE='2024-06-28T02:35:04.172281+00:00' AIRFLOW_CTX_TRY_NUMBER='1' AIRFLOW_CTX_DAG_RUN_ID='manual__2024-06-28T02:35:04.172281+00:00'
[2024-06-28T02:35:13.976+0000] {taskinstance.py:430} INFO - ::endgroup::
[2024-06-28T02:35:14.844+0000] {connectionpool.py:244} DEBUG - Starting new HTTP connection (1): localhost:34689
[2024-06-28T02:35:58.630+0000] {job.py:218} ERROR - Job heartbeat got an exception
Traceback (most recent call last):
  File "/home/airflow/.local/lib/python3.12/site-packages/sqlalchemy/engine/base.py", line 3371, in _wrap_pool_connect
    return fn()
           ^^^^
  File "/home/airflow/.local/lib/python3.12/site-packages/sqlalchemy/pool/base.py", line 327, in connect
    return _ConnectionFairy._checkout(self)
           ^^^^^^^^^^^^^^^^^^^^^^^^^^^^^^^^
  File "/home/airflow/.local/lib/python3.12/site-packages/sqlalchemy/pool/base.py", line 894, in _checkout
    fairy = _ConnectionRecord.checkout(pool)
            ^^^^^^^^^^^^^^^^^^^^^^^^^^^^^^^^
  File "/home/airflow/.local/lib/python3.12/site-packages/sqlalchemy/pool/base.py", line 493, in checkout
    rec = pool._do_get()
          ^^^^^^^^^^^^^^
  File "/home/airflow/.local/lib/python3.12/site-packages/sqlalchemy/pool/impl.py", line 256, in _do_get
    return self._create_connection()
           ^^^^^^^^^^^^^^^^^^^^^^^^^
  File "/home/airflow/.local/lib/python3.12/site-packages/sqlalchemy/pool/base.py", line 273, in _create_connection
    return _ConnectionRecord(self)
           ^^^^^^^^^^^^^^^^^^^^^^^
  File "/home/airflow/.local/lib/python3.12/site-packages/sqlalchemy/pool/base.py", line 388, in __init__
    self.__connect()
  File "/home/airflow/.local/lib/python3.12/site-packages/sqlalchemy/pool/base.py", line 690, in __connect
    with util.safe_reraise():
  File "/home/airflow/.local/lib/python3.12/site-packages/sqlalchemy/util/langhelpers.py", line 70, in __exit__
    compat.raise_(
  File "/home/airflow/.local/lib/python3.12/site-packages/sqlalchemy/util/compat.py", line 211, in raise_
    raise exception
  File "/home/airflow/.local/lib/python3.12/site-packages/sqlalchemy/pool/base.py", line 686, in __connect
    self.dbapi_connection = connection = pool._invoke_creator(self)
                                         ^^^^^^^^^^^^^^^^^^^^^^^^^^
  File "/home/airflow/.local/lib/python3.12/site-packages/sqlalchemy/engine/create.py", line 574, in connect
    return dialect.connect(*cargs, **cparams)
           ^^^^^^^^^^^^^^^^^^^^^^^^^^^^^^^^^^
  File "/home/airflow/.local/lib/python3.12/site-packages/sqlalchemy/engine/default.py", line 598, in connect
    return self.dbapi.connect(*cargs, **cparams)
           ^^^^^^^^^^^^^^^^^^^^^^^^^^^^^^^^^^^^^
  File "/home/airflow/.local/lib/python3.12/site-packages/psycopg2/__init__.py", line 122, in connect
    conn = _connect(dsn, connection_factory=connection_factory, **kwasync)
           ^^^^^^^^^^^^^^^^^^^^^^^^^^^^^^^^^^^^^^^^^^^^^^^^^^^^^^^^^^^^^^^
psycopg2.OperationalError: could not translate host name "postgres" to address: Temporary failure in name resolution


The above exception was the direct cause of the following exception:

Traceback (most recent call last):
  File "/home/airflow/.local/lib/python3.12/site-packages/airflow/jobs/job.py", line 192, in heartbeat
    self._merge_from(Job._fetch_from_db(self, session))
                     ^^^^^^^^^^^^^^^^^^^^^^^^^^^^^^^^^
  File "/home/airflow/.local/lib/python3.12/site-packages/airflow/api_internal/internal_api_call.py", line 115, in wrapper
    return func(*args, **kwargs)
           ^^^^^^^^^^^^^^^^^^^^^
  File "/home/airflow/.local/lib/python3.12/site-packages/airflow/utils/session.py", line 76, in wrapper
    return func(*args, **kwargs)
           ^^^^^^^^^^^^^^^^^^^^^
  File "/home/airflow/.local/lib/python3.12/site-packages/airflow/utils/retries.py", line 89, in wrapped_function
    for attempt in run_with_db_retries(max_retries=retries, logger=logger, **retry_kwargs):
  File "/home/airflow/.local/lib/python3.12/site-packages/tenacity/__init__.py", line 435, in __iter__
    do = self.iter(retry_state=retry_state)
         ^^^^^^^^^^^^^^^^^^^^^^^^^^^^^^^^^^
  File "/home/airflow/.local/lib/python3.12/site-packages/tenacity/__init__.py", line 368, in iter
    result = action(retry_state)
             ^^^^^^^^^^^^^^^^^^^
  File "/home/airflow/.local/lib/python3.12/site-packages/tenacity/__init__.py", line 410, in exc_check
    raise retry_exc.reraise()
          ^^^^^^^^^^^^^^^^^^^
  File "/home/airflow/.local/lib/python3.12/site-packages/tenacity/__init__.py", line 183, in reraise
    raise self.last_attempt.result()
          ^^^^^^^^^^^^^^^^^^^^^^^^^^
  File "/usr/local/lib/python3.12/concurrent/futures/_base.py", line 449, in result
    return self.__get_result()
           ^^^^^^^^^^^^^^^^^^^
  File "/usr/local/lib/python3.12/concurrent/futures/_base.py", line 401, in __get_result
    raise self._exception
  File "/home/airflow/.local/lib/python3.12/site-packages/airflow/utils/retries.py", line 98, in wrapped_function
    return func(*args, **kwargs)
           ^^^^^^^^^^^^^^^^^^^^^
  File "/home/airflow/.local/lib/python3.12/site-packages/airflow/jobs/job.py", line 316, in _fetch_from_db
    session.merge(job)
  File "/home/airflow/.local/lib/python3.12/site-packages/sqlalchemy/orm/session.py", line 3056, in merge
    return self._merge(
           ^^^^^^^^^^^^
  File "/home/airflow/.local/lib/python3.12/site-packages/sqlalchemy/orm/session.py", line 3136, in _merge
    merged = self.get(
             ^^^^^^^^^
  File "/home/airflow/.local/lib/python3.12/site-packages/sqlalchemy/orm/session.py", line 2853, in get
    return self._get_impl(
           ^^^^^^^^^^^^^^^
  File "/home/airflow/.local/lib/python3.12/site-packages/sqlalchemy/orm/session.py", line 2975, in _get_impl
    return db_load_fn(
           ^^^^^^^^^^^
  File "/home/airflow/.local/lib/python3.12/site-packages/sqlalchemy/orm/loading.py", line 530, in load_on_pk_identity
    session.execute(
  File "/home/airflow/.local/lib/python3.12/site-packages/sqlalchemy/orm/session.py", line 1716, in execute
    conn = self._connection_for_bind(bind)
           ^^^^^^^^^^^^^^^^^^^^^^^^^^^^^^^
  File "/home/airflow/.local/lib/python3.12/site-packages/sqlalchemy/orm/session.py", line 1555, in _connection_for_bind
    return self._transaction._connection_for_bind(
           ^^^^^^^^^^^^^^^^^^^^^^^^^^^^^^^^^^^^^^^
  File "/home/airflow/.local/lib/python3.12/site-packages/sqlalchemy/orm/session.py", line 750, in _connection_for_bind
    conn = bind.connect()
           ^^^^^^^^^^^^^^
  File "/home/airflow/.local/lib/python3.12/site-packages/sqlalchemy/future/engine.py", line 412, in connect
    return super(Engine, self).connect()
           ^^^^^^^^^^^^^^^^^^^^^^^^^^^^^
  File "/home/airflow/.local/lib/python3.12/site-packages/sqlalchemy/engine/base.py", line 3325, in connect
    return self._connection_cls(self, close_with_result=close_with_result)
           ^^^^^^^^^^^^^^^^^^^^^^^^^^^^^^^^^^^^^^^^^^^^^^^^^^^^^^^^^^^^^^^
  File "/home/airflow/.local/lib/python3.12/site-packages/sqlalchemy/engine/base.py", line 96, in __init__
    else engine.raw_connection()
         ^^^^^^^^^^^^^^^^^^^^^^^
  File "/home/airflow/.local/lib/python3.12/site-packages/sqlalchemy/engine/base.py", line 3404, in raw_connection
    return self._wrap_pool_connect(self.pool.connect, _connection)
           ^^^^^^^^^^^^^^^^^^^^^^^^^^^^^^^^^^^^^^^^^^^^^^^^^^^^^^^
  File "/home/airflow/.local/lib/python3.12/site-packages/sqlalchemy/engine/base.py", line 3374, in _wrap_pool_connect
    Connection._handle_dbapi_exception_noconnection(
  File "/home/airflow/.local/lib/python3.12/site-packages/sqlalchemy/engine/base.py", line 2208, in _handle_dbapi_exception_noconnection
    util.raise_(
  File "/home/airflow/.local/lib/python3.12/site-packages/sqlalchemy/util/compat.py", line 211, in raise_
    raise exception
  File "/home/airflow/.local/lib/python3.12/site-packages/sqlalchemy/engine/base.py", line 3371, in _wrap_pool_connect
    return fn()
           ^^^^
  File "/home/airflow/.local/lib/python3.12/site-packages/sqlalchemy/pool/base.py", line 327, in connect
    return _ConnectionFairy._checkout(self)
           ^^^^^^^^^^^^^^^^^^^^^^^^^^^^^^^^
  File "/home/airflow/.local/lib/python3.12/site-packages/sqlalchemy/pool/base.py", line 894, in _checkout
    fairy = _ConnectionRecord.checkout(pool)
            ^^^^^^^^^^^^^^^^^^^^^^^^^^^^^^^^
  File "/home/airflow/.local/lib/python3.12/site-packages/sqlalchemy/pool/base.py", line 493, in checkout
    rec = pool._do_get()
          ^^^^^^^^^^^^^^
  File "/home/airflow/.local/lib/python3.12/site-packages/sqlalchemy/pool/impl.py", line 256, in _do_get
    return self._create_connection()
           ^^^^^^^^^^^^^^^^^^^^^^^^^
  File "/home/airflow/.local/lib/python3.12/site-packages/sqlalchemy/pool/base.py", line 273, in _create_connection
    return _ConnectionRecord(self)
           ^^^^^^^^^^^^^^^^^^^^^^^
  File "/home/airflow/.local/lib/python3.12/site-packages/sqlalchemy/pool/base.py", line 388, in __init__
    self.__connect()
  File "/home/airflow/.local/lib/python3.12/site-packages/sqlalchemy/pool/base.py", line 690, in __connect
    with util.safe_reraise():
  File "/home/airflow/.local/lib/python3.12/site-packages/sqlalchemy/util/langhelpers.py", line 70, in __exit__
    compat.raise_(
  File "/home/airflow/.local/lib/python3.12/site-packages/sqlalchemy/util/compat.py", line 211, in raise_
    raise exception
  File "/home/airflow/.local/lib/python3.12/site-packages/sqlalchemy/pool/base.py", line 686, in __connect
    self.dbapi_connection = connection = pool._invoke_creator(self)
                                         ^^^^^^^^^^^^^^^^^^^^^^^^^^
  File "/home/airflow/.local/lib/python3.12/site-packages/sqlalchemy/engine/create.py", line 574, in connect
    return dialect.connect(*cargs, **cparams)
           ^^^^^^^^^^^^^^^^^^^^^^^^^^^^^^^^^^
  File "/home/airflow/.local/lib/python3.12/site-packages/sqlalchemy/engine/default.py", line 598, in connect
    return self.dbapi.connect(*cargs, **cparams)
           ^^^^^^^^^^^^^^^^^^^^^^^^^^^^^^^^^^^^^
  File "/home/airflow/.local/lib/python3.12/site-packages/psycopg2/__init__.py", line 122, in connect
    conn = _connect(dsn, connection_factory=connection_factory, **kwasync)
           ^^^^^^^^^^^^^^^^^^^^^^^^^^^^^^^^^^^^^^^^^^^^^^^^^^^^^^^^^^^^^^^
sqlalchemy.exc.OperationalError: (psycopg2.OperationalError) could not translate host name "postgres" to address: Temporary failure in name resolution

(Background on this error at: https://sqlalche.me/e/14/e3q8)
[2024-06-28T02:36:00.909+0000] {job.py:226} ERROR - Job heartbeat failed with error. Scheduler is in unhealthy state
[2024-06-28T02:36:04.151+0000] {connectionpool.py:549} DEBUG - http://localhost:34689 "POST /session HTTP/1.1" 200 0
[2024-06-28T02:36:37.165+0000] {job.py:226} ERROR - Job heartbeat failed with error. Scheduler is in unhealthy state
[2024-06-28T02:36:41.779+0000] {connectionpool.py:549} DEBUG - http://localhost:34689 "POST /session/5d18f2a0235ebda4e9425f77bb12824a/url HTTP/1.1" 500 0
[2024-06-28T02:36:41.816+0000] {taskinstance.py:441} INFO - ::group::Post task execution logs
[2024-06-28T02:36:41.821+0000] {taskinstance.py:2905} ERROR - Task failed with exception
Traceback (most recent call last):
  File "/home/airflow/.local/lib/python3.12/site-packages/airflow/models/taskinstance.py", line 465, in _execute_task
    result = _execute_callable(context=context, **execute_callable_kwargs)
             ^^^^^^^^^^^^^^^^^^^^^^^^^^^^^^^^^^^^^^^^^^^^^^^^^^^^^^^^^^^^^
  File "/home/airflow/.local/lib/python3.12/site-packages/airflow/models/taskinstance.py", line 432, in _execute_callable
    return execute_callable(context=context, **execute_callable_kwargs)
           ^^^^^^^^^^^^^^^^^^^^^^^^^^^^^^^^^^^^^^^^^^^^^^^^^^^^^^^^^^^^
  File "/home/airflow/.local/lib/python3.12/site-packages/airflow/models/baseoperator.py", line 401, in wrapper
    return func(self, *args, **kwargs)
           ^^^^^^^^^^^^^^^^^^^^^^^^^^^
  File "/home/airflow/.local/lib/python3.12/site-packages/airflow/operators/python.py", line 235, in execute
    return_value = self.execute_callable()
                   ^^^^^^^^^^^^^^^^^^^^^^^
  File "/home/airflow/.local/lib/python3.12/site-packages/airflow/operators/python.py", line 252, in execute_callable
    return self.python_callable(*self.op_args, **self.op_kwargs)
           ^^^^^^^^^^^^^^^^^^^^^^^^^^^^^^^^^^^^^^^^^^^^^^^^^^^^^
  File "/opt/airflow/dags/user_airflow.py", line 122, in process_link
    result = run_selenium_job(link)
             ^^^^^^^^^^^^^^^^^^^^^^
  File "/opt/airflow/dags/user_airflow.py", line 63, in run_selenium_job
    driver.get(link)
  File "/home/airflow/.local/lib/python3.12/site-packages/selenium/webdriver/remote/webdriver.py", line 356, in get
    self.execute(Command.GET, {"url": url})
  File "/home/airflow/.local/lib/python3.12/site-packages/selenium/webdriver/remote/webdriver.py", line 347, in execute
    self.error_handler.check_response(response)
  File "/home/airflow/.local/lib/python3.12/site-packages/selenium/webdriver/remote/errorhandler.py", line 229, in check_response
    raise exception_class(message, screen, stacktrace)
selenium.common.exceptions.WebDriverException: Message: unknown error: net::ERR_NAME_NOT_RESOLVED
  (Session info: chrome-headless-shell=126.0.6478.114)
Stacktrace:
#0 0x55cccf16d8ae <unknown>
#1 0x55cccee3ec57 <unknown>
#2 0x55cccee380d6 <unknown>
#3 0x55cccee2abbc <unknown>
#4 0x55cccee2c27b <unknown>
#5 0x55cccee2b03b <unknown>
#6 0x55cccee2a84b <unknown>
#7 0x55cccee2a6e0 <unknown>
#8 0x55cccee28ba0 <unknown>
#9 0x55cccee28ef4 <unknown>
#10 0x55cccee41f06 <unknown>
#11 0x55ccceec5de2 <unknown>
#12 0x55ccceea8b12 <unknown>
#13 0x55ccceec5920 <unknown>
#14 0x55ccceea8893 <unknown>
#15 0x55cccee792ed <unknown>
#16 0x55cccee7a092 <unknown>
#17 0x55cccf13d256 <unknown>
#18 0x55cccf1405f9 <unknown>
#19 0x55cccf1400bf <unknown>
#20 0x55cccf140a75 <unknown>
#21 0x55cccf12d79f <unknown>
#22 0x55cccf140dc0 <unknown>
#23 0x55cccf1166c6 <unknown>
#24 0x55cccf15dfb5 <unknown>
#25 0x55cccf15e1a2 <unknown>
#26 0x55cccf16cd9a <unknown>
#27 0x7f9625298134 <unknown>

[2024-06-28T02:36:47.470+0000] {taskinstance.py:562} DEBUG - Task Duration set to 94.191374
[2024-06-28T02:36:47.480+0000] {taskinstance.py:584} DEBUG - Clearing next_method and next_kwargs.
[2024-06-28T02:36:47.482+0000] {taskinstance.py:1206} INFO - Marking task as FAILED. dag_id=USER1, task_id=process_link_2, run_id=manual__2024-06-28T02:35:04.172281+00:00, execution_date=20240628T023504, start_date=20240628T023513, end_date=20240628T023647
[2024-06-28T02:36:47.576+0000] {standard_task_runner.py:110} ERROR - Failed to execute job 782 for task process_link_2 (Message: unknown error: net::ERR_NAME_NOT_RESOLVED
  (Session info: chrome-headless-shell=126.0.6478.114)
Stacktrace:
#0 0x55cccf16d8ae <unknown>
#1 0x55cccee3ec57 <unknown>
#2 0x55cccee380d6 <unknown>
#3 0x55cccee2abbc <unknown>
#4 0x55cccee2c27b <unknown>
#5 0x55cccee2b03b <unknown>
#6 0x55cccee2a84b <unknown>
#7 0x55cccee2a6e0 <unknown>
#8 0x55cccee28ba0 <unknown>
#9 0x55cccee28ef4 <unknown>
#10 0x55cccee41f06 <unknown>
#11 0x55ccceec5de2 <unknown>
#12 0x55ccceea8b12 <unknown>
#13 0x55ccceec5920 <unknown>
#14 0x55ccceea8893 <unknown>
#15 0x55cccee792ed <unknown>
#16 0x55cccee7a092 <unknown>
#17 0x55cccf13d256 <unknown>
#18 0x55cccf1405f9 <unknown>
#19 0x55cccf1400bf <unknown>
#20 0x55cccf140a75 <unknown>
#21 0x55cccf12d79f <unknown>
#22 0x55cccf140dc0 <unknown>
#23 0x55cccf1166c6 <unknown>
#24 0x55cccf15dfb5 <unknown>
#25 0x55cccf15e1a2 <unknown>
#26 0x55cccf16cd9a <unknown>
#27 0x7f9625298134 <unknown>
; 1026)
[2024-06-28T02:36:47.606+0000] {local_task_job_runner.py:240} INFO - Task exited with return code 1
[2024-06-28T02:36:47.633+0000] {taskinstance.py:3503} INFO - 0 downstream tasks scheduled from follow-on schedule check
[2024-06-28T02:36:47.638+0000] {local_task_job_runner.py:222} INFO - ::endgroup::
