[2024-06-27T01:52:05.621+0000] {taskinstance.py:1042} DEBUG - previous_execution_date was called
[2024-06-27T01:52:05.658+0000] {taskinstance.py:1042} DEBUG - previous_execution_date was called
[2024-06-27T01:52:05.672+0000] {local_task_job_runner.py:120} INFO - ::group::Pre task execution logs
[2024-06-27T01:52:05.708+0000] {taskinstance.py:2076} INFO - Dependencies all met for dep_context=non-requeueable deps ti=<TaskInstance: test_user.get_urls_task manual__2024-06-27T01:52:03.883426+00:00 [queued]>
[2024-06-27T01:52:05.718+0000] {taskinstance.py:2076} INFO - Dependencies all met for dep_context=requeueable deps ti=<TaskInstance: test_user.get_urls_task manual__2024-06-27T01:52:03.883426+00:00 [queued]>
[2024-06-27T01:52:05.720+0000] {taskinstance.py:2306} INFO - Starting attempt 1 of 1
[2024-06-27T01:52:05.738+0000] {taskinstance.py:2330} INFO - Executing <Task(PythonOperator): get_urls_task> on 2024-06-27 01:52:03.883426+00:00
[2024-06-27T01:52:05.744+0000] {warnings.py:112} WARNING - /home/***/.local/lib/python3.12/site-packages/***/task/task_runner/standard_task_runner.py:61: DeprecationWarning: This process (pid=108) is multi-threaded, use of fork() may lead to deadlocks in the child.
  pid = os.fork()

[2024-06-27T01:52:05.746+0000] {standard_task_runner.py:63} INFO - Started process 109 to run task
[2024-06-27T01:52:05.746+0000] {standard_task_runner.py:90} INFO - Running: ['***', 'tasks', 'run', 'test_user', 'get_urls_task', 'manual__2024-06-27T01:52:03.883426+00:00', '--job-id', '556', '--raw', '--subdir', 'DAGS_FOLDER/first_out.py', '--cfg-path', '/tmp/tmp0plnwwr_']
[2024-06-27T01:52:05.748+0000] {standard_task_runner.py:91} INFO - Job 556: Subtask get_urls_task
[2024-06-27T01:52:05.796+0000] {taskinstance.py:1042} DEBUG - previous_execution_date was called
[2024-06-27T01:52:05.803+0000] {task_command.py:426} INFO - Running <TaskInstance: test_user.get_urls_task manual__2024-06-27T01:52:03.883426+00:00 [running]> on host ccfa35e0da07
[2024-06-27T01:52:05.804+0000] {settings.py:363} DEBUG - Disposing DB connection pool (PID 109)
[2024-06-27T01:52:05.805+0000] {settings.py:250} DEBUG - Setting up DB connection pool (PID 109)
[2024-06-27T01:52:05.806+0000] {settings.py:298} DEBUG - settings.prepare_engine_args(): Using NullPool
[2024-06-27T01:52:05.851+0000] {taskinstance.py:1042} DEBUG - previous_execution_date was called
[2024-06-27T01:52:05.912+0000] {taskinstance.py:2648} INFO - Exporting env vars: AIRFLOW_CTX_DAG_OWNER='***' AIRFLOW_CTX_DAG_ID='test_user' AIRFLOW_CTX_TASK_ID='get_urls_task' AIRFLOW_CTX_EXECUTION_DATE='2024-06-27T01:52:03.883426+00:00' AIRFLOW_CTX_TRY_NUMBER='1' AIRFLOW_CTX_DAG_RUN_ID='manual__2024-06-27T01:52:03.883426+00:00'
[2024-06-27T01:52:05.914+0000] {taskinstance.py:430} INFO - ::endgroup::
[2024-06-27T01:52:23.193+0000] {fun_user.py:87} INFO - Found id: 100015161496348
[2024-06-27T01:52:23.541+0000] {taskinstance.py:441} INFO - ::group::Post task execution logs
[2024-06-27T01:52:23.544+0000] {taskinstance.py:2905} ERROR - Task failed with exception
Traceback (most recent call last):
  File "/home/airflow/.local/lib/python3.12/site-packages/airflow/models/taskinstance.py", line 465, in _execute_task
    result = _execute_callable(context=context, **execute_callable_kwargs)
             ^^^^^^^^^^^^^^^^^^^^^^^^^^^^^^^^^^^^^^^^^^^^^^^^^^^^^^^^^^^^^
  File "/home/airflow/.local/lib/python3.12/site-packages/airflow/models/taskinstance.py", line 432, in _execute_callable
    return execute_callable(context=context, **execute_callable_kwargs)
           ^^^^^^^^^^^^^^^^^^^^^^^^^^^^^^^^^^^^^^^^^^^^^^^^^^^^^^^^^^^^
  File "/home/airflow/.local/lib/python3.12/site-packages/airflow/models/baseoperator.py", line 401, in wrapper
    return func(self, *args, **kwargs)
           ^^^^^^^^^^^^^^^^^^^^^^^^^^^
  File "/home/airflow/.local/lib/python3.12/site-packages/airflow/operators/python.py", line 235, in execute
    return_value = self.execute_callable()
                   ^^^^^^^^^^^^^^^^^^^^^^^
  File "/home/airflow/.local/lib/python3.12/site-packages/airflow/operators/python.py", line 252, in execute_callable
    return self.python_callable(*self.op_args, **self.op_kwargs)
           ^^^^^^^^^^^^^^^^^^^^^^^^^^^^^^^^^^^^^^^^^^^^^^^^^^^^^
  File "/opt/airflow/dags/first_out.py", line 39, in run_selenium_job
    result = functions_instance.get_all_data(driver,page_id, access_token)
             ^^^^^^^^^^^^^^^^^^^^^^^^^^^^^^^^^^^^^^^^^^^^^^^^^^^^^^^^^^^^^
TypeError: User_Functions.get_all_data() takes 3 positional arguments but 4 were given
[2024-06-27T01:52:23.564+0000] {taskinstance.py:562} DEBUG - Task Duration set to 17.855615
[2024-06-27T01:52:23.567+0000] {taskinstance.py:584} DEBUG - Clearing next_method and next_kwargs.
[2024-06-27T01:52:23.568+0000] {taskinstance.py:1206} INFO - Marking task as FAILED. dag_id=test_user, task_id=get_urls_task, run_id=manual__2024-06-27T01:52:03.883426+00:00, execution_date=20240627T015203, start_date=20240627T015205, end_date=20240627T015223
[2024-06-27T01:52:23.598+0000] {standard_task_runner.py:110} ERROR - Failed to execute job 556 for task get_urls_task (User_Functions.get_all_data() takes 3 positional arguments but 4 were given; 109)
[2024-06-27T01:52:23.646+0000] {local_task_job_runner.py:240} INFO - Task exited with return code 1
[2024-06-27T01:52:23.918+0000] {taskinstance.py:3503} INFO - 0 downstream tasks scheduled from follow-on schedule check
[2024-06-27T01:52:23.923+0000] {local_task_job_runner.py:222} INFO - ::endgroup::
