[2024-06-26T07:41:00.126+0000] {taskinstance.py:1042} DEBUG - previous_execution_date was called
[2024-06-26T07:41:00.170+0000] {taskinstance.py:1042} DEBUG - previous_execution_date was called
[2024-06-26T07:41:00.185+0000] {local_task_job_runner.py:120} INFO - ::group::Pre task execution logs
[2024-06-26T07:41:00.221+0000] {taskinstance.py:2076} INFO - Dependencies all met for dep_context=non-requeueable deps ti=<TaskInstance: USER.process_link_0 manual__2024-06-26T07:40:55.337303+00:00 [queued]>
[2024-06-26T07:41:00.231+0000] {taskinstance.py:2076} INFO - Dependencies all met for dep_context=requeueable deps ti=<TaskInstance: USER.process_link_0 manual__2024-06-26T07:40:55.337303+00:00 [queued]>
[2024-06-26T07:41:00.233+0000] {taskinstance.py:2306} INFO - Starting attempt 1 of 1
[2024-06-26T07:41:00.251+0000] {taskinstance.py:2330} INFO - Executing <Task(PythonOperator): process_link_0> on 2024-06-26 07:40:55.337303+00:00
[2024-06-26T07:41:00.258+0000] {warnings.py:112} WARNING - /home/***/.local/lib/python3.12/site-packages/***/task/task_runner/standard_task_runner.py:61: DeprecationWarning: This process (pid=2111) is multi-threaded, use of fork() may lead to deadlocks in the child.
  pid = os.fork()

[2024-06-26T07:41:00.260+0000] {standard_task_runner.py:63} INFO - Started process 2112 to run task
[2024-06-26T07:41:00.261+0000] {standard_task_runner.py:90} INFO - Running: ['***', 'tasks', 'run', 'USER', 'process_link_0', 'manual__2024-06-26T07:40:55.337303+00:00', '--job-id', '532', '--raw', '--subdir', 'DAGS_FOLDER/user_***.py', '--cfg-path', '/tmp/tmpx4am0jsq']
[2024-06-26T07:41:00.262+0000] {standard_task_runner.py:91} INFO - Job 532: Subtask process_link_0
[2024-06-26T07:41:00.313+0000] {taskinstance.py:1042} DEBUG - previous_execution_date was called
[2024-06-26T07:41:00.322+0000] {task_command.py:426} INFO - Running <TaskInstance: USER.process_link_0 manual__2024-06-26T07:40:55.337303+00:00 [running]> on host ccfa35e0da07
[2024-06-26T07:41:00.323+0000] {settings.py:363} DEBUG - Disposing DB connection pool (PID 2112)
[2024-06-26T07:41:00.324+0000] {settings.py:250} DEBUG - Setting up DB connection pool (PID 2112)
[2024-06-26T07:41:00.325+0000] {settings.py:298} DEBUG - settings.prepare_engine_args(): Using NullPool
[2024-06-26T07:41:00.375+0000] {taskinstance.py:1042} DEBUG - previous_execution_date was called
[2024-06-26T07:41:00.465+0000] {taskinstance.py:2648} INFO - Exporting env vars: AIRFLOW_CTX_DAG_OWNER='***' AIRFLOW_CTX_DAG_ID='USER' AIRFLOW_CTX_TASK_ID='process_link_0' AIRFLOW_CTX_EXECUTION_DATE='2024-06-26T07:40:55.337303+00:00' AIRFLOW_CTX_TRY_NUMBER='1' AIRFLOW_CTX_DAG_RUN_ID='manual__2024-06-26T07:40:55.337303+00:00'
[2024-06-26T07:41:00.467+0000] {taskinstance.py:430} INFO - ::endgroup::
[2024-06-26T07:41:02.336+0000] {connectionpool.py:244} DEBUG - Starting new HTTP connection (1): localhost:46683
[2024-06-26T07:41:03.612+0000] {connectionpool.py:549} DEBUG - http://localhost:46683 "POST /session HTTP/1.1" 200 0
[2024-06-26T07:41:03.742+0000] {connectionpool.py:549} DEBUG - http://localhost:46683 "DELETE /session/80cb29848b696987197ff3ed5014e808 HTTP/1.1" 200 0
[2024-06-26T07:41:03.838+0000] {taskinstance.py:441} INFO - ::group::Post task execution logs
[2024-06-26T07:41:03.839+0000] {taskinstance.py:2905} ERROR - Task failed with exception
Traceback (most recent call last):
  File "/home/airflow/.local/lib/python3.12/site-packages/airflow/models/taskinstance.py", line 465, in _execute_task
    result = _execute_callable(context=context, **execute_callable_kwargs)
             ^^^^^^^^^^^^^^^^^^^^^^^^^^^^^^^^^^^^^^^^^^^^^^^^^^^^^^^^^^^^^
  File "/home/airflow/.local/lib/python3.12/site-packages/airflow/models/taskinstance.py", line 432, in _execute_callable
    return execute_callable(context=context, **execute_callable_kwargs)
           ^^^^^^^^^^^^^^^^^^^^^^^^^^^^^^^^^^^^^^^^^^^^^^^^^^^^^^^^^^^^
  File "/home/airflow/.local/lib/python3.12/site-packages/airflow/models/baseoperator.py", line 401, in wrapper
    return func(self, *args, **kwargs)
           ^^^^^^^^^^^^^^^^^^^^^^^^^^^
  File "/home/airflow/.local/lib/python3.12/site-packages/airflow/operators/python.py", line 235, in execute
    return_value = self.execute_callable()
                   ^^^^^^^^^^^^^^^^^^^^^^^
  File "/home/airflow/.local/lib/python3.12/site-packages/airflow/operators/python.py", line 252, in execute_callable
    return self.python_callable(*self.op_args, **self.op_kwargs)
           ^^^^^^^^^^^^^^^^^^^^^^^^^^^^^^^^^^^^^^^^^^^^^^^^^^^^^
  File "/opt/airflow/dags/user_airflow.py", line 127, in process_link
    result = run_selenium_job(link)
             ^^^^^^^^^^^^^^^^^^^^^^
  File "/opt/airflow/dags/user_airflow.py", line 65, in run_selenium_job
    functions_instance = User_Functions()
                       ^^^^^^^^^^^^^^^^
TypeError: User_Functions.__init__() missing 1 required positional argument: 'includesPosts'
[2024-06-26T07:41:03.863+0000] {taskinstance.py:562} DEBUG - Task Duration set to 3.641687
[2024-06-26T07:41:03.865+0000] {taskinstance.py:584} DEBUG - Clearing next_method and next_kwargs.
[2024-06-26T07:41:03.866+0000] {taskinstance.py:1206} INFO - Marking task as FAILED. dag_id=USER, task_id=process_link_0, run_id=manual__2024-06-26T07:40:55.337303+00:00, execution_date=20240626T074055, start_date=20240626T074100, end_date=20240626T074103
[2024-06-26T07:41:03.886+0000] {standard_task_runner.py:110} ERROR - Failed to execute job 532 for task process_link_0 (User_Functions.__init__() missing 1 required positional argument: 'includesPosts'; 2112)
[2024-06-26T07:41:03.932+0000] {local_task_job_runner.py:240} INFO - Task exited with return code 1
[2024-06-26T07:41:03.954+0000] {taskinstance.py:3503} INFO - 0 downstream tasks scheduled from follow-on schedule check
[2024-06-26T07:41:03.958+0000] {local_task_job_runner.py:222} INFO - ::endgroup::
