[2024-06-26T08:24:01.545+0000] {taskinstance.py:1042} DEBUG - previous_execution_date was called
[2024-06-26T08:24:01.585+0000] {taskinstance.py:1042} DEBUG - previous_execution_date was called
[2024-06-26T08:24:01.602+0000] {local_task_job_runner.py:120} INFO - ::group::Pre task execution logs
[2024-06-26T08:24:01.642+0000] {taskinstance.py:2076} INFO - Dependencies all met for dep_context=non-requeueable deps ti=<TaskInstance: Us.get_urls_task manual__2024-06-26T08:23:58.700860+00:00 [queued]>
[2024-06-26T08:24:01.653+0000] {taskinstance.py:2076} INFO - Dependencies all met for dep_context=requeueable deps ti=<TaskInstance: Us.get_urls_task manual__2024-06-26T08:23:58.700860+00:00 [queued]>
[2024-06-26T08:24:01.654+0000] {taskinstance.py:2306} INFO - Starting attempt 1 of 1
[2024-06-26T08:24:01.675+0000] {taskinstance.py:2330} INFO - Executing <Task(PythonOperator): get_urls_task> on 2024-06-26 08:23:58.700860+00:00
[2024-06-26T08:24:01.710+0000] {warnings.py:112} WARNING - /home/***/.local/lib/python3.12/site-packages/***/task/task_runner/standard_task_runner.py:61: DeprecationWarning: This process (pid=3369) is multi-threaded, use of fork() may lead to deadlocks in the child.
  pid = os.fork()

[2024-06-26T08:24:01.712+0000] {standard_task_runner.py:63} INFO - Started process 3370 to run task
[2024-06-26T08:24:01.712+0000] {standard_task_runner.py:90} INFO - Running: ['***', 'tasks', 'run', 'Us', 'get_urls_task', 'manual__2024-06-26T08:23:58.700860+00:00', '--job-id', '540', '--raw', '--subdir', 'DAGS_FOLDER/first_out.py', '--cfg-path', '/tmp/tmp1twdwyio']
[2024-06-26T08:24:01.715+0000] {standard_task_runner.py:91} INFO - Job 540: Subtask get_urls_task
[2024-06-26T08:24:01.773+0000] {taskinstance.py:1042} DEBUG - previous_execution_date was called
[2024-06-26T08:24:01.780+0000] {task_command.py:426} INFO - Running <TaskInstance: Us.get_urls_task manual__2024-06-26T08:23:58.700860+00:00 [running]> on host ccfa35e0da07
[2024-06-26T08:24:01.780+0000] {settings.py:363} DEBUG - Disposing DB connection pool (PID 3370)
[2024-06-26T08:24:01.781+0000] {settings.py:250} DEBUG - Setting up DB connection pool (PID 3370)
[2024-06-26T08:24:01.782+0000] {settings.py:298} DEBUG - settings.prepare_engine_args(): Using NullPool
[2024-06-26T08:24:01.843+0000] {taskinstance.py:1042} DEBUG - previous_execution_date was called
[2024-06-26T08:24:01.913+0000] {taskinstance.py:2648} INFO - Exporting env vars: AIRFLOW_CTX_DAG_OWNER='***' AIRFLOW_CTX_DAG_ID='Us' AIRFLOW_CTX_TASK_ID='get_urls_task' AIRFLOW_CTX_EXECUTION_DATE='2024-06-26T08:23:58.700860+00:00' AIRFLOW_CTX_TRY_NUMBER='1' AIRFLOW_CTX_DAG_RUN_ID='manual__2024-06-26T08:23:58.700860+00:00'
[2024-06-26T08:24:01.915+0000] {taskinstance.py:430} INFO - ::endgroup::
[2024-06-26T08:24:09.235+0000] {taskinstance.py:441} INFO - ::group::Post task execution logs
[2024-06-26T08:24:09.238+0000] {taskinstance.py:2905} ERROR - Task failed with exception
Traceback (most recent call last):
  File "/home/airflow/.local/lib/python3.12/site-packages/airflow/models/taskinstance.py", line 465, in _execute_task
    result = _execute_callable(context=context, **execute_callable_kwargs)
             ^^^^^^^^^^^^^^^^^^^^^^^^^^^^^^^^^^^^^^^^^^^^^^^^^^^^^^^^^^^^^
  File "/home/airflow/.local/lib/python3.12/site-packages/airflow/models/taskinstance.py", line 432, in _execute_callable
    return execute_callable(context=context, **execute_callable_kwargs)
           ^^^^^^^^^^^^^^^^^^^^^^^^^^^^^^^^^^^^^^^^^^^^^^^^^^^^^^^^^^^^
  File "/home/airflow/.local/lib/python3.12/site-packages/airflow/models/baseoperator.py", line 401, in wrapper
    return func(self, *args, **kwargs)
           ^^^^^^^^^^^^^^^^^^^^^^^^^^^
  File "/home/airflow/.local/lib/python3.12/site-packages/airflow/operators/python.py", line 235, in execute
    return_value = self.execute_callable()
                   ^^^^^^^^^^^^^^^^^^^^^^^
  File "/home/airflow/.local/lib/python3.12/site-packages/airflow/operators/python.py", line 252, in execute_callable
    return self.python_callable(*self.op_args, **self.op_kwargs)
           ^^^^^^^^^^^^^^^^^^^^^^^^^^^^^^^^^^^^^^^^^^^^^^^^^^^^^
  File "/opt/airflow/dags/first_out.py", line 32, in run_selenium_job
    page_id = functions_instance.get_id(link)
              ^^^^^^^^^^^^^^^^^^^^^^^^^^^^^^^
  File "/opt/airflow/dags/fun/fun_user.py", line 68, in get_id
    username_box = driver.find_element(By.ID, 'email')
                   ^^^^^^^^^^^^^^^^^^^^^^^^^^^^^^^^^^^
  File "/home/airflow/.local/lib/python3.12/site-packages/selenium/webdriver/remote/webdriver.py", line 741, in find_element
    return self.execute(Command.FIND_ELEMENT, {"using": by, "value": value})["value"]
           ^^^^^^^^^^^^^^^^^^^^^^^^^^^^^^^^^^^^^^^^^^^^^^^^^^^^^^^^^^^^^^^^^
  File "/home/airflow/.local/lib/python3.12/site-packages/selenium/webdriver/remote/webdriver.py", line 347, in execute
    self.error_handler.check_response(response)
  File "/home/airflow/.local/lib/python3.12/site-packages/selenium/webdriver/remote/errorhandler.py", line 229, in check_response
    raise exception_class(message, screen, stacktrace)
selenium.common.exceptions.NoSuchElementException: Message: no such element: Unable to locate element: {"method":"css selector","selector":"[id="email"]"}
  (Session info: chrome-headless-shell=126.0.6478.114); For documentation on this error, please visit: https://www.selenium.dev/documentation/webdriver/troubleshooting/errors#no-such-element-exception
Stacktrace:
#0 0x5609f24b88ae <unknown>
#1 0x5609f2189c57 <unknown>
#2 0x5609f21cff27 <unknown>
#3 0x5609f21d0001 <unknown>
#4 0x5609f2212a84 <unknown>
#5 0x5609f21f3b3d <unknown>
#6 0x5609f2210920 <unknown>
#7 0x5609f21f3893 <unknown>
#8 0x5609f21c42ed <unknown>
#9 0x5609f21c5092 <unknown>
#10 0x5609f2488256 <unknown>
#11 0x5609f248b5f9 <unknown>
#12 0x5609f248b0bf <unknown>
#13 0x5609f248ba75 <unknown>
#14 0x5609f247879f <unknown>
#15 0x5609f248bdc0 <unknown>
#16 0x5609f24616c6 <unknown>
#17 0x5609f24a8fb5 <unknown>
#18 0x5609f24a91a2 <unknown>
#19 0x5609f24b7d9a <unknown>
#20 0x7f55e076f134 <unknown>

[2024-06-26T08:24:09.301+0000] {taskinstance.py:562} DEBUG - Task Duration set to 7.658286
[2024-06-26T08:24:09.306+0000] {taskinstance.py:584} DEBUG - Clearing next_method and next_kwargs.
[2024-06-26T08:24:09.307+0000] {taskinstance.py:1206} INFO - Marking task as FAILED. dag_id=Us, task_id=get_urls_task, run_id=manual__2024-06-26T08:23:58.700860+00:00, execution_date=20240626T082358, start_date=20240626T082401, end_date=20240626T082409
[2024-06-26T08:24:09.337+0000] {standard_task_runner.py:110} ERROR - Failed to execute job 540 for task get_urls_task (Message: no such element: Unable to locate element: {"method":"css selector","selector":"[id="email"]"}
  (Session info: chrome-headless-shell=126.0.6478.114); For documentation on this error, please visit: https://www.selenium.dev/documentation/webdriver/troubleshooting/errors#no-such-element-exception
Stacktrace:
#0 0x5609f24b88ae <unknown>
#1 0x5609f2189c57 <unknown>
#2 0x5609f21cff27 <unknown>
#3 0x5609f21d0001 <unknown>
#4 0x5609f2212a84 <unknown>
#5 0x5609f21f3b3d <unknown>
#6 0x5609f2210920 <unknown>
#7 0x5609f21f3893 <unknown>
#8 0x5609f21c42ed <unknown>
#9 0x5609f21c5092 <unknown>
#10 0x5609f2488256 <unknown>
#11 0x5609f248b5f9 <unknown>
#12 0x5609f248b0bf <unknown>
#13 0x5609f248ba75 <unknown>
#14 0x5609f247879f <unknown>
#15 0x5609f248bdc0 <unknown>
#16 0x5609f24616c6 <unknown>
#17 0x5609f24a8fb5 <unknown>
#18 0x5609f24a91a2 <unknown>
#19 0x5609f24b7d9a <unknown>
#20 0x7f55e076f134 <unknown>
; 3370)
[2024-06-26T08:24:09.370+0000] {local_task_job_runner.py:240} INFO - Task exited with return code 1
[2024-06-26T08:24:09.389+0000] {taskinstance.py:3503} INFO - 0 downstream tasks scheduled from follow-on schedule check
[2024-06-26T08:24:09.392+0000] {local_task_job_runner.py:222} INFO - ::endgroup::
