[2024-06-26T08:16:27.810+0000] {taskinstance.py:1042} DEBUG - previous_execution_date was called
[2024-06-26T08:16:27.860+0000] {taskinstance.py:1042} DEBUG - previous_execution_date was called
[2024-06-26T08:16:27.874+0000] {local_task_job_runner.py:120} INFO - ::group::Pre task execution logs
[2024-06-26T08:16:27.924+0000] {taskinstance.py:2076} INFO - Dependencies all met for dep_context=non-requeueable deps ti=<TaskInstance: U.get_urls_task manual__2024-06-26T08:16:25.827378+00:00 [queued]>
[2024-06-26T08:16:27.935+0000] {taskinstance.py:2076} INFO - Dependencies all met for dep_context=requeueable deps ti=<TaskInstance: U.get_urls_task manual__2024-06-26T08:16:25.827378+00:00 [queued]>
[2024-06-26T08:16:27.936+0000] {taskinstance.py:2306} INFO - Starting attempt 1 of 1
[2024-06-26T08:16:27.963+0000] {taskinstance.py:2330} INFO - Executing <Task(PythonOperator): get_urls_task> on 2024-06-26 08:16:25.827378+00:00
[2024-06-26T08:16:27.970+0000] {warnings.py:112} WARNING - /home/***/.local/lib/python3.12/site-packages/***/task/task_runner/standard_task_runner.py:61: DeprecationWarning: This process (pid=3151) is multi-threaded, use of fork() may lead to deadlocks in the child.
  pid = os.fork()

[2024-06-26T08:16:27.972+0000] {standard_task_runner.py:63} INFO - Started process 3152 to run task
[2024-06-26T08:16:27.972+0000] {standard_task_runner.py:90} INFO - Running: ['***', 'tasks', 'run', 'U', 'get_urls_task', 'manual__2024-06-26T08:16:25.827378+00:00', '--job-id', '539', '--raw', '--subdir', 'DAGS_FOLDER/first_out.py', '--cfg-path', '/tmp/tmpjimxl2a9']
[2024-06-26T08:16:27.975+0000] {standard_task_runner.py:91} INFO - Job 539: Subtask get_urls_task
[2024-06-26T08:16:28.029+0000] {taskinstance.py:1042} DEBUG - previous_execution_date was called
[2024-06-26T08:16:28.036+0000] {task_command.py:426} INFO - Running <TaskInstance: U.get_urls_task manual__2024-06-26T08:16:25.827378+00:00 [running]> on host ccfa35e0da07
[2024-06-26T08:16:28.037+0000] {settings.py:363} DEBUG - Disposing DB connection pool (PID 3152)
[2024-06-26T08:16:28.038+0000] {settings.py:250} DEBUG - Setting up DB connection pool (PID 3152)
[2024-06-26T08:16:28.039+0000] {settings.py:298} DEBUG - settings.prepare_engine_args(): Using NullPool
[2024-06-26T08:16:28.092+0000] {taskinstance.py:1042} DEBUG - previous_execution_date was called
[2024-06-26T08:16:28.150+0000] {taskinstance.py:2648} INFO - Exporting env vars: AIRFLOW_CTX_DAG_OWNER='***' AIRFLOW_CTX_DAG_ID='U' AIRFLOW_CTX_TASK_ID='get_urls_task' AIRFLOW_CTX_EXECUTION_DATE='2024-06-26T08:16:25.827378+00:00' AIRFLOW_CTX_TRY_NUMBER='1' AIRFLOW_CTX_DAG_RUN_ID='manual__2024-06-26T08:16:25.827378+00:00'
[2024-06-26T08:16:28.152+0000] {taskinstance.py:430} INFO - ::endgroup::
[2024-06-26T08:16:40.367+0000] {fun_user.py:81} INFO - Found id: 00013963483849,
[2024-06-26T08:16:40.510+0000] {connectionpool.py:874} WARNING - Retrying (Retry(total=2, connect=None, read=None, redirect=None, status=None)) after connection broken by 'NewConnectionError('<urllib3.connection.HTTPConnection object at 0x7fab050af860>: Failed to establish a new connection: [Errno 111] Connection refused')': /session/2bbd9b0a6e94c103bc705d456b60b72e
[2024-06-26T08:16:40.513+0000] {connectionpool.py:874} WARNING - Retrying (Retry(total=1, connect=None, read=None, redirect=None, status=None)) after connection broken by 'NewConnectionError('<urllib3.connection.HTTPConnection object at 0x7fab050afd10>: Failed to establish a new connection: [Errno 111] Connection refused')': /session/2bbd9b0a6e94c103bc705d456b60b72e
[2024-06-26T08:16:40.514+0000] {connectionpool.py:874} WARNING - Retrying (Retry(total=0, connect=None, read=None, redirect=None, status=None)) after connection broken by 'NewConnectionError('<urllib3.connection.HTTPConnection object at 0x7fab05494110>: Failed to establish a new connection: [Errno 111] Connection refused')': /session/2bbd9b0a6e94c103bc705d456b60b72e
[2024-06-26T08:16:40.521+0000] {taskinstance.py:441} INFO - ::group::Post task execution logs
[2024-06-26T08:16:40.522+0000] {taskinstance.py:2905} ERROR - Task failed with exception
Traceback (most recent call last):
  File "/home/airflow/.local/lib/python3.12/site-packages/airflow/models/taskinstance.py", line 465, in _execute_task
    result = _execute_callable(context=context, **execute_callable_kwargs)
             ^^^^^^^^^^^^^^^^^^^^^^^^^^^^^^^^^^^^^^^^^^^^^^^^^^^^^^^^^^^^^
  File "/home/airflow/.local/lib/python3.12/site-packages/airflow/models/taskinstance.py", line 432, in _execute_callable
    return execute_callable(context=context, **execute_callable_kwargs)
           ^^^^^^^^^^^^^^^^^^^^^^^^^^^^^^^^^^^^^^^^^^^^^^^^^^^^^^^^^^^^
  File "/home/airflow/.local/lib/python3.12/site-packages/airflow/models/baseoperator.py", line 401, in wrapper
    return func(self, *args, **kwargs)
           ^^^^^^^^^^^^^^^^^^^^^^^^^^^
  File "/home/airflow/.local/lib/python3.12/site-packages/airflow/operators/python.py", line 235, in execute
    return_value = self.execute_callable()
                   ^^^^^^^^^^^^^^^^^^^^^^^
  File "/home/airflow/.local/lib/python3.12/site-packages/airflow/operators/python.py", line 252, in execute_callable
    return self.python_callable(*self.op_args, **self.op_kwargs)
           ^^^^^^^^^^^^^^^^^^^^^^^^^^^^^^^^^^^^^^^^^^^^^^^^^^^^^
  File "/opt/airflow/dags/first_out.py", line 33, in run_selenium_job
    result = functions_instance.get_all_data(driver,page_id, access_token)
             ^^^^^^^^^^^^^^^^^^^^^^^^^^^^^^^^^^^^^^^^^^^^^^^^^^^^^^^^^^^^^
TypeError: User_Functions.get_all_data() takes 3 positional arguments but 4 were given
[2024-06-26T08:16:40.547+0000] {taskinstance.py:562} DEBUG - Task Duration set to 12.622432
[2024-06-26T08:16:40.549+0000] {taskinstance.py:584} DEBUG - Clearing next_method and next_kwargs.
[2024-06-26T08:16:40.550+0000] {taskinstance.py:1206} INFO - Marking task as FAILED. dag_id=U, task_id=get_urls_task, run_id=manual__2024-06-26T08:16:25.827378+00:00, execution_date=20240626T081625, start_date=20240626T081627, end_date=20240626T081640
[2024-06-26T08:16:40.578+0000] {standard_task_runner.py:110} ERROR - Failed to execute job 539 for task get_urls_task (User_Functions.get_all_data() takes 3 positional arguments but 4 were given; 3152)
[2024-06-26T08:16:40.614+0000] {local_task_job_runner.py:240} INFO - Task exited with return code 1
[2024-06-26T08:16:40.632+0000] {taskinstance.py:3503} INFO - 0 downstream tasks scheduled from follow-on schedule check
[2024-06-26T08:16:40.638+0000] {local_task_job_runner.py:222} INFO - ::endgroup::
