[2024-06-28T03:09:20.602+0000] {taskinstance.py:1042} DEBUG - previous_execution_date was called
[2024-06-28T03:09:20.658+0000] {taskinstance.py:1042} DEBUG - previous_execution_date was called
[2024-06-28T03:09:20.676+0000] {local_task_job_runner.py:120} INFO - ::group::Pre task execution logs
[2024-06-28T03:09:20.723+0000] {taskinstance.py:2076} INFO - Dependencies all met for dep_context=non-requeueable deps ti=<TaskInstance: selenium_minio_.run_selenium_task manual__2024-06-28T03:09:18.931560+00:00 [queued]>
[2024-06-28T03:09:20.733+0000] {taskinstance.py:2076} INFO - Dependencies all met for dep_context=requeueable deps ti=<TaskInstance: selenium_minio_.run_selenium_task manual__2024-06-28T03:09:18.931560+00:00 [queued]>
[2024-06-28T03:09:20.735+0000] {taskinstance.py:2306} INFO - Starting attempt 1 of 1
[2024-06-28T03:09:20.755+0000] {taskinstance.py:2330} INFO - Executing <Task(PythonOperator): run_selenium_task> on 2024-06-28 03:09:18.931560+00:00
[2024-06-28T03:09:20.763+0000] {warnings.py:112} WARNING - /home/***/.local/lib/python3.12/site-packages/***/task/task_runner/standard_task_runner.py:61: DeprecationWarning: This process (pid=288) is multi-threaded, use of fork() may lead to deadlocks in the child.
  pid = os.fork()

[2024-06-28T03:09:20.766+0000] {standard_task_runner.py:63} INFO - Started process 289 to run task
[2024-06-28T03:09:20.765+0000] {standard_task_runner.py:90} INFO - Running: ['***', 'tasks', 'run', 'selenium_minio_', 'run_selenium_task', 'manual__2024-06-28T03:09:18.931560+00:00', '--job-id', '788', '--raw', '--subdir', 'DAGS_FOLDER/crawl_minio.py', '--cfg-path', '/tmp/tmpeo5xgs9c']
[2024-06-28T03:09:20.767+0000] {standard_task_runner.py:91} INFO - Job 788: Subtask run_selenium_task
[2024-06-28T03:09:20.826+0000] {taskinstance.py:1042} DEBUG - previous_execution_date was called
[2024-06-28T03:09:20.837+0000] {task_command.py:426} INFO - Running <TaskInstance: selenium_minio_.run_selenium_task manual__2024-06-28T03:09:18.931560+00:00 [running]> on host ccfa35e0da07
[2024-06-28T03:09:20.838+0000] {settings.py:363} DEBUG - Disposing DB connection pool (PID 289)
[2024-06-28T03:09:20.839+0000] {settings.py:250} DEBUG - Setting up DB connection pool (PID 289)
[2024-06-28T03:09:20.840+0000] {settings.py:298} DEBUG - settings.prepare_engine_args(): Using NullPool
[2024-06-28T03:09:20.899+0000] {taskinstance.py:1042} DEBUG - previous_execution_date was called
[2024-06-28T03:09:20.974+0000] {taskinstance.py:2648} INFO - Exporting env vars: AIRFLOW_CTX_DAG_OWNER='***' AIRFLOW_CTX_DAG_ID='selenium_minio_' AIRFLOW_CTX_TASK_ID='run_selenium_task' AIRFLOW_CTX_EXECUTION_DATE='2024-06-28T03:09:18.931560+00:00' AIRFLOW_CTX_TRY_NUMBER='1' AIRFLOW_CTX_DAG_RUN_ID='manual__2024-06-28T03:09:18.931560+00:00'
[2024-06-28T03:09:20.976+0000] {taskinstance.py:430} INFO - ::endgroup::
[2024-06-28T03:10:42.882+0000] {job.py:218} ERROR - Job heartbeat got an exception
Traceback (most recent call last):
  File "/home/airflow/.local/lib/python3.12/site-packages/sqlalchemy/engine/base.py", line 3371, in _wrap_pool_connect
    return fn()
           ^^^^
  File "/home/airflow/.local/lib/python3.12/site-packages/sqlalchemy/pool/base.py", line 327, in connect
    return _ConnectionFairy._checkout(self)
           ^^^^^^^^^^^^^^^^^^^^^^^^^^^^^^^^
  File "/home/airflow/.local/lib/python3.12/site-packages/sqlalchemy/pool/base.py", line 894, in _checkout
    fairy = _ConnectionRecord.checkout(pool)
            ^^^^^^^^^^^^^^^^^^^^^^^^^^^^^^^^
  File "/home/airflow/.local/lib/python3.12/site-packages/sqlalchemy/pool/base.py", line 493, in checkout
    rec = pool._do_get()
          ^^^^^^^^^^^^^^
  File "/home/airflow/.local/lib/python3.12/site-packages/sqlalchemy/pool/impl.py", line 256, in _do_get
    return self._create_connection()
           ^^^^^^^^^^^^^^^^^^^^^^^^^
  File "/home/airflow/.local/lib/python3.12/site-packages/sqlalchemy/pool/base.py", line 273, in _create_connection
    return _ConnectionRecord(self)
           ^^^^^^^^^^^^^^^^^^^^^^^
  File "/home/airflow/.local/lib/python3.12/site-packages/sqlalchemy/pool/base.py", line 388, in __init__
    self.__connect()
  File "/home/airflow/.local/lib/python3.12/site-packages/sqlalchemy/pool/base.py", line 690, in __connect
    with util.safe_reraise():
  File "/home/airflow/.local/lib/python3.12/site-packages/sqlalchemy/util/langhelpers.py", line 70, in __exit__
    compat.raise_(
  File "/home/airflow/.local/lib/python3.12/site-packages/sqlalchemy/util/compat.py", line 211, in raise_
    raise exception
  File "/home/airflow/.local/lib/python3.12/site-packages/sqlalchemy/pool/base.py", line 686, in __connect
    self.dbapi_connection = connection = pool._invoke_creator(self)
                                         ^^^^^^^^^^^^^^^^^^^^^^^^^^
  File "/home/airflow/.local/lib/python3.12/site-packages/sqlalchemy/engine/create.py", line 574, in connect
    return dialect.connect(*cargs, **cparams)
           ^^^^^^^^^^^^^^^^^^^^^^^^^^^^^^^^^^
  File "/home/airflow/.local/lib/python3.12/site-packages/sqlalchemy/engine/default.py", line 598, in connect
    return self.dbapi.connect(*cargs, **cparams)
           ^^^^^^^^^^^^^^^^^^^^^^^^^^^^^^^^^^^^^
  File "/home/airflow/.local/lib/python3.12/site-packages/psycopg2/__init__.py", line 122, in connect
    conn = _connect(dsn, connection_factory=connection_factory, **kwasync)
           ^^^^^^^^^^^^^^^^^^^^^^^^^^^^^^^^^^^^^^^^^^^^^^^^^^^^^^^^^^^^^^^
psycopg2.OperationalError: could not translate host name "postgres" to address: Temporary failure in name resolution


The above exception was the direct cause of the following exception:

Traceback (most recent call last):
  File "/home/airflow/.local/lib/python3.12/site-packages/airflow/jobs/job.py", line 192, in heartbeat
    self._merge_from(Job._fetch_from_db(self, session))
                     ^^^^^^^^^^^^^^^^^^^^^^^^^^^^^^^^^
  File "/home/airflow/.local/lib/python3.12/site-packages/airflow/api_internal/internal_api_call.py", line 115, in wrapper
    return func(*args, **kwargs)
           ^^^^^^^^^^^^^^^^^^^^^
  File "/home/airflow/.local/lib/python3.12/site-packages/airflow/utils/session.py", line 76, in wrapper
    return func(*args, **kwargs)
           ^^^^^^^^^^^^^^^^^^^^^
  File "/home/airflow/.local/lib/python3.12/site-packages/airflow/utils/retries.py", line 89, in wrapped_function
    for attempt in run_with_db_retries(max_retries=retries, logger=logger, **retry_kwargs):
  File "/home/airflow/.local/lib/python3.12/site-packages/tenacity/__init__.py", line 435, in __iter__
    do = self.iter(retry_state=retry_state)
         ^^^^^^^^^^^^^^^^^^^^^^^^^^^^^^^^^^
  File "/home/airflow/.local/lib/python3.12/site-packages/tenacity/__init__.py", line 368, in iter
    result = action(retry_state)
             ^^^^^^^^^^^^^^^^^^^
  File "/home/airflow/.local/lib/python3.12/site-packages/tenacity/__init__.py", line 410, in exc_check
    raise retry_exc.reraise()
          ^^^^^^^^^^^^^^^^^^^
  File "/home/airflow/.local/lib/python3.12/site-packages/tenacity/__init__.py", line 183, in reraise
    raise self.last_attempt.result()
          ^^^^^^^^^^^^^^^^^^^^^^^^^^
  File "/usr/local/lib/python3.12/concurrent/futures/_base.py", line 449, in result
    return self.__get_result()
           ^^^^^^^^^^^^^^^^^^^
  File "/usr/local/lib/python3.12/concurrent/futures/_base.py", line 401, in __get_result
    raise self._exception
  File "/home/airflow/.local/lib/python3.12/site-packages/airflow/utils/retries.py", line 98, in wrapped_function
    return func(*args, **kwargs)
           ^^^^^^^^^^^^^^^^^^^^^
  File "/home/airflow/.local/lib/python3.12/site-packages/airflow/jobs/job.py", line 316, in _fetch_from_db
    session.merge(job)
  File "/home/airflow/.local/lib/python3.12/site-packages/sqlalchemy/orm/session.py", line 3056, in merge
    return self._merge(
           ^^^^^^^^^^^^
  File "/home/airflow/.local/lib/python3.12/site-packages/sqlalchemy/orm/session.py", line 3136, in _merge
    merged = self.get(
             ^^^^^^^^^
  File "/home/airflow/.local/lib/python3.12/site-packages/sqlalchemy/orm/session.py", line 2853, in get
    return self._get_impl(
           ^^^^^^^^^^^^^^^
  File "/home/airflow/.local/lib/python3.12/site-packages/sqlalchemy/orm/session.py", line 2975, in _get_impl
    return db_load_fn(
           ^^^^^^^^^^^
  File "/home/airflow/.local/lib/python3.12/site-packages/sqlalchemy/orm/loading.py", line 530, in load_on_pk_identity
    session.execute(
  File "/home/airflow/.local/lib/python3.12/site-packages/sqlalchemy/orm/session.py", line 1716, in execute
    conn = self._connection_for_bind(bind)
           ^^^^^^^^^^^^^^^^^^^^^^^^^^^^^^^
  File "/home/airflow/.local/lib/python3.12/site-packages/sqlalchemy/orm/session.py", line 1555, in _connection_for_bind
    return self._transaction._connection_for_bind(
           ^^^^^^^^^^^^^^^^^^^^^^^^^^^^^^^^^^^^^^^
  File "/home/airflow/.local/lib/python3.12/site-packages/sqlalchemy/orm/session.py", line 750, in _connection_for_bind
    conn = bind.connect()
           ^^^^^^^^^^^^^^
  File "/home/airflow/.local/lib/python3.12/site-packages/sqlalchemy/future/engine.py", line 412, in connect
    return super(Engine, self).connect()
           ^^^^^^^^^^^^^^^^^^^^^^^^^^^^^
  File "/home/airflow/.local/lib/python3.12/site-packages/sqlalchemy/engine/base.py", line 3325, in connect
    return self._connection_cls(self, close_with_result=close_with_result)
           ^^^^^^^^^^^^^^^^^^^^^^^^^^^^^^^^^^^^^^^^^^^^^^^^^^^^^^^^^^^^^^^
  File "/home/airflow/.local/lib/python3.12/site-packages/sqlalchemy/engine/base.py", line 96, in __init__
    else engine.raw_connection()
         ^^^^^^^^^^^^^^^^^^^^^^^
  File "/home/airflow/.local/lib/python3.12/site-packages/sqlalchemy/engine/base.py", line 3404, in raw_connection
    return self._wrap_pool_connect(self.pool.connect, _connection)
           ^^^^^^^^^^^^^^^^^^^^^^^^^^^^^^^^^^^^^^^^^^^^^^^^^^^^^^^
  File "/home/airflow/.local/lib/python3.12/site-packages/sqlalchemy/engine/base.py", line 3374, in _wrap_pool_connect
    Connection._handle_dbapi_exception_noconnection(
  File "/home/airflow/.local/lib/python3.12/site-packages/sqlalchemy/engine/base.py", line 2208, in _handle_dbapi_exception_noconnection
    util.raise_(
  File "/home/airflow/.local/lib/python3.12/site-packages/sqlalchemy/util/compat.py", line 211, in raise_
    raise exception
  File "/home/airflow/.local/lib/python3.12/site-packages/sqlalchemy/engine/base.py", line 3371, in _wrap_pool_connect
    return fn()
           ^^^^
  File "/home/airflow/.local/lib/python3.12/site-packages/sqlalchemy/pool/base.py", line 327, in connect
    return _ConnectionFairy._checkout(self)
           ^^^^^^^^^^^^^^^^^^^^^^^^^^^^^^^^
  File "/home/airflow/.local/lib/python3.12/site-packages/sqlalchemy/pool/base.py", line 894, in _checkout
    fairy = _ConnectionRecord.checkout(pool)
            ^^^^^^^^^^^^^^^^^^^^^^^^^^^^^^^^
  File "/home/airflow/.local/lib/python3.12/site-packages/sqlalchemy/pool/base.py", line 493, in checkout
    rec = pool._do_get()
          ^^^^^^^^^^^^^^
  File "/home/airflow/.local/lib/python3.12/site-packages/sqlalchemy/pool/impl.py", line 256, in _do_get
    return self._create_connection()
           ^^^^^^^^^^^^^^^^^^^^^^^^^
  File "/home/airflow/.local/lib/python3.12/site-packages/sqlalchemy/pool/base.py", line 273, in _create_connection
    return _ConnectionRecord(self)
           ^^^^^^^^^^^^^^^^^^^^^^^
  File "/home/airflow/.local/lib/python3.12/site-packages/sqlalchemy/pool/base.py", line 388, in __init__
    self.__connect()
  File "/home/airflow/.local/lib/python3.12/site-packages/sqlalchemy/pool/base.py", line 690, in __connect
    with util.safe_reraise():
  File "/home/airflow/.local/lib/python3.12/site-packages/sqlalchemy/util/langhelpers.py", line 70, in __exit__
    compat.raise_(
  File "/home/airflow/.local/lib/python3.12/site-packages/sqlalchemy/util/compat.py", line 211, in raise_
    raise exception
  File "/home/airflow/.local/lib/python3.12/site-packages/sqlalchemy/pool/base.py", line 686, in __connect
    self.dbapi_connection = connection = pool._invoke_creator(self)
                                         ^^^^^^^^^^^^^^^^^^^^^^^^^^
  File "/home/airflow/.local/lib/python3.12/site-packages/sqlalchemy/engine/create.py", line 574, in connect
    return dialect.connect(*cargs, **cparams)
           ^^^^^^^^^^^^^^^^^^^^^^^^^^^^^^^^^^
  File "/home/airflow/.local/lib/python3.12/site-packages/sqlalchemy/engine/default.py", line 598, in connect
    return self.dbapi.connect(*cargs, **cparams)
           ^^^^^^^^^^^^^^^^^^^^^^^^^^^^^^^^^^^^^
  File "/home/airflow/.local/lib/python3.12/site-packages/psycopg2/__init__.py", line 122, in connect
    conn = _connect(dsn, connection_factory=connection_factory, **kwasync)
           ^^^^^^^^^^^^^^^^^^^^^^^^^^^^^^^^^^^^^^^^^^^^^^^^^^^^^^^^^^^^^^^
sqlalchemy.exc.OperationalError: (psycopg2.OperationalError) could not translate host name "postgres" to address: Temporary failure in name resolution

(Background on this error at: https://sqlalche.me/e/14/e3q8)
[2024-06-28T03:10:49.932+0000] {job.py:226} ERROR - Job heartbeat failed with error. Scheduler is in unhealthy state
[2024-06-28T03:11:28.525+0000] {job.py:226} ERROR - Job heartbeat failed with error. Scheduler is in unhealthy state
[2024-06-28T03:12:07.156+0000] {job.py:226} ERROR - Job heartbeat failed with error. Scheduler is in unhealthy state
[2024-06-28T03:12:43.993+0000] {job.py:226} ERROR - Job heartbeat failed with error. Scheduler is in unhealthy state
[2024-06-28T03:13:22.723+0000] {job.py:226} ERROR - Job heartbeat failed with error. Scheduler is in unhealthy state
[2024-06-28T03:14:01.873+0000] {job.py:226} ERROR - Job heartbeat failed with error. Scheduler is in unhealthy state
[2024-06-28T03:15:44.460+0000] {job.py:221} ERROR - Job heartbeat failed with error. Scheduler may go into unhealthy state
[2024-06-28T03:16:25.803+0000] {job.py:226} ERROR - Job heartbeat failed with error. Scheduler is in unhealthy state
[2024-06-28T03:17:31.550+0000] {job.py:226} ERROR - Job heartbeat failed with error. Scheduler is in unhealthy state
[2024-06-28T03:18:27.510+0000] {job.py:226} ERROR - Job heartbeat failed with error. Scheduler is in unhealthy state
[2024-06-28T03:19:08.978+0000] {job.py:226} ERROR - Job heartbeat failed with error. Scheduler is in unhealthy state
[2024-06-28T03:19:48.146+0000] {job.py:226} ERROR - Job heartbeat failed with error. Scheduler is in unhealthy state
[2024-06-28T03:20:26.216+0000] {job.py:226} ERROR - Job heartbeat failed with error. Scheduler is in unhealthy state
[2024-06-28T03:20:45.446+0000] {crawl_minio.py:48} ERROR - Error running Selenium job: Message: timeout: Timed out receiving message from renderer: 290.941
  (Session info: chrome-headless-shell=126.0.6478.114)
Stacktrace:
#0 0x5591491178ae <unknown>
#1 0x559148de8c57 <unknown>
#2 0x559148dd4913 <unknown>
#3 0x559148dd46e0 <unknown>
#4 0x559148dd2ba0 <unknown>
#5 0x559148dd30b9 <unknown>
#6 0x559148de0a14 <unknown>
#7 0x559148df3f6f <unknown>
#8 0x559148df868b <unknown>
#9 0x559148dd365b <unknown>
#10 0x559148df3d6d <unknown>
#11 0x559148e6fb22 <unknown>
#12 0x559148e52893 <unknown>
#13 0x559148e232ed <unknown>
#14 0x559148e24092 <unknown>
#15 0x5591490e7256 <unknown>
#16 0x5591490ea5f9 <unknown>
#17 0x5591490ea0bf <unknown>
#18 0x5591490eaa75 <unknown>
#19 0x5591490d779f <unknown>
#20 0x5591490eadc0 <unknown>
#21 0x5591490c06c6 <unknown>
#22 0x559149107fb5 <unknown>
#23 0x5591491081a2 <unknown>
#24 0x559149116d9a <unknown>
#25 0x7f9bde665134 <unknown>

[2024-06-28T03:20:53.198+0000] {taskinstance.py:441} INFO - ::group::Post task execution logs
[2024-06-28T03:20:53.486+0000] {taskinstance.py:2905} ERROR - Task failed with exception
Traceback (most recent call last):
  File "/home/airflow/.local/lib/python3.12/site-packages/airflow/models/taskinstance.py", line 465, in _execute_task
    result = _execute_callable(context=context, **execute_callable_kwargs)
             ^^^^^^^^^^^^^^^^^^^^^^^^^^^^^^^^^^^^^^^^^^^^^^^^^^^^^^^^^^^^^
  File "/home/airflow/.local/lib/python3.12/site-packages/airflow/models/taskinstance.py", line 432, in _execute_callable
    return execute_callable(context=context, **execute_callable_kwargs)
           ^^^^^^^^^^^^^^^^^^^^^^^^^^^^^^^^^^^^^^^^^^^^^^^^^^^^^^^^^^^^
  File "/home/airflow/.local/lib/python3.12/site-packages/airflow/models/baseoperator.py", line 401, in wrapper
    return func(self, *args, **kwargs)
           ^^^^^^^^^^^^^^^^^^^^^^^^^^^
  File "/home/airflow/.local/lib/python3.12/site-packages/airflow/operators/python.py", line 235, in execute
    return_value = self.execute_callable()
                   ^^^^^^^^^^^^^^^^^^^^^^^
  File "/home/airflow/.local/lib/python3.12/site-packages/airflow/operators/python.py", line 252, in execute_callable
    return self.python_callable(*self.op_args, **self.op_kwargs)
           ^^^^^^^^^^^^^^^^^^^^^^^^^^^^^^^^^^^^^^^^^^^^^^^^^^^^^
  File "/opt/airflow/dags/crawl_minio.py", line 40, in run_selenium_job
    result = functions_instance.get_all_data(driver, page_id, access_token)
             ^^^^^^^^^^^^^^^^^^^^^^^^^^^^^^^^^^^^^^^^^^^^^^^^^^^^^^^^^^^^^^
  File "/opt/airflow/dags/fun/fun_page.py", line 248, in get_all_data
    posts_dict = self.get_posts(driver, page_id, access_token)
                 ^^^^^^^^^^^^^^^^^^^^^^^^^^^^^^^^^^^^^^^^^^^^^
  File "/opt/airflow/dags/fun/fun_page.py", line 94, in get_posts
    driver.get(next_url)
  File "/home/airflow/.local/lib/python3.12/site-packages/selenium/webdriver/remote/webdriver.py", line 356, in get
    self.execute(Command.GET, {"url": url})
  File "/home/airflow/.local/lib/python3.12/site-packages/selenium/webdriver/remote/webdriver.py", line 347, in execute
    self.error_handler.check_response(response)
  File "/home/airflow/.local/lib/python3.12/site-packages/selenium/webdriver/remote/errorhandler.py", line 229, in check_response
    raise exception_class(message, screen, stacktrace)
selenium.common.exceptions.TimeoutException: Message: timeout: Timed out receiving message from renderer: 290.941
  (Session info: chrome-headless-shell=126.0.6478.114)
Stacktrace:
#0 0x5591491178ae <unknown>
#1 0x559148de8c57 <unknown>
#2 0x559148dd4913 <unknown>
#3 0x559148dd46e0 <unknown>
#4 0x559148dd2ba0 <unknown>
#5 0x559148dd30b9 <unknown>
#6 0x559148de0a14 <unknown>
#7 0x559148df3f6f <unknown>
#8 0x559148df868b <unknown>
#9 0x559148dd365b <unknown>
#10 0x559148df3d6d <unknown>
#11 0x559148e6fb22 <unknown>
#12 0x559148e52893 <unknown>
#13 0x559148e232ed <unknown>
#14 0x559148e24092 <unknown>
#15 0x5591490e7256 <unknown>
#16 0x5591490ea5f9 <unknown>
#17 0x5591490ea0bf <unknown>
#18 0x5591490eaa75 <unknown>
#19 0x5591490d779f <unknown>
#20 0x5591490eadc0 <unknown>
#21 0x5591490c06c6 <unknown>
#22 0x559149107fb5 <unknown>
#23 0x5591491081a2 <unknown>
#24 0x559149116d9a <unknown>
#25 0x7f9bde665134 <unknown>

[2024-06-28T03:20:56.436+0000] {taskinstance.py:562} DEBUG - Task Duration set to 695.710462
[2024-06-28T03:20:56.719+0000] {taskinstance.py:584} DEBUG - Clearing next_method and next_kwargs.
[2024-06-28T03:20:56.728+0000] {taskinstance.py:1206} INFO - Marking task as FAILED. dag_id=selenium_minio_, task_id=run_selenium_task, run_id=manual__2024-06-28T03:09:18.931560+00:00, execution_date=20240628T030918, start_date=20240628T030920, end_date=20240628T032056
[2024-06-28T03:20:57.192+0000] {standard_task_runner.py:110} ERROR - Failed to execute job 788 for task run_selenium_task (Message: timeout: Timed out receiving message from renderer: 290.941
  (Session info: chrome-headless-shell=126.0.6478.114)
Stacktrace:
#0 0x5591491178ae <unknown>
#1 0x559148de8c57 <unknown>
#2 0x559148dd4913 <unknown>
#3 0x559148dd46e0 <unknown>
#4 0x559148dd2ba0 <unknown>
#5 0x559148dd30b9 <unknown>
#6 0x559148de0a14 <unknown>
#7 0x559148df3f6f <unknown>
#8 0x559148df868b <unknown>
#9 0x559148dd365b <unknown>
#10 0x559148df3d6d <unknown>
#11 0x559148e6fb22 <unknown>
#12 0x559148e52893 <unknown>
#13 0x559148e232ed <unknown>
#14 0x559148e24092 <unknown>
#15 0x5591490e7256 <unknown>
#16 0x5591490ea5f9 <unknown>
#17 0x5591490ea0bf <unknown>
#18 0x5591490eaa75 <unknown>
#19 0x5591490d779f <unknown>
#20 0x5591490eadc0 <unknown>
#21 0x5591490c06c6 <unknown>
#22 0x559149107fb5 <unknown>
#23 0x5591491081a2 <unknown>
#24 0x559149116d9a <unknown>
#25 0x7f9bde665134 <unknown>
; 289)
[2024-06-28T03:20:57.357+0000] {local_task_job_runner.py:240} INFO - Task exited with return code 1
[2024-06-28T03:20:57.975+0000] {taskinstance.py:3503} INFO - 0 downstream tasks scheduled from follow-on schedule check
[2024-06-28T03:20:58.016+0000] {local_task_job_runner.py:222} INFO - ::endgroup::
