[2024-06-26T07:02:27.026+0000] {taskinstance.py:1042} DEBUG - previous_execution_date was called
[2024-06-26T07:02:27.097+0000] {taskinstance.py:1042} DEBUG - previous_execution_date was called
[2024-06-26T07:02:27.127+0000] {local_task_job_runner.py:120} INFO - ::group::Pre task execution logs
[2024-06-26T07:02:27.200+0000] {taskinstance.py:2076} INFO - Dependencies all met for dep_context=non-requeueable deps ti=<TaskInstance: selenium_minio_q.run_selenium_task manual__2024-06-26T07:02:24.018177+00:00 [queued]>
[2024-06-26T07:02:27.216+0000] {taskinstance.py:2076} INFO - Dependencies all met for dep_context=requeueable deps ti=<TaskInstance: selenium_minio_q.run_selenium_task manual__2024-06-26T07:02:24.018177+00:00 [queued]>
[2024-06-26T07:02:27.217+0000] {taskinstance.py:2306} INFO - Starting attempt 1 of 1
[2024-06-26T07:02:27.247+0000] {taskinstance.py:2330} INFO - Executing <Task(PythonOperator): run_selenium_task> on 2024-06-26 07:02:24.018177+00:00
[2024-06-26T07:02:27.257+0000] {warnings.py:112} WARNING - /home/***/.local/lib/python3.12/site-packages/***/task/task_runner/standard_task_runner.py:61: DeprecationWarning: This process (pid=1123) is multi-threaded, use of fork() may lead to deadlocks in the child.
  pid = os.fork()

[2024-06-26T07:02:27.259+0000] {standard_task_runner.py:63} INFO - Started process 1124 to run task
[2024-06-26T07:02:27.259+0000] {standard_task_runner.py:90} INFO - Running: ['***', 'tasks', 'run', 'selenium_minio_q', 'run_selenium_task', 'manual__2024-06-26T07:02:24.018177+00:00', '--job-id', '520', '--raw', '--subdir', 'DAGS_FOLDER/crawl_minio.py', '--cfg-path', '/tmp/tmpq8h0r_1o']
[2024-06-26T07:02:27.261+0000] {standard_task_runner.py:91} INFO - Job 520: Subtask run_selenium_task
[2024-06-26T07:02:27.351+0000] {taskinstance.py:1042} DEBUG - previous_execution_date was called
[2024-06-26T07:02:27.363+0000] {task_command.py:426} INFO - Running <TaskInstance: selenium_minio_q.run_selenium_task manual__2024-06-26T07:02:24.018177+00:00 [running]> on host ccfa35e0da07
[2024-06-26T07:02:27.364+0000] {settings.py:363} DEBUG - Disposing DB connection pool (PID 1124)
[2024-06-26T07:02:27.365+0000] {settings.py:250} DEBUG - Setting up DB connection pool (PID 1124)
[2024-06-26T07:02:27.366+0000] {settings.py:298} DEBUG - settings.prepare_engine_args(): Using NullPool
[2024-06-26T07:02:27.449+0000] {taskinstance.py:1042} DEBUG - previous_execution_date was called
[2024-06-26T07:02:27.574+0000] {taskinstance.py:2648} INFO - Exporting env vars: AIRFLOW_CTX_DAG_OWNER='***' AIRFLOW_CTX_DAG_ID='selenium_minio_q' AIRFLOW_CTX_TASK_ID='run_selenium_task' AIRFLOW_CTX_EXECUTION_DATE='2024-06-26T07:02:24.018177+00:00' AIRFLOW_CTX_TRY_NUMBER='1' AIRFLOW_CTX_DAG_RUN_ID='manual__2024-06-26T07:02:24.018177+00:00'
[2024-06-26T07:02:27.593+0000] {taskinstance.py:430} INFO - ::endgroup::
[2024-06-26T07:02:31.665+0000] {logging_mixin.py:188} INFO - ok
[2024-06-26T07:02:38.240+0000] {fun_page.py:109} INFO - getting another set
[2024-06-26T07:02:41.397+0000] {fun_page.py:109} INFO - getting another set
[2024-06-26T07:02:45.207+0000] {fun_page.py:109} INFO - getting another set
[2024-06-26T07:02:49.233+0000] {fun_page.py:109} INFO - getting another set
[2024-06-26T07:02:53.442+0000] {fun_page.py:109} INFO - getting another set
[2024-06-26T07:02:56.929+0000] {fun_page.py:109} INFO - getting another set
[2024-06-26T07:03:01.546+0000] {fun_page.py:109} INFO - getting another set
[2024-06-26T07:03:10.175+0000] {fun_page.py:109} INFO - getting another set
[2024-06-26T07:03:14.794+0000] {fun_page.py:109} INFO - getting another set
[2024-06-26T07:03:19.737+0000] {fun_page.py:109} INFO - getting another set
[2024-06-26T07:03:23.992+0000] {fun_page.py:109} INFO - getting another set
[2024-06-26T07:03:27.419+0000] {fun_page.py:109} INFO - getting another set
[2024-06-26T07:03:32.076+0000] {fun_page.py:109} INFO - getting another set
[2024-06-26T07:03:36.801+0000] {fun_page.py:109} INFO - getting another set
[2024-06-26T07:03:40.870+0000] {fun_page.py:109} INFO - getting another set
[2024-06-26T07:04:25.510+0000] {job.py:218} ERROR - Job heartbeat got an exception
Traceback (most recent call last):
  File "/home/airflow/.local/lib/python3.12/site-packages/sqlalchemy/engine/base.py", line 3371, in _wrap_pool_connect
    return fn()
           ^^^^
  File "/home/airflow/.local/lib/python3.12/site-packages/sqlalchemy/pool/base.py", line 327, in connect
    return _ConnectionFairy._checkout(self)
           ^^^^^^^^^^^^^^^^^^^^^^^^^^^^^^^^
  File "/home/airflow/.local/lib/python3.12/site-packages/sqlalchemy/pool/base.py", line 894, in _checkout
    fairy = _ConnectionRecord.checkout(pool)
            ^^^^^^^^^^^^^^^^^^^^^^^^^^^^^^^^
  File "/home/airflow/.local/lib/python3.12/site-packages/sqlalchemy/pool/base.py", line 493, in checkout
    rec = pool._do_get()
          ^^^^^^^^^^^^^^
  File "/home/airflow/.local/lib/python3.12/site-packages/sqlalchemy/pool/impl.py", line 256, in _do_get
    return self._create_connection()
           ^^^^^^^^^^^^^^^^^^^^^^^^^
  File "/home/airflow/.local/lib/python3.12/site-packages/sqlalchemy/pool/base.py", line 273, in _create_connection
    return _ConnectionRecord(self)
           ^^^^^^^^^^^^^^^^^^^^^^^
  File "/home/airflow/.local/lib/python3.12/site-packages/sqlalchemy/pool/base.py", line 388, in __init__
    self.__connect()
  File "/home/airflow/.local/lib/python3.12/site-packages/sqlalchemy/pool/base.py", line 690, in __connect
    with util.safe_reraise():
  File "/home/airflow/.local/lib/python3.12/site-packages/sqlalchemy/util/langhelpers.py", line 70, in __exit__
    compat.raise_(
  File "/home/airflow/.local/lib/python3.12/site-packages/sqlalchemy/util/compat.py", line 211, in raise_
    raise exception
  File "/home/airflow/.local/lib/python3.12/site-packages/sqlalchemy/pool/base.py", line 686, in __connect
    self.dbapi_connection = connection = pool._invoke_creator(self)
                                         ^^^^^^^^^^^^^^^^^^^^^^^^^^
  File "/home/airflow/.local/lib/python3.12/site-packages/sqlalchemy/engine/create.py", line 574, in connect
    return dialect.connect(*cargs, **cparams)
           ^^^^^^^^^^^^^^^^^^^^^^^^^^^^^^^^^^
  File "/home/airflow/.local/lib/python3.12/site-packages/sqlalchemy/engine/default.py", line 598, in connect
    return self.dbapi.connect(*cargs, **cparams)
           ^^^^^^^^^^^^^^^^^^^^^^^^^^^^^^^^^^^^^
  File "/home/airflow/.local/lib/python3.12/site-packages/psycopg2/__init__.py", line 122, in connect
    conn = _connect(dsn, connection_factory=connection_factory, **kwasync)
           ^^^^^^^^^^^^^^^^^^^^^^^^^^^^^^^^^^^^^^^^^^^^^^^^^^^^^^^^^^^^^^^
psycopg2.OperationalError: could not translate host name "postgres" to address: Temporary failure in name resolution


The above exception was the direct cause of the following exception:

Traceback (most recent call last):
  File "/home/airflow/.local/lib/python3.12/site-packages/airflow/jobs/job.py", line 192, in heartbeat
    self._merge_from(Job._fetch_from_db(self, session))
                     ^^^^^^^^^^^^^^^^^^^^^^^^^^^^^^^^^
  File "/home/airflow/.local/lib/python3.12/site-packages/airflow/api_internal/internal_api_call.py", line 115, in wrapper
    return func(*args, **kwargs)
           ^^^^^^^^^^^^^^^^^^^^^
  File "/home/airflow/.local/lib/python3.12/site-packages/airflow/utils/session.py", line 76, in wrapper
    return func(*args, **kwargs)
           ^^^^^^^^^^^^^^^^^^^^^
  File "/home/airflow/.local/lib/python3.12/site-packages/airflow/utils/retries.py", line 89, in wrapped_function
    for attempt in run_with_db_retries(max_retries=retries, logger=logger, **retry_kwargs):
  File "/home/airflow/.local/lib/python3.12/site-packages/tenacity/__init__.py", line 435, in __iter__
    do = self.iter(retry_state=retry_state)
         ^^^^^^^^^^^^^^^^^^^^^^^^^^^^^^^^^^
  File "/home/airflow/.local/lib/python3.12/site-packages/tenacity/__init__.py", line 368, in iter
    result = action(retry_state)
             ^^^^^^^^^^^^^^^^^^^
  File "/home/airflow/.local/lib/python3.12/site-packages/tenacity/__init__.py", line 410, in exc_check
    raise retry_exc.reraise()
          ^^^^^^^^^^^^^^^^^^^
  File "/home/airflow/.local/lib/python3.12/site-packages/tenacity/__init__.py", line 183, in reraise
    raise self.last_attempt.result()
          ^^^^^^^^^^^^^^^^^^^^^^^^^^
  File "/usr/local/lib/python3.12/concurrent/futures/_base.py", line 449, in result
    return self.__get_result()
           ^^^^^^^^^^^^^^^^^^^
  File "/usr/local/lib/python3.12/concurrent/futures/_base.py", line 401, in __get_result
    raise self._exception
  File "/home/airflow/.local/lib/python3.12/site-packages/airflow/utils/retries.py", line 98, in wrapped_function
    return func(*args, **kwargs)
           ^^^^^^^^^^^^^^^^^^^^^
  File "/home/airflow/.local/lib/python3.12/site-packages/airflow/jobs/job.py", line 316, in _fetch_from_db
    session.merge(job)
  File "/home/airflow/.local/lib/python3.12/site-packages/sqlalchemy/orm/session.py", line 3056, in merge
    return self._merge(
           ^^^^^^^^^^^^
  File "/home/airflow/.local/lib/python3.12/site-packages/sqlalchemy/orm/session.py", line 3136, in _merge
    merged = self.get(
             ^^^^^^^^^
  File "/home/airflow/.local/lib/python3.12/site-packages/sqlalchemy/orm/session.py", line 2853, in get
    return self._get_impl(
           ^^^^^^^^^^^^^^^
  File "/home/airflow/.local/lib/python3.12/site-packages/sqlalchemy/orm/session.py", line 2975, in _get_impl
    return db_load_fn(
           ^^^^^^^^^^^
  File "/home/airflow/.local/lib/python3.12/site-packages/sqlalchemy/orm/loading.py", line 530, in load_on_pk_identity
    session.execute(
  File "/home/airflow/.local/lib/python3.12/site-packages/sqlalchemy/orm/session.py", line 1716, in execute
    conn = self._connection_for_bind(bind)
           ^^^^^^^^^^^^^^^^^^^^^^^^^^^^^^^
  File "/home/airflow/.local/lib/python3.12/site-packages/sqlalchemy/orm/session.py", line 1555, in _connection_for_bind
    return self._transaction._connection_for_bind(
           ^^^^^^^^^^^^^^^^^^^^^^^^^^^^^^^^^^^^^^^
  File "/home/airflow/.local/lib/python3.12/site-packages/sqlalchemy/orm/session.py", line 750, in _connection_for_bind
    conn = bind.connect()
           ^^^^^^^^^^^^^^
  File "/home/airflow/.local/lib/python3.12/site-packages/sqlalchemy/future/engine.py", line 412, in connect
    return super(Engine, self).connect()
           ^^^^^^^^^^^^^^^^^^^^^^^^^^^^^
  File "/home/airflow/.local/lib/python3.12/site-packages/sqlalchemy/engine/base.py", line 3325, in connect
    return self._connection_cls(self, close_with_result=close_with_result)
           ^^^^^^^^^^^^^^^^^^^^^^^^^^^^^^^^^^^^^^^^^^^^^^^^^^^^^^^^^^^^^^^
  File "/home/airflow/.local/lib/python3.12/site-packages/sqlalchemy/engine/base.py", line 96, in __init__
    else engine.raw_connection()
         ^^^^^^^^^^^^^^^^^^^^^^^
  File "/home/airflow/.local/lib/python3.12/site-packages/sqlalchemy/engine/base.py", line 3404, in raw_connection
    return self._wrap_pool_connect(self.pool.connect, _connection)
           ^^^^^^^^^^^^^^^^^^^^^^^^^^^^^^^^^^^^^^^^^^^^^^^^^^^^^^^
  File "/home/airflow/.local/lib/python3.12/site-packages/sqlalchemy/engine/base.py", line 3374, in _wrap_pool_connect
    Connection._handle_dbapi_exception_noconnection(
  File "/home/airflow/.local/lib/python3.12/site-packages/sqlalchemy/engine/base.py", line 2208, in _handle_dbapi_exception_noconnection
    util.raise_(
  File "/home/airflow/.local/lib/python3.12/site-packages/sqlalchemy/util/compat.py", line 211, in raise_
    raise exception
  File "/home/airflow/.local/lib/python3.12/site-packages/sqlalchemy/engine/base.py", line 3371, in _wrap_pool_connect
    return fn()
           ^^^^
  File "/home/airflow/.local/lib/python3.12/site-packages/sqlalchemy/pool/base.py", line 327, in connect
    return _ConnectionFairy._checkout(self)
           ^^^^^^^^^^^^^^^^^^^^^^^^^^^^^^^^
  File "/home/airflow/.local/lib/python3.12/site-packages/sqlalchemy/pool/base.py", line 894, in _checkout
    fairy = _ConnectionRecord.checkout(pool)
            ^^^^^^^^^^^^^^^^^^^^^^^^^^^^^^^^
  File "/home/airflow/.local/lib/python3.12/site-packages/sqlalchemy/pool/base.py", line 493, in checkout
    rec = pool._do_get()
          ^^^^^^^^^^^^^^
  File "/home/airflow/.local/lib/python3.12/site-packages/sqlalchemy/pool/impl.py", line 256, in _do_get
    return self._create_connection()
           ^^^^^^^^^^^^^^^^^^^^^^^^^
  File "/home/airflow/.local/lib/python3.12/site-packages/sqlalchemy/pool/base.py", line 273, in _create_connection
    return _ConnectionRecord(self)
           ^^^^^^^^^^^^^^^^^^^^^^^
  File "/home/airflow/.local/lib/python3.12/site-packages/sqlalchemy/pool/base.py", line 388, in __init__
    self.__connect()
  File "/home/airflow/.local/lib/python3.12/site-packages/sqlalchemy/pool/base.py", line 690, in __connect
    with util.safe_reraise():
  File "/home/airflow/.local/lib/python3.12/site-packages/sqlalchemy/util/langhelpers.py", line 70, in __exit__
    compat.raise_(
  File "/home/airflow/.local/lib/python3.12/site-packages/sqlalchemy/util/compat.py", line 211, in raise_
    raise exception
  File "/home/airflow/.local/lib/python3.12/site-packages/sqlalchemy/pool/base.py", line 686, in __connect
    self.dbapi_connection = connection = pool._invoke_creator(self)
                                         ^^^^^^^^^^^^^^^^^^^^^^^^^^
  File "/home/airflow/.local/lib/python3.12/site-packages/sqlalchemy/engine/create.py", line 574, in connect
    return dialect.connect(*cargs, **cparams)
           ^^^^^^^^^^^^^^^^^^^^^^^^^^^^^^^^^^
  File "/home/airflow/.local/lib/python3.12/site-packages/sqlalchemy/engine/default.py", line 598, in connect
    return self.dbapi.connect(*cargs, **cparams)
           ^^^^^^^^^^^^^^^^^^^^^^^^^^^^^^^^^^^^^
  File "/home/airflow/.local/lib/python3.12/site-packages/psycopg2/__init__.py", line 122, in connect
    conn = _connect(dsn, connection_factory=connection_factory, **kwasync)
           ^^^^^^^^^^^^^^^^^^^^^^^^^^^^^^^^^^^^^^^^^^^^^^^^^^^^^^^^^^^^^^^
sqlalchemy.exc.OperationalError: (psycopg2.OperationalError) could not translate host name "postgres" to address: Temporary failure in name resolution

(Background on this error at: https://sqlalche.me/e/14/e3q8)
[2024-06-26T07:04:26.035+0000] {job.py:226} ERROR - Job heartbeat failed with error. Scheduler is in unhealthy state
[2024-06-26T07:04:41.343+0000] {fun_page.py:109} INFO - getting another set
[2024-06-26T07:04:49.286+0000] {fun_page.py:109} INFO - getting another set
[2024-06-26T07:04:55.549+0000] {fun_page.py:109} INFO - getting another set
[2024-06-26T07:05:01.485+0000] {fun_page.py:109} INFO - getting another set
[2024-06-26T07:05:07.519+0000] {fun_page.py:109} INFO - getting another set
[2024-06-26T07:05:14.528+0000] {fun_page.py:109} INFO - getting another set
[2024-06-26T07:05:20.782+0000] {fun_page.py:109} INFO - getting another set
[2024-06-26T07:05:23.926+0000] {fun_page.py:109} INFO - getting another set
[2024-06-26T07:05:29.531+0000] {fun_page.py:109} INFO - getting another set
[2024-06-26T07:05:32.992+0000] {fun_page.py:109} INFO - getting another set
[2024-06-26T07:05:37.904+0000] {fun_page.py:109} INFO - getting another set
[2024-06-26T07:05:43.457+0000] {fun_page.py:109} INFO - getting another set
[2024-06-26T07:05:48.581+0000] {fun_page.py:109} INFO - getting another set
[2024-06-26T07:05:56.787+0000] {fun_page.py:109} INFO - getting another set
[2024-06-26T07:06:00.148+0000] {fun_page.py:109} INFO - getting another set
[2024-06-26T07:06:04.095+0000] {fun_page.py:109} INFO - getting another set
[2024-06-26T07:06:08.609+0000] {fun_page.py:109} INFO - getting another set
[2024-06-26T07:06:13.641+0000] {fun_page.py:109} INFO - getting another set
[2024-06-26T07:06:17.771+0000] {fun_page.py:109} INFO - getting another set
[2024-06-26T07:06:26.768+0000] {fun_page.py:109} INFO - getting another set
[2024-06-26T07:06:35.210+0000] {fun_page.py:109} INFO - getting another set
[2024-06-26T07:06:40.896+0000] {fun_page.py:109} INFO - getting another set
[2024-06-26T07:06:46.079+0000] {fun_page.py:109} INFO - getting another set
[2024-06-26T07:06:51.511+0000] {fun_page.py:109} INFO - getting another set
[2024-06-26T07:06:58.203+0000] {fun_page.py:109} INFO - getting another set
[2024-06-26T07:07:04.929+0000] {fun_page.py:109} INFO - getting another set
[2024-06-26T07:07:09.131+0000] {fun_page.py:109} INFO - getting another set
[2024-06-26T07:07:17.747+0000] {fun_page.py:109} INFO - getting another set
[2024-06-26T07:07:21.732+0000] {fun_page.py:109} INFO - getting another set
[2024-06-26T07:07:26.736+0000] {fun_page.py:109} INFO - getting another set
[2024-06-26T07:07:30.301+0000] {fun_page.py:109} INFO - getting another set
[2024-06-26T07:07:34.979+0000] {fun_page.py:109} INFO - getting another set
[2024-06-26T07:07:38.598+0000] {fun_page.py:109} INFO - getting another set
[2024-06-26T07:07:51.213+0000] {fun_page.py:109} INFO - getting another set
[2024-06-26T07:07:56.304+0000] {fun_page.py:109} INFO - getting another set
[2024-06-26T07:08:00.948+0000] {fun_page.py:109} INFO - getting another set
[2024-06-26T07:08:05.745+0000] {fun_page.py:109} INFO - getting another set
[2024-06-26T07:08:11.516+0000] {fun_page.py:109} INFO - getting another set
[2024-06-26T07:08:16.409+0000] {fun_page.py:109} INFO - getting another set
[2024-06-26T07:08:22.412+0000] {fun_page.py:109} INFO - getting another set
[2024-06-26T07:08:33.261+0000] {fun_page.py:109} INFO - getting another set
[2024-06-26T07:08:42.183+0000] {fun_page.py:109} INFO - getting another set
[2024-06-26T07:08:46.805+0000] {fun_page.py:109} INFO - getting another set
[2024-06-26T07:08:53.816+0000] {fun_page.py:109} INFO - getting another set
[2024-06-26T07:09:35.207+0000] {job.py:226} ERROR - Job heartbeat failed with error. Scheduler is in unhealthy state
[2024-06-26T07:09:47.721+0000] {fun_page.py:109} INFO - getting another set
[2024-06-26T07:09:55.786+0000] {fun_page.py:109} INFO - getting another set
[2024-06-26T07:10:00.686+0000] {fun_page.py:109} INFO - getting another set
[2024-06-26T07:10:04.984+0000] {fun_page.py:109} INFO - getting another set
[2024-06-26T07:10:10.314+0000] {fun_page.py:109} INFO - getting another set
[2024-06-26T07:10:15.819+0000] {fun_page.py:109} INFO - getting another set
[2024-06-26T07:11:05.801+0000] {job.py:226} ERROR - Job heartbeat failed with error. Scheduler is in unhealthy state
[2024-06-26T07:12:04.769+0000] {job.py:226} ERROR - Job heartbeat failed with error. Scheduler is in unhealthy state
[2024-06-26T07:12:56.997+0000] {job.py:226} ERROR - Job heartbeat failed with error. Scheduler is in unhealthy state
[2024-06-26T07:13:51.313+0000] {job.py:226} ERROR - Job heartbeat failed with error. Scheduler is in unhealthy state
[2024-06-26T07:15:23.366+0000] {job.py:226} ERROR - Job heartbeat failed with error. Scheduler is in unhealthy state
[2024-06-26T07:15:33.308+0000] {local_task_job_runner.py:214} ERROR - Heartbeat time limit exceeded!
[2024-06-26T07:15:41.523+0000] {local_task_job_runner.py:222} INFO - ::endgroup::
[2024-06-26T07:16:05.269+0000] {process_utils.py:132} INFO - Sending 15 to group 1124. PIDs of all processes in the group: [1155, 1161, 1176, 1177, 1201, 1179, 1232, 1222, 1223, 1124]
[2024-06-26T07:16:07.846+0000] {process_utils.py:87} INFO - Sending the signal 15 to group 1124
[2024-06-26T07:16:09.464+0000] {process_utils.py:80} INFO - Process psutil.Process(pid=1179, status='terminated', started='07:02:28') (1179) terminated with exit code None
[2024-06-26T07:16:09.372+0000] {taskinstance.py:2611} ERROR - Received SIGTERM. Terminating subprocesses.
[2024-06-26T07:16:09.661+0000] {connectionpool.py:874} WARNING - Retrying (Retry(total=2, connect=None, read=None, redirect=None, status=None)) after connection broken by 'NewConnectionError('<urllib3.connection.HTTPConnection object at 0x7faaf57be300>: Failed to establish a new connection: [Errno 111] Connection refused')': /session/bde81194d439aaf21bd93e2921317d5d
[2024-06-26T07:16:09.672+0000] {connectionpool.py:874} WARNING - Retrying (Retry(total=1, connect=None, read=None, redirect=None, status=None)) after connection broken by 'NewConnectionError('<urllib3.connection.HTTPConnection object at 0x7faaf61ce510>: Failed to establish a new connection: [Errno 111] Connection refused')': /session/bde81194d439aaf21bd93e2921317d5d
[2024-06-26T07:16:09.725+0000] {connectionpool.py:874} WARNING - Retrying (Retry(total=0, connect=None, read=None, redirect=None, status=None)) after connection broken by 'NewConnectionError('<urllib3.connection.HTTPConnection object at 0x7faaf61ce660>: Failed to establish a new connection: [Errno 111] Connection refused')': /session/bde81194d439aaf21bd93e2921317d5d
[2024-06-26T07:16:09.928+0000] {process_utils.py:80} INFO - Process psutil.Process(pid=1232, status='terminated', started='07:02:29') (1232) terminated with exit code None
[2024-06-26T07:16:09.931+0000] {process_utils.py:80} INFO - Process psutil.Process(pid=1222, status='terminated', started='07:02:29') (1222) terminated with exit code None
[2024-06-26T07:16:09.933+0000] {process_utils.py:80} INFO - Process psutil.Process(pid=1223, status='terminated', started='07:02:29') (1223) terminated with exit code None
[2024-06-26T07:16:10.073+0000] {process_utils.py:80} INFO - Process psutil.Process(pid=1177, status='terminated', started='07:02:28') (1177) terminated with exit code None
[2024-06-26T07:16:10.317+0000] {process_utils.py:80} INFO - Process psutil.Process(pid=1201, status='terminated', started='07:02:28') (1201) terminated with exit code None
[2024-06-26T07:16:10.821+0000] {taskinstance.py:441} INFO - ::group::Post task execution logs
[2024-06-26T07:16:10.854+0000] {process_utils.py:80} INFO - Process psutil.Process(pid=1155, status='terminated', started='07:02:28') (1155) terminated with exit code None
[2024-06-26T07:16:12.300+0000] {taskinstance.py:2905} ERROR - Task failed with exception
Traceback (most recent call last):
  File "/home/airflow/.local/lib/python3.12/site-packages/airflow/models/taskinstance.py", line 465, in _execute_task
    result = _execute_callable(context=context, **execute_callable_kwargs)
             ^^^^^^^^^^^^^^^^^^^^^^^^^^^^^^^^^^^^^^^^^^^^^^^^^^^^^^^^^^^^^
  File "/home/airflow/.local/lib/python3.12/site-packages/airflow/models/taskinstance.py", line 432, in _execute_callable
    return execute_callable(context=context, **execute_callable_kwargs)
           ^^^^^^^^^^^^^^^^^^^^^^^^^^^^^^^^^^^^^^^^^^^^^^^^^^^^^^^^^^^^
  File "/home/airflow/.local/lib/python3.12/site-packages/airflow/models/baseoperator.py", line 401, in wrapper
    return func(self, *args, **kwargs)
           ^^^^^^^^^^^^^^^^^^^^^^^^^^^
  File "/home/airflow/.local/lib/python3.12/site-packages/airflow/operators/python.py", line 235, in execute
    return_value = self.execute_callable()
                   ^^^^^^^^^^^^^^^^^^^^^^^
  File "/home/airflow/.local/lib/python3.12/site-packages/airflow/operators/python.py", line 252, in execute_callable
    return self.python_callable(*self.op_args, **self.op_kwargs)
           ^^^^^^^^^^^^^^^^^^^^^^^^^^^^^^^^^^^^^^^^^^^^^^^^^^^^^
  File "/opt/airflow/dags/crawl_minio.py", line 40, in run_selenium_job
    result = functions_instance.get_all_data(driver, page_id, access_token)
             ^^^^^^^^^^^^^^^^^^^^^^^^^^^^^^^^^^^^^^^^^^^^^^^^^^^^^^^^^^^^^^
  File "/opt/airflow/dags/fun/fun_page.py", line 246, in get_all_data
    posts_dict = self.get_posts(driver, user_id, access_token)
                 ^^^^^^^^^^^^^^^^^^^^^^^^^^^^^^^^^^^^^^^^^^^^^
  File "/opt/airflow/dags/fun/fun_page.py", line 94, in get_posts
    driver.get(next_url)
  File "/home/airflow/.local/lib/python3.12/site-packages/selenium/webdriver/remote/webdriver.py", line 356, in get
    self.execute(Command.GET, {"url": url})
  File "/home/airflow/.local/lib/python3.12/site-packages/selenium/webdriver/remote/webdriver.py", line 345, in execute
    response = self.command_executor.execute(driver_command, params)
               ^^^^^^^^^^^^^^^^^^^^^^^^^^^^^^^^^^^^^^^^^^^^^^^^^^^^^
  File "/home/airflow/.local/lib/python3.12/site-packages/selenium/webdriver/remote/remote_connection.py", line 302, in execute
    return self._request(command_info[0], url, body=data)
           ^^^^^^^^^^^^^^^^^^^^^^^^^^^^^^^^^^^^^^^^^^^^^^
  File "/home/airflow/.local/lib/python3.12/site-packages/selenium/webdriver/remote/remote_connection.py", line 322, in _request
    response = self._conn.request(method, url, body=body, headers=headers)
               ^^^^^^^^^^^^^^^^^^^^^^^^^^^^^^^^^^^^^^^^^^^^^^^^^^^^^^^^^^^
  File "/home/airflow/.local/lib/python3.12/site-packages/urllib3/_request_methods.py", line 144, in request
    return self.request_encode_body(
           ^^^^^^^^^^^^^^^^^^^^^^^^^
  File "/home/airflow/.local/lib/python3.12/site-packages/urllib3/_request_methods.py", line 279, in request_encode_body
    return self.urlopen(method, url, **extra_kw)
           ^^^^^^^^^^^^^^^^^^^^^^^^^^^^^^^^^^^^^
  File "/home/airflow/.local/lib/python3.12/site-packages/urllib3/poolmanager.py", line 444, in urlopen
    response = conn.urlopen(method, u.request_uri, **kw)
               ^^^^^^^^^^^^^^^^^^^^^^^^^^^^^^^^^^^^^^^^^
  File "/home/airflow/.local/lib/python3.12/site-packages/urllib3/connectionpool.py", line 793, in urlopen
    response = self._make_request(
               ^^^^^^^^^^^^^^^^^^^
  File "/home/airflow/.local/lib/python3.12/site-packages/urllib3/connectionpool.py", line 537, in _make_request
    response = conn.getresponse()
               ^^^^^^^^^^^^^^^^^^
  File "/home/airflow/.local/lib/python3.12/site-packages/urllib3/connection.py", line 466, in getresponse
    httplib_response = super().getresponse()
                       ^^^^^^^^^^^^^^^^^^^^^
  File "/usr/local/lib/python3.12/http/client.py", line 1428, in getresponse
    response.begin()
  File "/usr/local/lib/python3.12/http/client.py", line 331, in begin
    version, status, reason = self._read_status()
                              ^^^^^^^^^^^^^^^^^^^
  File "/usr/local/lib/python3.12/http/client.py", line 292, in _read_status
    line = str(self.fp.readline(_MAXLINE + 1), "iso-8859-1")
               ^^^^^^^^^^^^^^^^^^^^^^^^^^^^^^
  File "/usr/local/lib/python3.12/socket.py", line 708, in readinto
    return self._sock.recv_into(b)
           ^^^^^^^^^^^^^^^^^^^^^^^
  File "/home/airflow/.local/lib/python3.12/site-packages/airflow/models/taskinstance.py", line 2613, in signal_handler
    raise AirflowTaskTerminated("Task received SIGTERM signal")
airflow.exceptions.AirflowTaskTerminated: Task received SIGTERM signal
[2024-06-26T07:16:12.537+0000] {taskinstance.py:562} DEBUG - Task Duration set to 825.333531
[2024-06-26T07:16:12.732+0000] {taskinstance.py:584} DEBUG - Clearing next_method and next_kwargs.
[2024-06-26T07:16:12.743+0000] {taskinstance.py:1206} INFO - Marking task as FAILED. dag_id=selenium_minio_q, task_id=run_selenium_task, run_id=manual__2024-06-26T07:02:24.018177+00:00, execution_date=20240626T070224, start_date=20240626T070227, end_date=20240626T071612
[2024-06-26T07:16:13.796+0000] {process_utils.py:80} INFO - Process psutil.Process(pid=1124, status='terminated', exitcode=2, started='07:02:26') (1124) terminated with exit code 2
[2024-06-26T07:16:16.670+0000] {process_utils.py:80} INFO - Process psutil.Process(pid=1161, status='terminated', started='07:02:28') (1161) terminated with exit code None
[2024-06-26T07:16:16.674+0000] {process_utils.py:80} INFO - Process psutil.Process(pid=1176, status='terminated', started='07:02:28') (1176) terminated with exit code None
