[2024-06-28T02:35:10.515+0000] {taskinstance.py:1042} DEBUG - previous_execution_date was called
[2024-06-28T02:35:10.582+0000] {taskinstance.py:1042} DEBUG - previous_execution_date was called
[2024-06-28T02:35:10.620+0000] {local_task_job_runner.py:120} INFO - ::group::Pre task execution logs
[2024-06-28T02:35:10.695+0000] {taskinstance.py:2076} INFO - Dependencies all met for dep_context=non-requeueable deps ti=<TaskInstance: USER1.process_link_0 manual__2024-06-28T01:37:52.831588+00:00 [queued]>
[2024-06-28T02:35:10.715+0000] {taskinstance.py:2076} INFO - Dependencies all met for dep_context=requeueable deps ti=<TaskInstance: USER1.process_link_0 manual__2024-06-28T01:37:52.831588+00:00 [queued]>
[2024-06-28T02:35:10.716+0000] {taskinstance.py:2306} INFO - Starting attempt 2 of 2
[2024-06-28T02:35:10.744+0000] {taskinstance.py:2330} INFO - Executing <Task(PythonOperator): process_link_0> on 2024-06-28 01:37:52.831588+00:00
[2024-06-28T02:35:10.756+0000] {warnings.py:112} WARNING - /home/***/.local/lib/python3.12/site-packages/***/task/task_runner/standard_task_runner.py:61: DeprecationWarning: This process (pid=970) is multi-threaded, use of fork() may lead to deadlocks in the child.
  pid = os.fork()

[2024-06-28T02:35:10.758+0000] {standard_task_runner.py:90} INFO - Running: ['***', 'tasks', 'run', 'USER1', 'process_link_0', 'manual__2024-06-28T01:37:52.831588+00:00', '--job-id', '781', '--raw', '--subdir', 'DAGS_FOLDER/user_***.py', '--cfg-path', '/tmp/tmpg9c2n0q8']
[2024-06-28T02:35:10.759+0000] {standard_task_runner.py:63} INFO - Started process 973 to run task
[2024-06-28T02:35:10.760+0000] {standard_task_runner.py:91} INFO - Job 781: Subtask process_link_0
[2024-06-28T02:35:10.826+0000] {taskinstance.py:1042} DEBUG - previous_execution_date was called
[2024-06-28T02:35:10.834+0000] {task_command.py:426} INFO - Running <TaskInstance: USER1.process_link_0 manual__2024-06-28T01:37:52.831588+00:00 [running]> on host ccfa35e0da07
[2024-06-28T02:35:10.835+0000] {settings.py:363} DEBUG - Disposing DB connection pool (PID 973)
[2024-06-28T02:35:10.836+0000] {settings.py:250} DEBUG - Setting up DB connection pool (PID 973)
[2024-06-28T02:35:10.837+0000] {settings.py:298} DEBUG - settings.prepare_engine_args(): Using NullPool
[2024-06-28T02:35:10.889+0000] {taskinstance.py:1042} DEBUG - previous_execution_date was called
[2024-06-28T02:35:10.979+0000] {taskinstance.py:2648} INFO - Exporting env vars: AIRFLOW_CTX_DAG_OWNER='***' AIRFLOW_CTX_DAG_ID='USER1' AIRFLOW_CTX_TASK_ID='process_link_0' AIRFLOW_CTX_EXECUTION_DATE='2024-06-28T01:37:52.831588+00:00' AIRFLOW_CTX_TRY_NUMBER='2' AIRFLOW_CTX_DAG_RUN_ID='manual__2024-06-28T01:37:52.831588+00:00'
[2024-06-28T02:35:10.984+0000] {taskinstance.py:430} INFO - ::endgroup::
[2024-06-28T02:35:13.138+0000] {connectionpool.py:244} DEBUG - Starting new HTTP connection (1): localhost:54039
[2024-06-28T02:35:19.336+0000] {connectionpool.py:549} DEBUG - http://localhost:54039 "POST /session HTTP/1.1" 200 0
[2024-06-28T02:35:58.630+0000] {job.py:218} ERROR - Job heartbeat got an exception
Traceback (most recent call last):
  File "/home/airflow/.local/lib/python3.12/site-packages/sqlalchemy/engine/base.py", line 3371, in _wrap_pool_connect
    return fn()
           ^^^^
  File "/home/airflow/.local/lib/python3.12/site-packages/sqlalchemy/pool/base.py", line 327, in connect
    return _ConnectionFairy._checkout(self)
           ^^^^^^^^^^^^^^^^^^^^^^^^^^^^^^^^
  File "/home/airflow/.local/lib/python3.12/site-packages/sqlalchemy/pool/base.py", line 894, in _checkout
    fairy = _ConnectionRecord.checkout(pool)
            ^^^^^^^^^^^^^^^^^^^^^^^^^^^^^^^^
  File "/home/airflow/.local/lib/python3.12/site-packages/sqlalchemy/pool/base.py", line 493, in checkout
    rec = pool._do_get()
          ^^^^^^^^^^^^^^
  File "/home/airflow/.local/lib/python3.12/site-packages/sqlalchemy/pool/impl.py", line 256, in _do_get
    return self._create_connection()
           ^^^^^^^^^^^^^^^^^^^^^^^^^
  File "/home/airflow/.local/lib/python3.12/site-packages/sqlalchemy/pool/base.py", line 273, in _create_connection
    return _ConnectionRecord(self)
           ^^^^^^^^^^^^^^^^^^^^^^^
  File "/home/airflow/.local/lib/python3.12/site-packages/sqlalchemy/pool/base.py", line 388, in __init__
    self.__connect()
  File "/home/airflow/.local/lib/python3.12/site-packages/sqlalchemy/pool/base.py", line 690, in __connect
    with util.safe_reraise():
  File "/home/airflow/.local/lib/python3.12/site-packages/sqlalchemy/util/langhelpers.py", line 70, in __exit__
    compat.raise_(
  File "/home/airflow/.local/lib/python3.12/site-packages/sqlalchemy/util/compat.py", line 211, in raise_
    raise exception
  File "/home/airflow/.local/lib/python3.12/site-packages/sqlalchemy/pool/base.py", line 686, in __connect
    self.dbapi_connection = connection = pool._invoke_creator(self)
                                         ^^^^^^^^^^^^^^^^^^^^^^^^^^
  File "/home/airflow/.local/lib/python3.12/site-packages/sqlalchemy/engine/create.py", line 574, in connect
    return dialect.connect(*cargs, **cparams)
           ^^^^^^^^^^^^^^^^^^^^^^^^^^^^^^^^^^
  File "/home/airflow/.local/lib/python3.12/site-packages/sqlalchemy/engine/default.py", line 598, in connect
    return self.dbapi.connect(*cargs, **cparams)
           ^^^^^^^^^^^^^^^^^^^^^^^^^^^^^^^^^^^^^
  File "/home/airflow/.local/lib/python3.12/site-packages/psycopg2/__init__.py", line 122, in connect
    conn = _connect(dsn, connection_factory=connection_factory, **kwasync)
           ^^^^^^^^^^^^^^^^^^^^^^^^^^^^^^^^^^^^^^^^^^^^^^^^^^^^^^^^^^^^^^^
psycopg2.OperationalError: could not translate host name "postgres" to address: Temporary failure in name resolution


The above exception was the direct cause of the following exception:

Traceback (most recent call last):
  File "/home/airflow/.local/lib/python3.12/site-packages/airflow/jobs/job.py", line 192, in heartbeat
    self._merge_from(Job._fetch_from_db(self, session))
                     ^^^^^^^^^^^^^^^^^^^^^^^^^^^^^^^^^
  File "/home/airflow/.local/lib/python3.12/site-packages/airflow/api_internal/internal_api_call.py", line 115, in wrapper
    return func(*args, **kwargs)
           ^^^^^^^^^^^^^^^^^^^^^
  File "/home/airflow/.local/lib/python3.12/site-packages/airflow/utils/session.py", line 76, in wrapper
    return func(*args, **kwargs)
           ^^^^^^^^^^^^^^^^^^^^^
  File "/home/airflow/.local/lib/python3.12/site-packages/airflow/utils/retries.py", line 89, in wrapped_function
    for attempt in run_with_db_retries(max_retries=retries, logger=logger, **retry_kwargs):
  File "/home/airflow/.local/lib/python3.12/site-packages/tenacity/__init__.py", line 435, in __iter__
    do = self.iter(retry_state=retry_state)
         ^^^^^^^^^^^^^^^^^^^^^^^^^^^^^^^^^^
  File "/home/airflow/.local/lib/python3.12/site-packages/tenacity/__init__.py", line 368, in iter
    result = action(retry_state)
             ^^^^^^^^^^^^^^^^^^^
  File "/home/airflow/.local/lib/python3.12/site-packages/tenacity/__init__.py", line 410, in exc_check
    raise retry_exc.reraise()
          ^^^^^^^^^^^^^^^^^^^
  File "/home/airflow/.local/lib/python3.12/site-packages/tenacity/__init__.py", line 183, in reraise
    raise self.last_attempt.result()
          ^^^^^^^^^^^^^^^^^^^^^^^^^^
  File "/usr/local/lib/python3.12/concurrent/futures/_base.py", line 449, in result
    return self.__get_result()
           ^^^^^^^^^^^^^^^^^^^
  File "/usr/local/lib/python3.12/concurrent/futures/_base.py", line 401, in __get_result
    raise self._exception
  File "/home/airflow/.local/lib/python3.12/site-packages/airflow/utils/retries.py", line 98, in wrapped_function
    return func(*args, **kwargs)
           ^^^^^^^^^^^^^^^^^^^^^
  File "/home/airflow/.local/lib/python3.12/site-packages/airflow/jobs/job.py", line 316, in _fetch_from_db
    session.merge(job)
  File "/home/airflow/.local/lib/python3.12/site-packages/sqlalchemy/orm/session.py", line 3056, in merge
    return self._merge(
           ^^^^^^^^^^^^
  File "/home/airflow/.local/lib/python3.12/site-packages/sqlalchemy/orm/session.py", line 3136, in _merge
    merged = self.get(
             ^^^^^^^^^
  File "/home/airflow/.local/lib/python3.12/site-packages/sqlalchemy/orm/session.py", line 2853, in get
    return self._get_impl(
           ^^^^^^^^^^^^^^^
  File "/home/airflow/.local/lib/python3.12/site-packages/sqlalchemy/orm/session.py", line 2975, in _get_impl
    return db_load_fn(
           ^^^^^^^^^^^
  File "/home/airflow/.local/lib/python3.12/site-packages/sqlalchemy/orm/loading.py", line 530, in load_on_pk_identity
    session.execute(
  File "/home/airflow/.local/lib/python3.12/site-packages/sqlalchemy/orm/session.py", line 1716, in execute
    conn = self._connection_for_bind(bind)
           ^^^^^^^^^^^^^^^^^^^^^^^^^^^^^^^
  File "/home/airflow/.local/lib/python3.12/site-packages/sqlalchemy/orm/session.py", line 1555, in _connection_for_bind
    return self._transaction._connection_for_bind(
           ^^^^^^^^^^^^^^^^^^^^^^^^^^^^^^^^^^^^^^^
  File "/home/airflow/.local/lib/python3.12/site-packages/sqlalchemy/orm/session.py", line 750, in _connection_for_bind
    conn = bind.connect()
           ^^^^^^^^^^^^^^
  File "/home/airflow/.local/lib/python3.12/site-packages/sqlalchemy/future/engine.py", line 412, in connect
    return super(Engine, self).connect()
           ^^^^^^^^^^^^^^^^^^^^^^^^^^^^^
  File "/home/airflow/.local/lib/python3.12/site-packages/sqlalchemy/engine/base.py", line 3325, in connect
    return self._connection_cls(self, close_with_result=close_with_result)
           ^^^^^^^^^^^^^^^^^^^^^^^^^^^^^^^^^^^^^^^^^^^^^^^^^^^^^^^^^^^^^^^
  File "/home/airflow/.local/lib/python3.12/site-packages/sqlalchemy/engine/base.py", line 96, in __init__
    else engine.raw_connection()
         ^^^^^^^^^^^^^^^^^^^^^^^
  File "/home/airflow/.local/lib/python3.12/site-packages/sqlalchemy/engine/base.py", line 3404, in raw_connection
    return self._wrap_pool_connect(self.pool.connect, _connection)
           ^^^^^^^^^^^^^^^^^^^^^^^^^^^^^^^^^^^^^^^^^^^^^^^^^^^^^^^
  File "/home/airflow/.local/lib/python3.12/site-packages/sqlalchemy/engine/base.py", line 3374, in _wrap_pool_connect
    Connection._handle_dbapi_exception_noconnection(
  File "/home/airflow/.local/lib/python3.12/site-packages/sqlalchemy/engine/base.py", line 2208, in _handle_dbapi_exception_noconnection
    util.raise_(
  File "/home/airflow/.local/lib/python3.12/site-packages/sqlalchemy/util/compat.py", line 211, in raise_
    raise exception
  File "/home/airflow/.local/lib/python3.12/site-packages/sqlalchemy/engine/base.py", line 3371, in _wrap_pool_connect
    return fn()
           ^^^^
  File "/home/airflow/.local/lib/python3.12/site-packages/sqlalchemy/pool/base.py", line 327, in connect
    return _ConnectionFairy._checkout(self)
           ^^^^^^^^^^^^^^^^^^^^^^^^^^^^^^^^
  File "/home/airflow/.local/lib/python3.12/site-packages/sqlalchemy/pool/base.py", line 894, in _checkout
    fairy = _ConnectionRecord.checkout(pool)
            ^^^^^^^^^^^^^^^^^^^^^^^^^^^^^^^^
  File "/home/airflow/.local/lib/python3.12/site-packages/sqlalchemy/pool/base.py", line 493, in checkout
    rec = pool._do_get()
          ^^^^^^^^^^^^^^
  File "/home/airflow/.local/lib/python3.12/site-packages/sqlalchemy/pool/impl.py", line 256, in _do_get
    return self._create_connection()
           ^^^^^^^^^^^^^^^^^^^^^^^^^
  File "/home/airflow/.local/lib/python3.12/site-packages/sqlalchemy/pool/base.py", line 273, in _create_connection
    return _ConnectionRecord(self)
           ^^^^^^^^^^^^^^^^^^^^^^^
  File "/home/airflow/.local/lib/python3.12/site-packages/sqlalchemy/pool/base.py", line 388, in __init__
    self.__connect()
  File "/home/airflow/.local/lib/python3.12/site-packages/sqlalchemy/pool/base.py", line 690, in __connect
    with util.safe_reraise():
  File "/home/airflow/.local/lib/python3.12/site-packages/sqlalchemy/util/langhelpers.py", line 70, in __exit__
    compat.raise_(
  File "/home/airflow/.local/lib/python3.12/site-packages/sqlalchemy/util/compat.py", line 211, in raise_
    raise exception
  File "/home/airflow/.local/lib/python3.12/site-packages/sqlalchemy/pool/base.py", line 686, in __connect
    self.dbapi_connection = connection = pool._invoke_creator(self)
                                         ^^^^^^^^^^^^^^^^^^^^^^^^^^
  File "/home/airflow/.local/lib/python3.12/site-packages/sqlalchemy/engine/create.py", line 574, in connect
    return dialect.connect(*cargs, **cparams)
           ^^^^^^^^^^^^^^^^^^^^^^^^^^^^^^^^^^
  File "/home/airflow/.local/lib/python3.12/site-packages/sqlalchemy/engine/default.py", line 598, in connect
    return self.dbapi.connect(*cargs, **cparams)
           ^^^^^^^^^^^^^^^^^^^^^^^^^^^^^^^^^^^^^
  File "/home/airflow/.local/lib/python3.12/site-packages/psycopg2/__init__.py", line 122, in connect
    conn = _connect(dsn, connection_factory=connection_factory, **kwasync)
           ^^^^^^^^^^^^^^^^^^^^^^^^^^^^^^^^^^^^^^^^^^^^^^^^^^^^^^^^^^^^^^^
sqlalchemy.exc.OperationalError: (psycopg2.OperationalError) could not translate host name "postgres" to address: Temporary failure in name resolution

(Background on this error at: https://sqlalche.me/e/14/e3q8)
[2024-06-28T02:36:00.910+0000] {job.py:226} ERROR - Job heartbeat failed with error. Scheduler is in unhealthy state
[2024-06-28T02:36:19.448+0000] {connectionpool.py:549} DEBUG - http://localhost:54039 "POST /session/fc6ef6035b0d699760b2c638988963db/url HTTP/1.1" 500 0
[2024-06-28T02:36:19.517+0000] {taskinstance.py:441} INFO - ::group::Post task execution logs
[2024-06-28T02:36:19.556+0000] {taskinstance.py:2905} ERROR - Task failed with exception
Traceback (most recent call last):
  File "/home/airflow/.local/lib/python3.12/site-packages/airflow/models/taskinstance.py", line 465, in _execute_task
    result = _execute_callable(context=context, **execute_callable_kwargs)
             ^^^^^^^^^^^^^^^^^^^^^^^^^^^^^^^^^^^^^^^^^^^^^^^^^^^^^^^^^^^^^
  File "/home/airflow/.local/lib/python3.12/site-packages/airflow/models/taskinstance.py", line 432, in _execute_callable
    return execute_callable(context=context, **execute_callable_kwargs)
           ^^^^^^^^^^^^^^^^^^^^^^^^^^^^^^^^^^^^^^^^^^^^^^^^^^^^^^^^^^^^
  File "/home/airflow/.local/lib/python3.12/site-packages/airflow/models/baseoperator.py", line 401, in wrapper
    return func(self, *args, **kwargs)
           ^^^^^^^^^^^^^^^^^^^^^^^^^^^
  File "/home/airflow/.local/lib/python3.12/site-packages/airflow/operators/python.py", line 235, in execute
    return_value = self.execute_callable()
                   ^^^^^^^^^^^^^^^^^^^^^^^
  File "/home/airflow/.local/lib/python3.12/site-packages/airflow/operators/python.py", line 252, in execute_callable
    return self.python_callable(*self.op_args, **self.op_kwargs)
           ^^^^^^^^^^^^^^^^^^^^^^^^^^^^^^^^^^^^^^^^^^^^^^^^^^^^^
  File "/opt/airflow/dags/user_airflow.py", line 122, in process_link
    result = run_selenium_job(link)
             ^^^^^^^^^^^^^^^^^^^^^^
  File "/opt/airflow/dags/user_airflow.py", line 63, in run_selenium_job
    driver.get(link)
  File "/home/airflow/.local/lib/python3.12/site-packages/selenium/webdriver/remote/webdriver.py", line 356, in get
    self.execute(Command.GET, {"url": url})
  File "/home/airflow/.local/lib/python3.12/site-packages/selenium/webdriver/remote/webdriver.py", line 347, in execute
    self.error_handler.check_response(response)
  File "/home/airflow/.local/lib/python3.12/site-packages/selenium/webdriver/remote/errorhandler.py", line 229, in check_response
    raise exception_class(message, screen, stacktrace)
selenium.common.exceptions.WebDriverException: Message: unknown error: net::ERR_NAME_NOT_RESOLVED
  (Session info: chrome-headless-shell=126.0.6478.114)
Stacktrace:
#0 0x55a0be0928ae <unknown>
#1 0x55a0bdd63c57 <unknown>
#2 0x55a0bdd5d0d6 <unknown>
#3 0x55a0bdd4fbbc <unknown>
#4 0x55a0bdd5127b <unknown>
#5 0x55a0bdd5003b <unknown>
#6 0x55a0bdd4f84b <unknown>
#7 0x55a0bdd4f6e0 <unknown>
#8 0x55a0bdd4dba0 <unknown>
#9 0x55a0bdd4def4 <unknown>
#10 0x55a0bdd66f06 <unknown>
#11 0x55a0bddeade2 <unknown>
#12 0x55a0bddcdb12 <unknown>
#13 0x55a0bddea920 <unknown>
#14 0x55a0bddcd893 <unknown>
#15 0x55a0bdd9e2ed <unknown>
#16 0x55a0bdd9f092 <unknown>
#17 0x55a0be062256 <unknown>
#18 0x55a0be0655f9 <unknown>
#19 0x55a0be0650bf <unknown>
#20 0x55a0be065a75 <unknown>
#21 0x55a0be05279f <unknown>
#22 0x55a0be065dc0 <unknown>
#23 0x55a0be03b6c6 <unknown>
#24 0x55a0be082fb5 <unknown>
#25 0x55a0be0831a2 <unknown>
#26 0x55a0be091d9a <unknown>
#27 0x7fd11cd7f134 <unknown>

[2024-06-28T02:36:30.943+0000] {standard_task_runner.py:110} ERROR - Failed to execute job 781 for task process_link_0 ((psycopg2.OperationalError) could not translate host name "postgres" to address: Temporary failure in name resolution

(Background on this error at: https://sqlalche.me/e/14/e3q8); 973)
[2024-06-28T02:36:37.169+0000] {job.py:226} ERROR - Job heartbeat failed with error. Scheduler is in unhealthy state
[2024-06-28T02:36:37.184+0000] {local_task_job_runner.py:240} INFO - Task exited with return code 1
[2024-06-28T02:36:47.513+0000] {taskinstance.py:3503} INFO - 0 downstream tasks scheduled from follow-on schedule check
[2024-06-28T02:36:47.529+0000] {local_task_job_runner.py:222} INFO - ::endgroup::
