[2024-06-27T08:35:29.411+0000] {taskinstance.py:1042} DEBUG - previous_execution_date was called
[2024-06-27T08:35:29.502+0000] {taskinstance.py:1042} DEBUG - previous_execution_date was called
[2024-06-27T08:35:29.556+0000] {local_task_job_runner.py:120} INFO - ::group::Pre task execution logs
[2024-06-27T08:35:29.706+0000] {taskinstance.py:2076} INFO - Dependencies all met for dep_context=non-requeueable deps ti=<TaskInstance: USER.process_link_2 manual__2024-06-27T08:35:08.312991+00:00 [queued]>
[2024-06-27T08:35:29.739+0000] {taskinstance.py:2076} INFO - Dependencies all met for dep_context=requeueable deps ti=<TaskInstance: USER.process_link_2 manual__2024-06-27T08:35:08.312991+00:00 [queued]>
[2024-06-27T08:35:29.741+0000] {taskinstance.py:2306} INFO - Starting attempt 1 of 1
[2024-06-27T08:35:29.773+0000] {taskinstance.py:2330} INFO - Executing <Task(PythonOperator): process_link_2> on 2024-06-27 08:35:08.312991+00:00
[2024-06-27T08:35:29.785+0000] {warnings.py:112} WARNING - /home/***/.local/lib/python3.12/site-packages/***/task/task_runner/standard_task_runner.py:61: DeprecationWarning: This process (pid=559) is multi-threaded, use of fork() may lead to deadlocks in the child.
  pid = os.fork()

[2024-06-27T08:35:29.787+0000] {standard_task_runner.py:63} INFO - Started process 766 to run task
[2024-06-27T08:35:29.788+0000] {standard_task_runner.py:90} INFO - Running: ['***', 'tasks', 'run', 'USER', 'process_link_2', 'manual__2024-06-27T08:35:08.312991+00:00', '--job-id', '717', '--raw', '--subdir', 'DAGS_FOLDER/user_***.py', '--cfg-path', '/tmp/tmp4ycyggwb']
[2024-06-27T08:35:29.790+0000] {standard_task_runner.py:91} INFO - Job 717: Subtask process_link_2
[2024-06-27T08:35:29.869+0000] {taskinstance.py:1042} DEBUG - previous_execution_date was called
[2024-06-27T08:35:29.890+0000] {task_command.py:426} INFO - Running <TaskInstance: USER.process_link_2 manual__2024-06-27T08:35:08.312991+00:00 [running]> on host ccfa35e0da07
[2024-06-27T08:35:29.891+0000] {settings.py:363} DEBUG - Disposing DB connection pool (PID 766)
[2024-06-27T08:35:29.892+0000] {settings.py:250} DEBUG - Setting up DB connection pool (PID 766)
[2024-06-27T08:35:29.892+0000] {settings.py:298} DEBUG - settings.prepare_engine_args(): Using NullPool
[2024-06-27T08:35:29.963+0000] {taskinstance.py:1042} DEBUG - previous_execution_date was called
[2024-06-27T08:35:30.074+0000] {taskinstance.py:2648} INFO - Exporting env vars: AIRFLOW_CTX_DAG_OWNER='***' AIRFLOW_CTX_DAG_ID='USER' AIRFLOW_CTX_TASK_ID='process_link_2' AIRFLOW_CTX_EXECUTION_DATE='2024-06-27T08:35:08.312991+00:00' AIRFLOW_CTX_TRY_NUMBER='1' AIRFLOW_CTX_DAG_RUN_ID='manual__2024-06-27T08:35:08.312991+00:00'
[2024-06-27T08:35:30.080+0000] {taskinstance.py:430} INFO - ::endgroup::
[2024-06-27T08:35:34.483+0000] {connectionpool.py:244} DEBUG - Starting new HTTP connection (1): localhost:53321
[2024-06-27T08:36:06.945+0000] {job.py:218} ERROR - Job heartbeat got an exception
Traceback (most recent call last):
  File "/home/airflow/.local/lib/python3.12/site-packages/sqlalchemy/engine/base.py", line 3371, in _wrap_pool_connect
    return fn()
           ^^^^
  File "/home/airflow/.local/lib/python3.12/site-packages/sqlalchemy/pool/base.py", line 327, in connect
    return _ConnectionFairy._checkout(self)
           ^^^^^^^^^^^^^^^^^^^^^^^^^^^^^^^^
  File "/home/airflow/.local/lib/python3.12/site-packages/sqlalchemy/pool/base.py", line 894, in _checkout
    fairy = _ConnectionRecord.checkout(pool)
            ^^^^^^^^^^^^^^^^^^^^^^^^^^^^^^^^
  File "/home/airflow/.local/lib/python3.12/site-packages/sqlalchemy/pool/base.py", line 493, in checkout
    rec = pool._do_get()
          ^^^^^^^^^^^^^^
  File "/home/airflow/.local/lib/python3.12/site-packages/sqlalchemy/pool/impl.py", line 256, in _do_get
    return self._create_connection()
           ^^^^^^^^^^^^^^^^^^^^^^^^^
  File "/home/airflow/.local/lib/python3.12/site-packages/sqlalchemy/pool/base.py", line 273, in _create_connection
    return _ConnectionRecord(self)
           ^^^^^^^^^^^^^^^^^^^^^^^
  File "/home/airflow/.local/lib/python3.12/site-packages/sqlalchemy/pool/base.py", line 388, in __init__
    self.__connect()
  File "/home/airflow/.local/lib/python3.12/site-packages/sqlalchemy/pool/base.py", line 690, in __connect
    with util.safe_reraise():
  File "/home/airflow/.local/lib/python3.12/site-packages/sqlalchemy/util/langhelpers.py", line 70, in __exit__
    compat.raise_(
  File "/home/airflow/.local/lib/python3.12/site-packages/sqlalchemy/util/compat.py", line 211, in raise_
    raise exception
  File "/home/airflow/.local/lib/python3.12/site-packages/sqlalchemy/pool/base.py", line 686, in __connect
    self.dbapi_connection = connection = pool._invoke_creator(self)
                                         ^^^^^^^^^^^^^^^^^^^^^^^^^^
  File "/home/airflow/.local/lib/python3.12/site-packages/sqlalchemy/engine/create.py", line 574, in connect
    return dialect.connect(*cargs, **cparams)
           ^^^^^^^^^^^^^^^^^^^^^^^^^^^^^^^^^^
  File "/home/airflow/.local/lib/python3.12/site-packages/sqlalchemy/engine/default.py", line 598, in connect
    return self.dbapi.connect(*cargs, **cparams)
           ^^^^^^^^^^^^^^^^^^^^^^^^^^^^^^^^^^^^^
  File "/home/airflow/.local/lib/python3.12/site-packages/psycopg2/__init__.py", line 122, in connect
    conn = _connect(dsn, connection_factory=connection_factory, **kwasync)
           ^^^^^^^^^^^^^^^^^^^^^^^^^^^^^^^^^^^^^^^^^^^^^^^^^^^^^^^^^^^^^^^
psycopg2.OperationalError: could not translate host name "postgres" to address: Temporary failure in name resolution


The above exception was the direct cause of the following exception:

Traceback (most recent call last):
  File "/home/airflow/.local/lib/python3.12/site-packages/airflow/jobs/job.py", line 192, in heartbeat
    self._merge_from(Job._fetch_from_db(self, session))
                     ^^^^^^^^^^^^^^^^^^^^^^^^^^^^^^^^^
  File "/home/airflow/.local/lib/python3.12/site-packages/airflow/api_internal/internal_api_call.py", line 115, in wrapper
    return func(*args, **kwargs)
           ^^^^^^^^^^^^^^^^^^^^^
  File "/home/airflow/.local/lib/python3.12/site-packages/airflow/utils/session.py", line 76, in wrapper
    return func(*args, **kwargs)
           ^^^^^^^^^^^^^^^^^^^^^
  File "/home/airflow/.local/lib/python3.12/site-packages/airflow/utils/retries.py", line 89, in wrapped_function
    for attempt in run_with_db_retries(max_retries=retries, logger=logger, **retry_kwargs):
  File "/home/airflow/.local/lib/python3.12/site-packages/tenacity/__init__.py", line 435, in __iter__
    do = self.iter(retry_state=retry_state)
         ^^^^^^^^^^^^^^^^^^^^^^^^^^^^^^^^^^
  File "/home/airflow/.local/lib/python3.12/site-packages/tenacity/__init__.py", line 368, in iter
    result = action(retry_state)
             ^^^^^^^^^^^^^^^^^^^
  File "/home/airflow/.local/lib/python3.12/site-packages/tenacity/__init__.py", line 410, in exc_check
    raise retry_exc.reraise()
          ^^^^^^^^^^^^^^^^^^^
  File "/home/airflow/.local/lib/python3.12/site-packages/tenacity/__init__.py", line 183, in reraise
    raise self.last_attempt.result()
          ^^^^^^^^^^^^^^^^^^^^^^^^^^
  File "/usr/local/lib/python3.12/concurrent/futures/_base.py", line 449, in result
    return self.__get_result()
           ^^^^^^^^^^^^^^^^^^^
  File "/usr/local/lib/python3.12/concurrent/futures/_base.py", line 401, in __get_result
    raise self._exception
  File "/home/airflow/.local/lib/python3.12/site-packages/airflow/utils/retries.py", line 98, in wrapped_function
    return func(*args, **kwargs)
           ^^^^^^^^^^^^^^^^^^^^^
  File "/home/airflow/.local/lib/python3.12/site-packages/airflow/jobs/job.py", line 316, in _fetch_from_db
    session.merge(job)
  File "/home/airflow/.local/lib/python3.12/site-packages/sqlalchemy/orm/session.py", line 3056, in merge
    return self._merge(
           ^^^^^^^^^^^^
  File "/home/airflow/.local/lib/python3.12/site-packages/sqlalchemy/orm/session.py", line 3136, in _merge
    merged = self.get(
             ^^^^^^^^^
  File "/home/airflow/.local/lib/python3.12/site-packages/sqlalchemy/orm/session.py", line 2853, in get
    return self._get_impl(
           ^^^^^^^^^^^^^^^
  File "/home/airflow/.local/lib/python3.12/site-packages/sqlalchemy/orm/session.py", line 2975, in _get_impl
    return db_load_fn(
           ^^^^^^^^^^^
  File "/home/airflow/.local/lib/python3.12/site-packages/sqlalchemy/orm/loading.py", line 530, in load_on_pk_identity
    session.execute(
  File "/home/airflow/.local/lib/python3.12/site-packages/sqlalchemy/orm/session.py", line 1716, in execute
    conn = self._connection_for_bind(bind)
           ^^^^^^^^^^^^^^^^^^^^^^^^^^^^^^^
  File "/home/airflow/.local/lib/python3.12/site-packages/sqlalchemy/orm/session.py", line 1555, in _connection_for_bind
    return self._transaction._connection_for_bind(
           ^^^^^^^^^^^^^^^^^^^^^^^^^^^^^^^^^^^^^^^
  File "/home/airflow/.local/lib/python3.12/site-packages/sqlalchemy/orm/session.py", line 750, in _connection_for_bind
    conn = bind.connect()
           ^^^^^^^^^^^^^^
  File "/home/airflow/.local/lib/python3.12/site-packages/sqlalchemy/future/engine.py", line 412, in connect
    return super(Engine, self).connect()
           ^^^^^^^^^^^^^^^^^^^^^^^^^^^^^
  File "/home/airflow/.local/lib/python3.12/site-packages/sqlalchemy/engine/base.py", line 3325, in connect
    return self._connection_cls(self, close_with_result=close_with_result)
           ^^^^^^^^^^^^^^^^^^^^^^^^^^^^^^^^^^^^^^^^^^^^^^^^^^^^^^^^^^^^^^^
  File "/home/airflow/.local/lib/python3.12/site-packages/sqlalchemy/engine/base.py", line 96, in __init__
    else engine.raw_connection()
         ^^^^^^^^^^^^^^^^^^^^^^^
  File "/home/airflow/.local/lib/python3.12/site-packages/sqlalchemy/engine/base.py", line 3404, in raw_connection
    return self._wrap_pool_connect(self.pool.connect, _connection)
           ^^^^^^^^^^^^^^^^^^^^^^^^^^^^^^^^^^^^^^^^^^^^^^^^^^^^^^^
  File "/home/airflow/.local/lib/python3.12/site-packages/sqlalchemy/engine/base.py", line 3374, in _wrap_pool_connect
    Connection._handle_dbapi_exception_noconnection(
  File "/home/airflow/.local/lib/python3.12/site-packages/sqlalchemy/engine/base.py", line 2208, in _handle_dbapi_exception_noconnection
    util.raise_(
  File "/home/airflow/.local/lib/python3.12/site-packages/sqlalchemy/util/compat.py", line 211, in raise_
    raise exception
  File "/home/airflow/.local/lib/python3.12/site-packages/sqlalchemy/engine/base.py", line 3371, in _wrap_pool_connect
    return fn()
           ^^^^
  File "/home/airflow/.local/lib/python3.12/site-packages/sqlalchemy/pool/base.py", line 327, in connect
    return _ConnectionFairy._checkout(self)
           ^^^^^^^^^^^^^^^^^^^^^^^^^^^^^^^^
  File "/home/airflow/.local/lib/python3.12/site-packages/sqlalchemy/pool/base.py", line 894, in _checkout
    fairy = _ConnectionRecord.checkout(pool)
            ^^^^^^^^^^^^^^^^^^^^^^^^^^^^^^^^
  File "/home/airflow/.local/lib/python3.12/site-packages/sqlalchemy/pool/base.py", line 493, in checkout
    rec = pool._do_get()
          ^^^^^^^^^^^^^^
  File "/home/airflow/.local/lib/python3.12/site-packages/sqlalchemy/pool/impl.py", line 256, in _do_get
    return self._create_connection()
           ^^^^^^^^^^^^^^^^^^^^^^^^^
  File "/home/airflow/.local/lib/python3.12/site-packages/sqlalchemy/pool/base.py", line 273, in _create_connection
    return _ConnectionRecord(self)
           ^^^^^^^^^^^^^^^^^^^^^^^
  File "/home/airflow/.local/lib/python3.12/site-packages/sqlalchemy/pool/base.py", line 388, in __init__
    self.__connect()
  File "/home/airflow/.local/lib/python3.12/site-packages/sqlalchemy/pool/base.py", line 690, in __connect
    with util.safe_reraise():
  File "/home/airflow/.local/lib/python3.12/site-packages/sqlalchemy/util/langhelpers.py", line 70, in __exit__
    compat.raise_(
  File "/home/airflow/.local/lib/python3.12/site-packages/sqlalchemy/util/compat.py", line 211, in raise_
    raise exception
  File "/home/airflow/.local/lib/python3.12/site-packages/sqlalchemy/pool/base.py", line 686, in __connect
    self.dbapi_connection = connection = pool._invoke_creator(self)
                                         ^^^^^^^^^^^^^^^^^^^^^^^^^^
  File "/home/airflow/.local/lib/python3.12/site-packages/sqlalchemy/engine/create.py", line 574, in connect
    return dialect.connect(*cargs, **cparams)
           ^^^^^^^^^^^^^^^^^^^^^^^^^^^^^^^^^^
  File "/home/airflow/.local/lib/python3.12/site-packages/sqlalchemy/engine/default.py", line 598, in connect
    return self.dbapi.connect(*cargs, **cparams)
           ^^^^^^^^^^^^^^^^^^^^^^^^^^^^^^^^^^^^^
  File "/home/airflow/.local/lib/python3.12/site-packages/psycopg2/__init__.py", line 122, in connect
    conn = _connect(dsn, connection_factory=connection_factory, **kwasync)
           ^^^^^^^^^^^^^^^^^^^^^^^^^^^^^^^^^^^^^^^^^^^^^^^^^^^^^^^^^^^^^^^
sqlalchemy.exc.OperationalError: (psycopg2.OperationalError) could not translate host name "postgres" to address: Temporary failure in name resolution

(Background on this error at: https://sqlalche.me/e/14/e3q8)
[2024-06-27T08:36:11.582+0000] {job.py:226} ERROR - Job heartbeat failed with error. Scheduler is in unhealthy state
[2024-06-27T08:36:38.534+0000] {connectionpool.py:549} DEBUG - http://localhost:53321 "POST /session HTTP/1.1" 500 0
[2024-06-27T08:36:40.185+0000] {taskinstance.py:441} INFO - ::group::Post task execution logs
[2024-06-27T08:36:40.225+0000] {taskinstance.py:2905} ERROR - Task failed with exception
Traceback (most recent call last):
  File "/home/airflow/.local/lib/python3.12/site-packages/airflow/models/taskinstance.py", line 465, in _execute_task
    result = _execute_callable(context=context, **execute_callable_kwargs)
             ^^^^^^^^^^^^^^^^^^^^^^^^^^^^^^^^^^^^^^^^^^^^^^^^^^^^^^^^^^^^^
  File "/home/airflow/.local/lib/python3.12/site-packages/airflow/models/taskinstance.py", line 432, in _execute_callable
    return execute_callable(context=context, **execute_callable_kwargs)
           ^^^^^^^^^^^^^^^^^^^^^^^^^^^^^^^^^^^^^^^^^^^^^^^^^^^^^^^^^^^^
  File "/home/airflow/.local/lib/python3.12/site-packages/airflow/models/baseoperator.py", line 401, in wrapper
    return func(self, *args, **kwargs)
           ^^^^^^^^^^^^^^^^^^^^^^^^^^^
  File "/home/airflow/.local/lib/python3.12/site-packages/airflow/operators/python.py", line 235, in execute
    return_value = self.execute_callable()
                   ^^^^^^^^^^^^^^^^^^^^^^^
  File "/home/airflow/.local/lib/python3.12/site-packages/airflow/operators/python.py", line 252, in execute_callable
    return self.python_callable(*self.op_args, **self.op_kwargs)
           ^^^^^^^^^^^^^^^^^^^^^^^^^^^^^^^^^^^^^^^^^^^^^^^^^^^^^
  File "/opt/airflow/dags/user_airflow.py", line 122, in process_link
    result = run_selenium_job(link)
             ^^^^^^^^^^^^^^^^^^^^^^
  File "/opt/airflow/dags/user_airflow.py", line 62, in run_selenium_job
    driver = webdriver.Chrome(options=options)
             ^^^^^^^^^^^^^^^^^^^^^^^^^^^^^^^^^
  File "/home/airflow/.local/lib/python3.12/site-packages/selenium/webdriver/chrome/webdriver.py", line 45, in __init__
    super().__init__(
  File "/home/airflow/.local/lib/python3.12/site-packages/selenium/webdriver/chromium/webdriver.py", line 66, in __init__
    super().__init__(command_executor=executor, options=options)
  File "/home/airflow/.local/lib/python3.12/site-packages/selenium/webdriver/remote/webdriver.py", line 208, in __init__
    self.start_session(capabilities)
  File "/home/airflow/.local/lib/python3.12/site-packages/selenium/webdriver/remote/webdriver.py", line 292, in start_session
    response = self.execute(Command.NEW_SESSION, caps)["value"]
               ^^^^^^^^^^^^^^^^^^^^^^^^^^^^^^^^^^^^^^^
  File "/home/airflow/.local/lib/python3.12/site-packages/selenium/webdriver/remote/webdriver.py", line 347, in execute
    self.error_handler.check_response(response)
  File "/home/airflow/.local/lib/python3.12/site-packages/selenium/webdriver/remote/errorhandler.py", line 229, in check_response
    raise exception_class(message, screen, stacktrace)
selenium.common.exceptions.SessionNotCreatedException: Message: session not created: DevToolsActivePort file doesn't exist
Stacktrace:
#0 0x55e61c1198ae <unknown>
#1 0x55e61bdeac57 <unknown>
#2 0x55e61be20e4d <unknown>
#3 0x55e61be1d221 <unknown>
#4 0x55e61be1925d <unknown>
#5 0x55e61be62639 <unknown>
#6 0x55e61be54893 <unknown>
#7 0x55e61be252ed <unknown>
#8 0x55e61be26092 <unknown>
#9 0x55e61c0e9256 <unknown>
#10 0x55e61c0ec5f9 <unknown>
#11 0x55e61c0ec0bf <unknown>
#12 0x55e61c0eca75 <unknown>
#13 0x55e61c0d979f <unknown>
#14 0x55e61c0ecdc0 <unknown>
#15 0x55e61c0c26c6 <unknown>
#16 0x55e61c109fb5 <unknown>
#17 0x55e61c10a1a2 <unknown>
#18 0x55e61c118d9a <unknown>
#19 0x7f4be6a81134 <unknown>

[2024-06-27T08:36:44.402+0000] {taskinstance.py:562} DEBUG - Task Duration set to 74.692664
[2024-06-27T08:36:44.416+0000] {taskinstance.py:584} DEBUG - Clearing next_method and next_kwargs.
[2024-06-27T08:36:44.420+0000] {taskinstance.py:1206} INFO - Marking task as FAILED. dag_id=USER, task_id=process_link_2, run_id=manual__2024-06-27T08:35:08.312991+00:00, execution_date=20240627T083508, start_date=20240627T083529, end_date=20240627T083644
[2024-06-27T08:36:44.487+0000] {standard_task_runner.py:110} ERROR - Failed to execute job 717 for task process_link_2 (Message: session not created: DevToolsActivePort file doesn't exist
Stacktrace:
#0 0x55e61c1198ae <unknown>
#1 0x55e61bdeac57 <unknown>
#2 0x55e61be20e4d <unknown>
#3 0x55e61be1d221 <unknown>
#4 0x55e61be1925d <unknown>
#5 0x55e61be62639 <unknown>
#6 0x55e61be54893 <unknown>
#7 0x55e61be252ed <unknown>
#8 0x55e61be26092 <unknown>
#9 0x55e61c0e9256 <unknown>
#10 0x55e61c0ec5f9 <unknown>
#11 0x55e61c0ec0bf <unknown>
#12 0x55e61c0eca75 <unknown>
#13 0x55e61c0d979f <unknown>
#14 0x55e61c0ecdc0 <unknown>
#15 0x55e61c0c26c6 <unknown>
#16 0x55e61c109fb5 <unknown>
#17 0x55e61c10a1a2 <unknown>
#18 0x55e61c118d9a <unknown>
#19 0x7f4be6a81134 <unknown>
; 766)
[2024-06-27T08:36:44.725+0000] {local_task_job_runner.py:240} INFO - Task exited with return code 1
[2024-06-27T08:36:44.784+0000] {taskinstance.py:3503} INFO - 0 downstream tasks scheduled from follow-on schedule check
[2024-06-27T08:36:44.788+0000] {local_task_job_runner.py:222} INFO - ::endgroup::
