[2024-06-27T02:37:57.857+0000] {taskinstance.py:1042} DEBUG - previous_execution_date was called
[2024-06-27T02:37:57.905+0000] {taskinstance.py:1042} DEBUG - previous_execution_date was called
[2024-06-27T02:37:57.922+0000] {local_task_job_runner.py:120} INFO - ::group::Pre task execution logs
[2024-06-27T02:37:57.961+0000] {taskinstance.py:2076} INFO - Dependencies all met for dep_context=non-requeueable deps ti=<TaskInstance: test_use.get_urls_task manual__2024-06-27T02:37:56.403413+00:00 [queued]>
[2024-06-27T02:37:57.974+0000] {taskinstance.py:2076} INFO - Dependencies all met for dep_context=requeueable deps ti=<TaskInstance: test_use.get_urls_task manual__2024-06-27T02:37:56.403413+00:00 [queued]>
[2024-06-27T02:37:57.975+0000] {taskinstance.py:2306} INFO - Starting attempt 1 of 1
[2024-06-27T02:37:57.997+0000] {taskinstance.py:2330} INFO - Executing <Task(PythonOperator): get_urls_task> on 2024-06-27 02:37:56.403413+00:00
[2024-06-27T02:37:58.007+0000] {warnings.py:112} WARNING - /home/***/.local/lib/python3.12/site-packages/***/task/task_runner/standard_task_runner.py:61: DeprecationWarning: This process (pid=2091) is multi-threaded, use of fork() may lead to deadlocks in the child.
  pid = os.fork()

[2024-06-27T02:37:58.009+0000] {standard_task_runner.py:63} INFO - Started process 2092 to run task
[2024-06-27T02:37:58.009+0000] {standard_task_runner.py:90} INFO - Running: ['***', 'tasks', 'run', 'test_use', 'get_urls_task', 'manual__2024-06-27T02:37:56.403413+00:00', '--job-id', '569', '--raw', '--subdir', 'DAGS_FOLDER/first_out.py', '--cfg-path', '/tmp/tmpmepwg9_a']
[2024-06-27T02:37:58.012+0000] {standard_task_runner.py:91} INFO - Job 569: Subtask get_urls_task
[2024-06-27T02:37:58.059+0000] {taskinstance.py:1042} DEBUG - previous_execution_date was called
[2024-06-27T02:37:58.070+0000] {task_command.py:426} INFO - Running <TaskInstance: test_use.get_urls_task manual__2024-06-27T02:37:56.403413+00:00 [running]> on host ccfa35e0da07
[2024-06-27T02:37:58.071+0000] {settings.py:363} DEBUG - Disposing DB connection pool (PID 2092)
[2024-06-27T02:37:58.071+0000] {settings.py:250} DEBUG - Setting up DB connection pool (PID 2092)
[2024-06-27T02:37:58.072+0000] {settings.py:298} DEBUG - settings.prepare_engine_args(): Using NullPool
[2024-06-27T02:37:58.122+0000] {taskinstance.py:1042} DEBUG - previous_execution_date was called
[2024-06-27T02:37:58.196+0000] {taskinstance.py:2648} INFO - Exporting env vars: AIRFLOW_CTX_DAG_OWNER='***' AIRFLOW_CTX_DAG_ID='test_use' AIRFLOW_CTX_TASK_ID='get_urls_task' AIRFLOW_CTX_EXECUTION_DATE='2024-06-27T02:37:56.403413+00:00' AIRFLOW_CTX_TRY_NUMBER='1' AIRFLOW_CTX_DAG_RUN_ID='manual__2024-06-27T02:37:56.403413+00:00'
[2024-06-27T02:37:58.198+0000] {taskinstance.py:430} INFO - ::endgroup::
[2024-06-27T02:38:19.678+0000] {taskinstance.py:441} INFO - ::group::Post task execution logs
[2024-06-27T02:38:19.682+0000] {taskinstance.py:2905} ERROR - Task failed with exception
Traceback (most recent call last):
  File "/home/airflow/.local/lib/python3.12/site-packages/airflow/models/taskinstance.py", line 465, in _execute_task
    result = _execute_callable(context=context, **execute_callable_kwargs)
             ^^^^^^^^^^^^^^^^^^^^^^^^^^^^^^^^^^^^^^^^^^^^^^^^^^^^^^^^^^^^^
  File "/home/airflow/.local/lib/python3.12/site-packages/airflow/models/taskinstance.py", line 432, in _execute_callable
    return execute_callable(context=context, **execute_callable_kwargs)
           ^^^^^^^^^^^^^^^^^^^^^^^^^^^^^^^^^^^^^^^^^^^^^^^^^^^^^^^^^^^^
  File "/home/airflow/.local/lib/python3.12/site-packages/airflow/models/baseoperator.py", line 401, in wrapper
    return func(self, *args, **kwargs)
           ^^^^^^^^^^^^^^^^^^^^^^^^^^^
  File "/home/airflow/.local/lib/python3.12/site-packages/airflow/operators/python.py", line 235, in execute
    return_value = self.execute_callable()
                   ^^^^^^^^^^^^^^^^^^^^^^^
  File "/home/airflow/.local/lib/python3.12/site-packages/airflow/operators/python.py", line 252, in execute_callable
    return self.python_callable(*self.op_args, **self.op_kwargs)
           ^^^^^^^^^^^^^^^^^^^^^^^^^^^^^^^^^^^^^^^^^^^^^^^^^^^^^
  File "/opt/airflow/dags/first_out.py", line 29, in run_selenium_job
    page_id = functions_instance.get_id(link)
              ^^^^^^^^^^^^^^^^^^^^^^^^^^^^^^^
  File "/opt/airflow/dags/fun/fun_user.py", line 77, in get_id
    soup = BeautifulSoup(driver.page_source, "html.parser")
                         ^^^^^^^^^^^^^^^^^^
  File "/home/airflow/.local/lib/python3.12/site-packages/selenium/webdriver/remote/webdriver.py", line 448, in page_source
    return self.execute(Command.GET_PAGE_SOURCE)["value"]
           ^^^^^^^^^^^^^^^^^^^^^^^^^^^^^^^^^^^^^
  File "/home/airflow/.local/lib/python3.12/site-packages/selenium/webdriver/remote/webdriver.py", line 347, in execute
    self.error_handler.check_response(response)
  File "/home/airflow/.local/lib/python3.12/site-packages/selenium/webdriver/remote/errorhandler.py", line 229, in check_response
    raise exception_class(message, screen, stacktrace)
selenium.common.exceptions.WebDriverException: Message: unknown error: session deleted because of page crash
from unknown error: cannot determine loading status
from tab crashed
  (Session info: chrome-headless-shell=126.0.6478.114)
Stacktrace:
#0 0x562862a748ae <unknown>
#1 0x562862745966 <unknown>
#2 0x562862732899 <unknown>
#3 0x562862731fa6 <unknown>
#4 0x56286273184b <unknown>
#5 0x5628627316e0 <unknown>
#6 0x56286272fba0 <unknown>
#7 0x5628627300b9 <unknown>
#8 0x56286273da14 <unknown>
#9 0x562862750f6f <unknown>
#10 0x56286275568b <unknown>
#11 0x56286273065b <unknown>
#12 0x562862750b71 <unknown>
#13 0x5628627ccb22 <unknown>
#14 0x5628627af893 <unknown>
#15 0x5628627802ed <unknown>
#16 0x562862781092 <unknown>
#17 0x562862a44256 <unknown>
#18 0x562862a475f9 <unknown>
#19 0x562862a470bf <unknown>
#20 0x562862a47a75 <unknown>
#21 0x562862a3479f <unknown>
#22 0x562862a47dc0 <unknown>
#23 0x562862a1d6c6 <unknown>
#24 0x562862a64fb5 <unknown>
#25 0x562862a651a2 <unknown>
#26 0x562862a73d9a <unknown>
#27 0x7efdc8005134 <unknown>

[2024-06-27T02:38:20.659+0000] {taskinstance.py:562} DEBUG - Task Duration set to 22.697386
[2024-06-27T02:38:20.673+0000] {taskinstance.py:584} DEBUG - Clearing next_method and next_kwargs.
[2024-06-27T02:38:20.676+0000] {taskinstance.py:1206} INFO - Marking task as FAILED. dag_id=test_use, task_id=get_urls_task, run_id=manual__2024-06-27T02:37:56.403413+00:00, execution_date=20240627T023756, start_date=20240627T023757, end_date=20240627T023820
[2024-06-27T02:38:20.736+0000] {standard_task_runner.py:110} ERROR - Failed to execute job 569 for task get_urls_task (Message: unknown error: session deleted because of page crash
from unknown error: cannot determine loading status
from tab crashed
  (Session info: chrome-headless-shell=126.0.6478.114)
Stacktrace:
#0 0x562862a748ae <unknown>
#1 0x562862745966 <unknown>
#2 0x562862732899 <unknown>
#3 0x562862731fa6 <unknown>
#4 0x56286273184b <unknown>
#5 0x5628627316e0 <unknown>
#6 0x56286272fba0 <unknown>
#7 0x5628627300b9 <unknown>
#8 0x56286273da14 <unknown>
#9 0x562862750f6f <unknown>
#10 0x56286275568b <unknown>
#11 0x56286273065b <unknown>
#12 0x562862750b71 <unknown>
#13 0x5628627ccb22 <unknown>
#14 0x5628627af893 <unknown>
#15 0x5628627802ed <unknown>
#16 0x562862781092 <unknown>
#17 0x562862a44256 <unknown>
#18 0x562862a475f9 <unknown>
#19 0x562862a470bf <unknown>
#20 0x562862a47a75 <unknown>
#21 0x562862a3479f <unknown>
#22 0x562862a47dc0 <unknown>
#23 0x562862a1d6c6 <unknown>
#24 0x562862a64fb5 <unknown>
#25 0x562862a651a2 <unknown>
#26 0x562862a73d9a <unknown>
#27 0x7efdc8005134 <unknown>
; 2092)
[2024-06-27T02:38:20.792+0000] {local_task_job_runner.py:240} INFO - Task exited with return code 1
[2024-06-27T02:38:20.819+0000] {taskinstance.py:3503} INFO - 0 downstream tasks scheduled from follow-on schedule check
[2024-06-27T02:38:20.824+0000] {local_task_job_runner.py:222} INFO - ::endgroup::
