[2024-06-26T08:49:39.419+0000] {taskinstance.py:1042} DEBUG - previous_execution_date was called
[2024-06-26T08:49:39.501+0000] {taskinstance.py:1042} DEBUG - previous_execution_date was called
[2024-06-26T08:49:39.551+0000] {local_task_job_runner.py:120} INFO - ::group::Pre task execution logs
[2024-06-26T08:49:39.649+0000] {taskinstance.py:2076} INFO - Dependencies all met for dep_context=non-requeueable deps ti=<TaskInstance: User.get_urls_task manual__2024-06-26T08:49:32.912679+00:00 [queued]>
[2024-06-26T08:49:39.671+0000] {taskinstance.py:2076} INFO - Dependencies all met for dep_context=requeueable deps ti=<TaskInstance: User.get_urls_task manual__2024-06-26T08:49:32.912679+00:00 [queued]>
[2024-06-26T08:49:39.673+0000] {taskinstance.py:2306} INFO - Starting attempt 1 of 1
[2024-06-26T08:49:39.697+0000] {taskinstance.py:2330} INFO - Executing <Task(PythonOperator): get_urls_task> on 2024-06-26 08:49:32.912679+00:00
[2024-06-26T08:49:39.708+0000] {warnings.py:112} WARNING - /home/***/.local/lib/python3.12/site-packages/***/task/task_runner/standard_task_runner.py:61: DeprecationWarning: This process (pid=4043) is multi-threaded, use of fork() may lead to deadlocks in the child.
  pid = os.fork()

[2024-06-26T08:49:39.710+0000] {standard_task_runner.py:63} INFO - Started process 4051 to run task
[2024-06-26T08:49:39.708+0000] {standard_task_runner.py:90} INFO - Running: ['***', 'tasks', 'run', 'User', 'get_urls_task', 'manual__2024-06-26T08:49:32.912679+00:00', '--job-id', '542', '--raw', '--subdir', 'DAGS_FOLDER/first_out.py', '--cfg-path', '/tmp/tmp_tqvd4_z']
[2024-06-26T08:49:39.712+0000] {standard_task_runner.py:91} INFO - Job 542: Subtask get_urls_task
[2024-06-26T08:49:39.769+0000] {taskinstance.py:1042} DEBUG - previous_execution_date was called
[2024-06-26T08:49:39.780+0000] {task_command.py:426} INFO - Running <TaskInstance: User.get_urls_task manual__2024-06-26T08:49:32.912679+00:00 [running]> on host ccfa35e0da07
[2024-06-26T08:49:39.781+0000] {settings.py:363} DEBUG - Disposing DB connection pool (PID 4051)
[2024-06-26T08:49:39.782+0000] {settings.py:250} DEBUG - Setting up DB connection pool (PID 4051)
[2024-06-26T08:49:39.783+0000] {settings.py:298} DEBUG - settings.prepare_engine_args(): Using NullPool
[2024-06-26T08:49:39.855+0000] {taskinstance.py:1042} DEBUG - previous_execution_date was called
[2024-06-26T08:49:39.985+0000] {taskinstance.py:2648} INFO - Exporting env vars: AIRFLOW_CTX_DAG_OWNER='***' AIRFLOW_CTX_DAG_ID='User' AIRFLOW_CTX_TASK_ID='get_urls_task' AIRFLOW_CTX_EXECUTION_DATE='2024-06-26T08:49:32.912679+00:00' AIRFLOW_CTX_TRY_NUMBER='1' AIRFLOW_CTX_DAG_RUN_ID='manual__2024-06-26T08:49:32.912679+00:00'
[2024-06-26T08:49:39.989+0000] {taskinstance.py:430} INFO - ::endgroup::
[2024-06-26T08:49:50.728+0000] {taskinstance.py:441} INFO - ::group::Post task execution logs
[2024-06-26T08:49:50.738+0000] {taskinstance.py:2905} ERROR - Task failed with exception
Traceback (most recent call last):
  File "/home/airflow/.local/lib/python3.12/site-packages/airflow/models/taskinstance.py", line 465, in _execute_task
    result = _execute_callable(context=context, **execute_callable_kwargs)
             ^^^^^^^^^^^^^^^^^^^^^^^^^^^^^^^^^^^^^^^^^^^^^^^^^^^^^^^^^^^^^
  File "/home/airflow/.local/lib/python3.12/site-packages/airflow/models/taskinstance.py", line 432, in _execute_callable
    return execute_callable(context=context, **execute_callable_kwargs)
           ^^^^^^^^^^^^^^^^^^^^^^^^^^^^^^^^^^^^^^^^^^^^^^^^^^^^^^^^^^^^
  File "/home/airflow/.local/lib/python3.12/site-packages/airflow/models/baseoperator.py", line 401, in wrapper
    return func(self, *args, **kwargs)
           ^^^^^^^^^^^^^^^^^^^^^^^^^^^
  File "/home/airflow/.local/lib/python3.12/site-packages/airflow/operators/python.py", line 235, in execute
    return_value = self.execute_callable()
                   ^^^^^^^^^^^^^^^^^^^^^^^
  File "/home/airflow/.local/lib/python3.12/site-packages/airflow/operators/python.py", line 252, in execute_callable
    return self.python_callable(*self.op_args, **self.op_kwargs)
           ^^^^^^^^^^^^^^^^^^^^^^^^^^^^^^^^^^^^^^^^^^^^^^^^^^^^^
  File "/opt/airflow/dags/first_out.py", line 37, in run_selenium_job
    page_id = functions_instance.get_id(link)
              ^^^^^^^^^^^^^^^^^^^^^^^^^^^^^^^
  File "/opt/airflow/dags/fun/fun_user.py", line 66, in get_id
    driver = webdriver.Chrome()
             ^^^^^^^^^^^^^^^^^^
  File "/home/airflow/.local/lib/python3.12/site-packages/selenium/webdriver/chrome/webdriver.py", line 45, in __init__
    super().__init__(
  File "/home/airflow/.local/lib/python3.12/site-packages/selenium/webdriver/chromium/webdriver.py", line 66, in __init__
    super().__init__(command_executor=executor, options=options)
  File "/home/airflow/.local/lib/python3.12/site-packages/selenium/webdriver/remote/webdriver.py", line 208, in __init__
    self.start_session(capabilities)
  File "/home/airflow/.local/lib/python3.12/site-packages/selenium/webdriver/remote/webdriver.py", line 292, in start_session
    response = self.execute(Command.NEW_SESSION, caps)["value"]
               ^^^^^^^^^^^^^^^^^^^^^^^^^^^^^^^^^^^^^^^
  File "/home/airflow/.local/lib/python3.12/site-packages/selenium/webdriver/remote/webdriver.py", line 347, in execute
    self.error_handler.check_response(response)
  File "/home/airflow/.local/lib/python3.12/site-packages/selenium/webdriver/remote/errorhandler.py", line 229, in check_response
    raise exception_class(message, screen, stacktrace)
selenium.common.exceptions.SessionNotCreatedException: Message: session not created: Chrome failed to start: exited normally.
  (session not created: DevToolsActivePort file doesn't exist)
  (The process started from chrome location /usr/bin/chromium is no longer running, so ChromeDriver is assuming that Chrome has crashed.)
Stacktrace:
#0 0x556ba99268ae <unknown>
#1 0x556ba95f7c57 <unknown>
#2 0x556ba962b35f <unknown>
#3 0x556ba962625d <unknown>
#4 0x556ba966f639 <unknown>
#5 0x556ba9661893 <unknown>
#6 0x556ba96322ed <unknown>
#7 0x556ba9633092 <unknown>
#8 0x556ba98f6256 <unknown>
#9 0x556ba98f95f9 <unknown>
#10 0x556ba98f90bf <unknown>
#11 0x556ba98f9a75 <unknown>
#12 0x556ba98e679f <unknown>
#13 0x556ba98f9dc0 <unknown>
#14 0x556ba98cf6c6 <unknown>
#15 0x556ba9916fb5 <unknown>
#16 0x556ba99171a2 <unknown>
#17 0x556ba9925d9a <unknown>
#18 0x7fb76849a134 <unknown>

[2024-06-26T08:49:50.799+0000] {taskinstance.py:562} DEBUG - Task Duration set to 11.148969
[2024-06-26T08:49:50.806+0000] {taskinstance.py:584} DEBUG - Clearing next_method and next_kwargs.
[2024-06-26T08:49:50.808+0000] {taskinstance.py:1206} INFO - Marking task as FAILED. dag_id=User, task_id=get_urls_task, run_id=manual__2024-06-26T08:49:32.912679+00:00, execution_date=20240626T084932, start_date=20240626T084939, end_date=20240626T084950
[2024-06-26T08:49:50.839+0000] {standard_task_runner.py:110} ERROR - Failed to execute job 542 for task get_urls_task (Message: session not created: Chrome failed to start: exited normally.
  (session not created: DevToolsActivePort file doesn't exist)
  (The process started from chrome location /usr/bin/chromium is no longer running, so ChromeDriver is assuming that Chrome has crashed.)
Stacktrace:
#0 0x556ba99268ae <unknown>
#1 0x556ba95f7c57 <unknown>
#2 0x556ba962b35f <unknown>
#3 0x556ba962625d <unknown>
#4 0x556ba966f639 <unknown>
#5 0x556ba9661893 <unknown>
#6 0x556ba96322ed <unknown>
#7 0x556ba9633092 <unknown>
#8 0x556ba98f6256 <unknown>
#9 0x556ba98f95f9 <unknown>
#10 0x556ba98f90bf <unknown>
#11 0x556ba98f9a75 <unknown>
#12 0x556ba98e679f <unknown>
#13 0x556ba98f9dc0 <unknown>
#14 0x556ba98cf6c6 <unknown>
#15 0x556ba9916fb5 <unknown>
#16 0x556ba99171a2 <unknown>
#17 0x556ba9925d9a <unknown>
#18 0x7fb76849a134 <unknown>
; 4051)
[2024-06-26T08:49:50.861+0000] {local_task_job_runner.py:240} INFO - Task exited with return code 1
[2024-06-26T08:49:50.885+0000] {taskinstance.py:3503} INFO - 0 downstream tasks scheduled from follow-on schedule check
[2024-06-26T08:49:50.889+0000] {local_task_job_runner.py:222} INFO - ::endgroup::
