[2024-06-27T07:50:41.329+0000] {taskinstance.py:1042} DEBUG - previous_execution_date was called
[2024-06-27T07:50:41.380+0000] {taskinstance.py:1042} DEBUG - previous_execution_date was called
[2024-06-27T07:50:41.406+0000] {local_task_job_runner.py:120} INFO - ::group::Pre task execution logs
[2024-06-27T07:50:41.457+0000] {taskinstance.py:2076} INFO - Dependencies all met for dep_context=non-requeueable deps ti=<TaskInstance: USER.process_link_2 manual__2024-06-27T07:50:33.544496+00:00 [queued]>
[2024-06-27T07:50:41.477+0000] {taskinstance.py:2076} INFO - Dependencies all met for dep_context=requeueable deps ti=<TaskInstance: USER.process_link_2 manual__2024-06-27T07:50:33.544496+00:00 [queued]>
[2024-06-27T07:50:41.479+0000] {taskinstance.py:2306} INFO - Starting attempt 1 of 1
[2024-06-27T07:50:41.508+0000] {taskinstance.py:2330} INFO - Executing <Task(PythonOperator): process_link_2> on 2024-06-27 07:50:33.544496+00:00
[2024-06-27T07:50:41.519+0000] {warnings.py:112} WARNING - /home/***/.local/lib/python3.12/site-packages/***/task/task_runner/standard_task_runner.py:61: DeprecationWarning: This process (pid=104) is multi-threaded, use of fork() may lead to deadlocks in the child.
  pid = os.fork()

[2024-06-27T07:50:41.523+0000] {standard_task_runner.py:63} INFO - Started process 107 to run task
[2024-06-27T07:50:41.522+0000] {standard_task_runner.py:90} INFO - Running: ['***', 'tasks', 'run', 'USER', 'process_link_2', 'manual__2024-06-27T07:50:33.544496+00:00', '--job-id', '708', '--raw', '--subdir', 'DAGS_FOLDER/user_***.py', '--cfg-path', '/tmp/tmpo6ja4s_v']
[2024-06-27T07:50:41.524+0000] {standard_task_runner.py:91} INFO - Job 708: Subtask process_link_2
[2024-06-27T07:50:41.609+0000] {taskinstance.py:1042} DEBUG - previous_execution_date was called
[2024-06-27T07:50:41.618+0000] {task_command.py:426} INFO - Running <TaskInstance: USER.process_link_2 manual__2024-06-27T07:50:33.544496+00:00 [running]> on host ccfa35e0da07
[2024-06-27T07:50:41.619+0000] {settings.py:363} DEBUG - Disposing DB connection pool (PID 107)
[2024-06-27T07:50:41.620+0000] {settings.py:250} DEBUG - Setting up DB connection pool (PID 107)
[2024-06-27T07:50:41.621+0000] {settings.py:298} DEBUG - settings.prepare_engine_args(): Using NullPool
[2024-06-27T07:50:41.719+0000] {taskinstance.py:1042} DEBUG - previous_execution_date was called
[2024-06-27T07:50:41.789+0000] {taskinstance.py:2648} INFO - Exporting env vars: AIRFLOW_CTX_DAG_OWNER='***' AIRFLOW_CTX_DAG_ID='USER' AIRFLOW_CTX_TASK_ID='process_link_2' AIRFLOW_CTX_EXECUTION_DATE='2024-06-27T07:50:33.544496+00:00' AIRFLOW_CTX_TRY_NUMBER='1' AIRFLOW_CTX_DAG_RUN_ID='manual__2024-06-27T07:50:33.544496+00:00'
[2024-06-27T07:50:41.792+0000] {taskinstance.py:430} INFO - ::endgroup::
[2024-06-27T07:50:43.561+0000] {connectionpool.py:244} DEBUG - Starting new HTTP connection (1): localhost:36071
[2024-06-27T07:50:44.832+0000] {connectionpool.py:549} DEBUG - http://localhost:36071 "POST /session HTTP/1.1" 200 0
[2024-06-27T07:50:47.038+0000] {connectionpool.py:549} DEBUG - http://localhost:36071 "POST /session/947bdd02824de56ac4a752e814118e56/url HTTP/1.1" 200 0
[2024-06-27T07:50:47.247+0000] {connectionpool.py:549} DEBUG - http://localhost:36071 "GET /session/947bdd02824de56ac4a752e814118e56/source HTTP/1.1" 200 0
[2024-06-27T07:50:47.338+0000] {connectionpool.py:549} DEBUG - http://localhost:36071 "POST /session/947bdd02824de56ac4a752e814118e56/timeouts HTTP/1.1" 200 0
[2024-06-27T07:50:47.352+0000] {fun_user.py:70} INFO - Found id: 100014218684116
[2024-06-27T07:50:47.385+0000] {connectionpool.py:1055} DEBUG - Starting new HTTPS connection (1): graph.facebook.com:443
[2024-06-27T07:50:48.133+0000] {connectionpool.py:549} DEBUG - https://graph.facebook.com:443 "GET /v20.0/100014218684116?fields=id,name,picture,location,work,education,relationship_status,events,email,mobile_phone,gender,birthday&access_token=*** HTTP/1.1" 200 1066
[2024-06-27T07:50:48.151+0000] {connectionpool.py:1055} DEBUG - Starting new HTTPS connection (1): graph.facebook.com:443
[2024-06-27T07:50:48.673+0000] {connectionpool.py:549} DEBUG - https://graph.facebook.com:443 "GET /v20.0/100014218684116/family?access_token=***&fields=id,name,relationship&limit=15 HTTP/1.1" 200 11
[2024-06-27T07:50:48.691+0000] {connectionpool.py:1055} DEBUG - Starting new HTTPS connection (1): graph.facebook.com:443
[2024-06-27T07:50:52.507+0000] {connectionpool.py:549} DEBUG - https://graph.facebook.com:443 "GET /v20.0/100014218684116/friends?access_token=***&fields=id,name,link HTTP/1.1" 200 1339
[2024-06-27T07:50:52.517+0000] {connectionpool.py:1055} DEBUG - Starting new HTTPS connection (1): graph.facebook.com:443
[2024-06-27T07:51:02.543+0000] {taskinstance.py:441} INFO - ::group::Post task execution logs
[2024-06-27T07:51:02.595+0000] {taskinstance.py:2905} ERROR - Task failed with exception
Traceback (most recent call last):
  File "/home/airflow/.local/lib/python3.12/site-packages/urllib3/connection.py", line 198, in _new_conn
    sock = connection.create_connection(
           ^^^^^^^^^^^^^^^^^^^^^^^^^^^^^
  File "/home/airflow/.local/lib/python3.12/site-packages/urllib3/util/connection.py", line 60, in create_connection
    for res in socket.getaddrinfo(host, port, family, socket.SOCK_STREAM):
               ^^^^^^^^^^^^^^^^^^^^^^^^^^^^^^^^^^^^^^^^^^^^^^^^^^^^^^^^^^
  File "/usr/local/lib/python3.12/socket.py", line 964, in getaddrinfo
    for res in _socket.getaddrinfo(host, port, family, type, proto, flags):
               ^^^^^^^^^^^^^^^^^^^^^^^^^^^^^^^^^^^^^^^^^^^^^^^^^^^^^^^^^^^
socket.gaierror: [Errno -3] Temporary failure in name resolution

The above exception was the direct cause of the following exception:

Traceback (most recent call last):
  File "/home/airflow/.local/lib/python3.12/site-packages/urllib3/connectionpool.py", line 793, in urlopen
    response = self._make_request(
               ^^^^^^^^^^^^^^^^^^^
  File "/home/airflow/.local/lib/python3.12/site-packages/urllib3/connectionpool.py", line 491, in _make_request
    raise new_e
  File "/home/airflow/.local/lib/python3.12/site-packages/urllib3/connectionpool.py", line 467, in _make_request
    self._validate_conn(conn)
  File "/home/airflow/.local/lib/python3.12/site-packages/urllib3/connectionpool.py", line 1099, in _validate_conn
    conn.connect()
  File "/home/airflow/.local/lib/python3.12/site-packages/urllib3/connection.py", line 616, in connect
    self.sock = sock = self._new_conn()
                       ^^^^^^^^^^^^^^^^
  File "/home/airflow/.local/lib/python3.12/site-packages/urllib3/connection.py", line 205, in _new_conn
    raise NameResolutionError(self.host, self, e) from e
urllib3.exceptions.NameResolutionError: <urllib3.connection.HTTPSConnection object at 0x7f1d6c648d40>: Failed to resolve 'graph.facebook.com' ([Errno -3] Temporary failure in name resolution)

The above exception was the direct cause of the following exception:

Traceback (most recent call last):
  File "/home/airflow/.local/lib/python3.12/site-packages/requests/adapters.py", line 486, in send
    resp = conn.urlopen(
           ^^^^^^^^^^^^^
  File "/home/airflow/.local/lib/python3.12/site-packages/urllib3/connectionpool.py", line 847, in urlopen
    retries = retries.increment(
              ^^^^^^^^^^^^^^^^^^
  File "/home/airflow/.local/lib/python3.12/site-packages/urllib3/util/retry.py", line 515, in increment
    raise MaxRetryError(_pool, url, reason) from reason  # type: ignore[arg-type]
    ^^^^^^^^^^^^^^^^^^^^^^^^^^^^^^^^^^^^^^^^^^^^^^^^^^^
urllib3.exceptions.MaxRetryError: HTTPSConnectionPool(host='graph.facebook.com', port=443): Max retries exceeded with url: /v20.0/100014218684116/friends?access_token=***&fields=id,name,link&after=QVFIUndjSC1nODVuVzIxOU1kRy1TTnJRRVJ6SlBRRkpFYUk1V3JqZAElJV2kycGh1UFZA4MG01emNPd0ZAWWkxMVWR2endzcUZALbS13Q3ZAFRF9lOFktX0dVR0hn (Caused by NameResolutionError("<urllib3.connection.HTTPSConnection object at 0x7f1d6c648d40>: Failed to resolve 'graph.facebook.com' ([Errno -3] Temporary failure in name resolution)"))

During handling of the above exception, another exception occurred:

Traceback (most recent call last):
  File "/home/airflow/.local/lib/python3.12/site-packages/airflow/models/taskinstance.py", line 465, in _execute_task
    result = _execute_callable(context=context, **execute_callable_kwargs)
             ^^^^^^^^^^^^^^^^^^^^^^^^^^^^^^^^^^^^^^^^^^^^^^^^^^^^^^^^^^^^^
  File "/home/airflow/.local/lib/python3.12/site-packages/airflow/models/taskinstance.py", line 432, in _execute_callable
    return execute_callable(context=context, **execute_callable_kwargs)
           ^^^^^^^^^^^^^^^^^^^^^^^^^^^^^^^^^^^^^^^^^^^^^^^^^^^^^^^^^^^^
  File "/home/airflow/.local/lib/python3.12/site-packages/airflow/models/baseoperator.py", line 401, in wrapper
    return func(self, *args, **kwargs)
           ^^^^^^^^^^^^^^^^^^^^^^^^^^^
  File "/home/airflow/.local/lib/python3.12/site-packages/airflow/operators/python.py", line 235, in execute
    return_value = self.execute_callable()
                   ^^^^^^^^^^^^^^^^^^^^^^^
  File "/home/airflow/.local/lib/python3.12/site-packages/airflow/operators/python.py", line 252, in execute_callable
    return self.python_callable(*self.op_args, **self.op_kwargs)
           ^^^^^^^^^^^^^^^^^^^^^^^^^^^^^^^^^^^^^^^^^^^^^^^^^^^^^
  File "/opt/airflow/dags/user_airflow.py", line 122, in process_link
    result = run_selenium_job(link)
             ^^^^^^^^^^^^^^^^^^^^^^
  File "/opt/airflow/dags/user_airflow.py", line 68, in run_selenium_job
    result = functions_instance.get_all_data(page_id, access_token)
             ^^^^^^^^^^^^^^^^^^^^^^^^^^^^^^^^^^^^^^^^^^^^^^^^^^^^^^
  File "/opt/airflow/dags/fun/fun_user.py", line 247, in get_all_data
    result['fb_friends'] = self.get_friends(user_id, access_token)
                           ^^^^^^^^^^^^^^^^^^^^^^^^^^^^^^^^^^^^^^^
  File "/opt/airflow/dags/fun/fun_user.py", line 83, in get_friends
    data = self.fetch_user(url)
           ^^^^^^^^^^^^^^^^^^^^
  File "/opt/airflow/dags/fun/fun_user.py", line 74, in fetch_user
    response = requests.get(url)
               ^^^^^^^^^^^^^^^^^
  File "/home/airflow/.local/lib/python3.12/site-packages/requests/api.py", line 73, in get
    return request("get", url, params=params, **kwargs)
           ^^^^^^^^^^^^^^^^^^^^^^^^^^^^^^^^^^^^^^^^^^^^
  File "/home/airflow/.local/lib/python3.12/site-packages/requests/api.py", line 59, in request
    return session.request(method=method, url=url, **kwargs)
           ^^^^^^^^^^^^^^^^^^^^^^^^^^^^^^^^^^^^^^^^^^^^^^^^^
  File "/home/airflow/.local/lib/python3.12/site-packages/requests/sessions.py", line 589, in request
    resp = self.send(prep, **send_kwargs)
           ^^^^^^^^^^^^^^^^^^^^^^^^^^^^^^
  File "/home/airflow/.local/lib/python3.12/site-packages/requests/sessions.py", line 703, in send
    r = adapter.send(request, **kwargs)
        ^^^^^^^^^^^^^^^^^^^^^^^^^^^^^^^
  File "/home/airflow/.local/lib/python3.12/site-packages/requests/adapters.py", line 519, in send
    raise ConnectionError(e, request=request)
requests.exceptions.ConnectionError: HTTPSConnectionPool(host='graph.facebook.com', port=443): Max retries exceeded with url: /v20.0/100014218684116/friends?access_token=***&fields=id,name,link&after=QVFIUndjSC1nODVuVzIxOU1kRy1TTnJRRVJ6SlBRRkpFYUk1V3JqZAElJV2kycGh1UFZA4MG01emNPd0ZAWWkxMVWR2endzcUZALbS13Q3ZAFRF9lOFktX0dVR0hn (Caused by NameResolutionError("<urllib3.connection.HTTPSConnection object at 0x7f1d6c648d40>: Failed to resolve 'graph.facebook.com' ([Errno -3] Temporary failure in name resolution)"))
[2024-06-27T07:51:12.827+0000] {standard_task_runner.py:110} ERROR - Failed to execute job 708 for task process_link_2 ((psycopg2.OperationalError) could not translate host name "postgres" to address: Temporary failure in name resolution

(Background on this error at: https://sqlalche.me/e/14/e3q8); 107)
[2024-06-27T07:51:32.555+0000] {local_task_job_runner.py:240} INFO - Task exited with return code 1
[2024-06-27T07:51:32.732+0000] {taskinstance.py:3503} INFO - 0 downstream tasks scheduled from follow-on schedule check
[2024-06-27T07:51:32.743+0000] {local_task_job_runner.py:222} INFO - ::endgroup::
