[2024-06-25T08:36:52.341+0000] {taskinstance.py:1042} DEBUG - previous_execution_date was called
[2024-06-25T08:36:52.444+0000] {taskinstance.py:1042} DEBUG - previous_execution_date was called
[2024-06-25T08:36:52.520+0000] {local_task_job_runner.py:120} INFO - ::group::Pre task execution logs
[2024-06-25T08:36:52.670+0000] {taskinstance.py:2076} INFO - Dependencies all met for dep_context=non-requeueable deps ti=<TaskInstance: selenium_minio.run_selenium_task manual__2024-06-25T08:36:45.173029+00:00 [queued]>
[2024-06-25T08:36:52.726+0000] {taskinstance.py:2076} INFO - Dependencies all met for dep_context=requeueable deps ti=<TaskInstance: selenium_minio.run_selenium_task manual__2024-06-25T08:36:45.173029+00:00 [queued]>
[2024-06-25T08:36:52.727+0000] {taskinstance.py:2306} INFO - Starting attempt 1 of 1
[2024-06-25T08:36:52.843+0000] {taskinstance.py:2330} INFO - Executing <Task(PythonOperator): run_selenium_task> on 2024-06-25 08:36:45.173029+00:00
[2024-06-25T08:36:52.883+0000] {warnings.py:112} WARNING - /home/***/.local/lib/python3.12/site-packages/***/task/task_runner/standard_task_runner.py:61: DeprecationWarning: This process (pid=770) is multi-threaded, use of fork() may lead to deadlocks in the child.
  pid = os.fork()

[2024-06-25T08:36:52.892+0000] {standard_task_runner.py:63} INFO - Started process 771 to run task
[2024-06-25T08:36:52.887+0000] {standard_task_runner.py:90} INFO - Running: ['***', 'tasks', 'run', 'selenium_minio', 'run_selenium_task', 'manual__2024-06-25T08:36:45.173029+00:00', '--job-id', '460', '--raw', '--subdir', 'DAGS_FOLDER/crawl_minio.py', '--cfg-path', '/tmp/tmpnc_gvlw1']
[2024-06-25T08:36:52.896+0000] {standard_task_runner.py:91} INFO - Job 460: Subtask run_selenium_task
[2024-06-25T08:36:52.977+0000] {taskinstance.py:1042} DEBUG - previous_execution_date was called
[2024-06-25T08:36:52.986+0000] {task_command.py:426} INFO - Running <TaskInstance: selenium_minio.run_selenium_task manual__2024-06-25T08:36:45.173029+00:00 [running]> on host ae041f19a8bf
[2024-06-25T08:36:52.987+0000] {settings.py:363} DEBUG - Disposing DB connection pool (PID 771)
[2024-06-25T08:36:52.988+0000] {settings.py:250} DEBUG - Setting up DB connection pool (PID 771)
[2024-06-25T08:36:52.989+0000] {settings.py:298} DEBUG - settings.prepare_engine_args(): Using NullPool
[2024-06-25T08:36:53.051+0000] {taskinstance.py:1042} DEBUG - previous_execution_date was called
[2024-06-25T08:36:53.213+0000] {taskinstance.py:2648} INFO - Exporting env vars: AIRFLOW_CTX_DAG_OWNER='***' AIRFLOW_CTX_DAG_ID='selenium_minio' AIRFLOW_CTX_TASK_ID='run_selenium_task' AIRFLOW_CTX_EXECUTION_DATE='2024-06-25T08:36:45.173029+00:00' AIRFLOW_CTX_TRY_NUMBER='1' AIRFLOW_CTX_DAG_RUN_ID='manual__2024-06-25T08:36:45.173029+00:00'
[2024-06-25T08:36:53.215+0000] {taskinstance.py:430} INFO - ::endgroup::
[2024-06-25T08:37:02.101+0000] {logging_mixin.py:188} INFO - ok
[2024-06-25T08:37:16.412+0000] {fun_page.py:109} INFO - getting another set
[2024-06-25T08:37:19.263+0000] {fun_page.py:109} INFO - getting another set
[2024-06-25T08:37:23.678+0000] {fun_page.py:109} INFO - getting another set
[2024-06-25T08:37:30.646+0000] {fun_page.py:109} INFO - getting another set
[2024-06-25T08:37:33.833+0000] {fun_page.py:109} INFO - getting another set
[2024-06-25T08:37:38.261+0000] {fun_page.py:109} INFO - getting another set
[2024-06-25T08:37:48.910+0000] {fun_page.py:109} INFO - getting another set
[2024-06-25T08:37:55.167+0000] {fun_page.py:109} INFO - getting another set
[2024-06-25T08:37:59.930+0000] {fun_page.py:109} INFO - getting another set
[2024-06-25T08:38:09.673+0000] {fun_page.py:109} INFO - getting another set
[2024-06-25T08:38:14.684+0000] {fun_page.py:109} INFO - getting another set
[2024-06-25T08:38:18.376+0000] {fun_page.py:109} INFO - getting another set
[2024-06-25T08:38:23.079+0000] {fun_page.py:109} INFO - getting another set
[2024-06-25T08:38:26.679+0000] {fun_page.py:109} INFO - getting another set
[2024-06-25T08:38:31.289+0000] {fun_page.py:109} INFO - getting another set
[2024-06-25T08:38:36.495+0000] {fun_page.py:109} INFO - getting another set
[2024-06-25T08:38:40.352+0000] {fun_page.py:109} INFO - getting another set
[2024-06-25T08:38:45.257+0000] {fun_page.py:109} INFO - getting another set
[2024-06-25T08:38:48.376+0000] {fun_page.py:109} INFO - getting another set
[2024-06-25T08:38:51.581+0000] {fun_page.py:109} INFO - getting another set
[2024-06-25T08:38:55.946+0000] {fun_page.py:109} INFO - getting another set
[2024-06-25T08:38:58.698+0000] {fun_page.py:109} INFO - getting another set
[2024-06-25T08:39:02.587+0000] {fun_page.py:109} INFO - getting another set
[2024-06-25T08:39:07.244+0000] {fun_page.py:109} INFO - getting another set
[2024-06-25T08:39:46.708+0000] {job.py:218} ERROR - Job heartbeat got an exception
Traceback (most recent call last):
  File "/home/airflow/.local/lib/python3.12/site-packages/sqlalchemy/engine/base.py", line 3371, in _wrap_pool_connect
    return fn()
           ^^^^
  File "/home/airflow/.local/lib/python3.12/site-packages/sqlalchemy/pool/base.py", line 327, in connect
    return _ConnectionFairy._checkout(self)
           ^^^^^^^^^^^^^^^^^^^^^^^^^^^^^^^^
  File "/home/airflow/.local/lib/python3.12/site-packages/sqlalchemy/pool/base.py", line 894, in _checkout
    fairy = _ConnectionRecord.checkout(pool)
            ^^^^^^^^^^^^^^^^^^^^^^^^^^^^^^^^
  File "/home/airflow/.local/lib/python3.12/site-packages/sqlalchemy/pool/base.py", line 493, in checkout
    rec = pool._do_get()
          ^^^^^^^^^^^^^^
  File "/home/airflow/.local/lib/python3.12/site-packages/sqlalchemy/pool/impl.py", line 256, in _do_get
    return self._create_connection()
           ^^^^^^^^^^^^^^^^^^^^^^^^^
  File "/home/airflow/.local/lib/python3.12/site-packages/sqlalchemy/pool/base.py", line 273, in _create_connection
    return _ConnectionRecord(self)
           ^^^^^^^^^^^^^^^^^^^^^^^
  File "/home/airflow/.local/lib/python3.12/site-packages/sqlalchemy/pool/base.py", line 388, in __init__
    self.__connect()
  File "/home/airflow/.local/lib/python3.12/site-packages/sqlalchemy/pool/base.py", line 690, in __connect
    with util.safe_reraise():
  File "/home/airflow/.local/lib/python3.12/site-packages/sqlalchemy/util/langhelpers.py", line 70, in __exit__
    compat.raise_(
  File "/home/airflow/.local/lib/python3.12/site-packages/sqlalchemy/util/compat.py", line 211, in raise_
    raise exception
  File "/home/airflow/.local/lib/python3.12/site-packages/sqlalchemy/pool/base.py", line 686, in __connect
    self.dbapi_connection = connection = pool._invoke_creator(self)
                                         ^^^^^^^^^^^^^^^^^^^^^^^^^^
  File "/home/airflow/.local/lib/python3.12/site-packages/sqlalchemy/engine/create.py", line 574, in connect
    return dialect.connect(*cargs, **cparams)
           ^^^^^^^^^^^^^^^^^^^^^^^^^^^^^^^^^^
  File "/home/airflow/.local/lib/python3.12/site-packages/sqlalchemy/engine/default.py", line 598, in connect
    return self.dbapi.connect(*cargs, **cparams)
           ^^^^^^^^^^^^^^^^^^^^^^^^^^^^^^^^^^^^^
  File "/home/airflow/.local/lib/python3.12/site-packages/psycopg2/__init__.py", line 122, in connect
    conn = _connect(dsn, connection_factory=connection_factory, **kwasync)
           ^^^^^^^^^^^^^^^^^^^^^^^^^^^^^^^^^^^^^^^^^^^^^^^^^^^^^^^^^^^^^^^
psycopg2.OperationalError: could not translate host name "postgres" to address: Temporary failure in name resolution


The above exception was the direct cause of the following exception:

Traceback (most recent call last):
  File "/home/airflow/.local/lib/python3.12/site-packages/airflow/jobs/job.py", line 192, in heartbeat
    self._merge_from(Job._fetch_from_db(self, session))
                     ^^^^^^^^^^^^^^^^^^^^^^^^^^^^^^^^^
  File "/home/airflow/.local/lib/python3.12/site-packages/airflow/api_internal/internal_api_call.py", line 115, in wrapper
    return func(*args, **kwargs)
           ^^^^^^^^^^^^^^^^^^^^^
  File "/home/airflow/.local/lib/python3.12/site-packages/airflow/utils/session.py", line 76, in wrapper
    return func(*args, **kwargs)
           ^^^^^^^^^^^^^^^^^^^^^
  File "/home/airflow/.local/lib/python3.12/site-packages/airflow/utils/retries.py", line 89, in wrapped_function
    for attempt in run_with_db_retries(max_retries=retries, logger=logger, **retry_kwargs):
  File "/home/airflow/.local/lib/python3.12/site-packages/tenacity/__init__.py", line 435, in __iter__
    do = self.iter(retry_state=retry_state)
         ^^^^^^^^^^^^^^^^^^^^^^^^^^^^^^^^^^
  File "/home/airflow/.local/lib/python3.12/site-packages/tenacity/__init__.py", line 368, in iter
    result = action(retry_state)
             ^^^^^^^^^^^^^^^^^^^
  File "/home/airflow/.local/lib/python3.12/site-packages/tenacity/__init__.py", line 410, in exc_check
    raise retry_exc.reraise()
          ^^^^^^^^^^^^^^^^^^^
  File "/home/airflow/.local/lib/python3.12/site-packages/tenacity/__init__.py", line 183, in reraise
    raise self.last_attempt.result()
          ^^^^^^^^^^^^^^^^^^^^^^^^^^
  File "/usr/local/lib/python3.12/concurrent/futures/_base.py", line 449, in result
    return self.__get_result()
           ^^^^^^^^^^^^^^^^^^^
  File "/usr/local/lib/python3.12/concurrent/futures/_base.py", line 401, in __get_result
    raise self._exception
  File "/home/airflow/.local/lib/python3.12/site-packages/airflow/utils/retries.py", line 98, in wrapped_function
    return func(*args, **kwargs)
           ^^^^^^^^^^^^^^^^^^^^^
  File "/home/airflow/.local/lib/python3.12/site-packages/airflow/jobs/job.py", line 316, in _fetch_from_db
    session.merge(job)
  File "/home/airflow/.local/lib/python3.12/site-packages/sqlalchemy/orm/session.py", line 3056, in merge
    return self._merge(
           ^^^^^^^^^^^^
  File "/home/airflow/.local/lib/python3.12/site-packages/sqlalchemy/orm/session.py", line 3136, in _merge
    merged = self.get(
             ^^^^^^^^^
  File "/home/airflow/.local/lib/python3.12/site-packages/sqlalchemy/orm/session.py", line 2853, in get
    return self._get_impl(
           ^^^^^^^^^^^^^^^
  File "/home/airflow/.local/lib/python3.12/site-packages/sqlalchemy/orm/session.py", line 2975, in _get_impl
    return db_load_fn(
           ^^^^^^^^^^^
  File "/home/airflow/.local/lib/python3.12/site-packages/sqlalchemy/orm/loading.py", line 530, in load_on_pk_identity
    session.execute(
  File "/home/airflow/.local/lib/python3.12/site-packages/sqlalchemy/orm/session.py", line 1716, in execute
    conn = self._connection_for_bind(bind)
           ^^^^^^^^^^^^^^^^^^^^^^^^^^^^^^^
  File "/home/airflow/.local/lib/python3.12/site-packages/sqlalchemy/orm/session.py", line 1555, in _connection_for_bind
    return self._transaction._connection_for_bind(
           ^^^^^^^^^^^^^^^^^^^^^^^^^^^^^^^^^^^^^^^
  File "/home/airflow/.local/lib/python3.12/site-packages/sqlalchemy/orm/session.py", line 750, in _connection_for_bind
    conn = bind.connect()
           ^^^^^^^^^^^^^^
  File "/home/airflow/.local/lib/python3.12/site-packages/sqlalchemy/future/engine.py", line 412, in connect
    return super(Engine, self).connect()
           ^^^^^^^^^^^^^^^^^^^^^^^^^^^^^
  File "/home/airflow/.local/lib/python3.12/site-packages/sqlalchemy/engine/base.py", line 3325, in connect
    return self._connection_cls(self, close_with_result=close_with_result)
           ^^^^^^^^^^^^^^^^^^^^^^^^^^^^^^^^^^^^^^^^^^^^^^^^^^^^^^^^^^^^^^^
  File "/home/airflow/.local/lib/python3.12/site-packages/sqlalchemy/engine/base.py", line 96, in __init__
    else engine.raw_connection()
         ^^^^^^^^^^^^^^^^^^^^^^^
  File "/home/airflow/.local/lib/python3.12/site-packages/sqlalchemy/engine/base.py", line 3404, in raw_connection
    return self._wrap_pool_connect(self.pool.connect, _connection)
           ^^^^^^^^^^^^^^^^^^^^^^^^^^^^^^^^^^^^^^^^^^^^^^^^^^^^^^^
  File "/home/airflow/.local/lib/python3.12/site-packages/sqlalchemy/engine/base.py", line 3374, in _wrap_pool_connect
    Connection._handle_dbapi_exception_noconnection(
  File "/home/airflow/.local/lib/python3.12/site-packages/sqlalchemy/engine/base.py", line 2208, in _handle_dbapi_exception_noconnection
    util.raise_(
  File "/home/airflow/.local/lib/python3.12/site-packages/sqlalchemy/util/compat.py", line 211, in raise_
    raise exception
  File "/home/airflow/.local/lib/python3.12/site-packages/sqlalchemy/engine/base.py", line 3371, in _wrap_pool_connect
    return fn()
           ^^^^
  File "/home/airflow/.local/lib/python3.12/site-packages/sqlalchemy/pool/base.py", line 327, in connect
    return _ConnectionFairy._checkout(self)
           ^^^^^^^^^^^^^^^^^^^^^^^^^^^^^^^^
  File "/home/airflow/.local/lib/python3.12/site-packages/sqlalchemy/pool/base.py", line 894, in _checkout
    fairy = _ConnectionRecord.checkout(pool)
            ^^^^^^^^^^^^^^^^^^^^^^^^^^^^^^^^
  File "/home/airflow/.local/lib/python3.12/site-packages/sqlalchemy/pool/base.py", line 493, in checkout
    rec = pool._do_get()
          ^^^^^^^^^^^^^^
  File "/home/airflow/.local/lib/python3.12/site-packages/sqlalchemy/pool/impl.py", line 256, in _do_get
    return self._create_connection()
           ^^^^^^^^^^^^^^^^^^^^^^^^^
  File "/home/airflow/.local/lib/python3.12/site-packages/sqlalchemy/pool/base.py", line 273, in _create_connection
    return _ConnectionRecord(self)
           ^^^^^^^^^^^^^^^^^^^^^^^
  File "/home/airflow/.local/lib/python3.12/site-packages/sqlalchemy/pool/base.py", line 388, in __init__
    self.__connect()
  File "/home/airflow/.local/lib/python3.12/site-packages/sqlalchemy/pool/base.py", line 690, in __connect
    with util.safe_reraise():
  File "/home/airflow/.local/lib/python3.12/site-packages/sqlalchemy/util/langhelpers.py", line 70, in __exit__
    compat.raise_(
  File "/home/airflow/.local/lib/python3.12/site-packages/sqlalchemy/util/compat.py", line 211, in raise_
    raise exception
  File "/home/airflow/.local/lib/python3.12/site-packages/sqlalchemy/pool/base.py", line 686, in __connect
    self.dbapi_connection = connection = pool._invoke_creator(self)
                                         ^^^^^^^^^^^^^^^^^^^^^^^^^^
  File "/home/airflow/.local/lib/python3.12/site-packages/sqlalchemy/engine/create.py", line 574, in connect
    return dialect.connect(*cargs, **cparams)
           ^^^^^^^^^^^^^^^^^^^^^^^^^^^^^^^^^^
  File "/home/airflow/.local/lib/python3.12/site-packages/sqlalchemy/engine/default.py", line 598, in connect
    return self.dbapi.connect(*cargs, **cparams)
           ^^^^^^^^^^^^^^^^^^^^^^^^^^^^^^^^^^^^^
  File "/home/airflow/.local/lib/python3.12/site-packages/psycopg2/__init__.py", line 122, in connect
    conn = _connect(dsn, connection_factory=connection_factory, **kwasync)
           ^^^^^^^^^^^^^^^^^^^^^^^^^^^^^^^^^^^^^^^^^^^^^^^^^^^^^^^^^^^^^^^
sqlalchemy.exc.OperationalError: (psycopg2.OperationalError) could not translate host name "postgres" to address: Temporary failure in name resolution

(Background on this error at: https://sqlalche.me/e/14/e3q8)
[2024-06-25T08:39:46.766+0000] {job.py:226} ERROR - Job heartbeat failed with error. Scheduler is in unhealthy state
[2024-06-25T08:39:50.925+0000] {fun_page.py:109} INFO - getting another set
[2024-06-25T08:39:54.883+0000] {fun_page.py:109} INFO - getting another set
[2024-06-25T08:39:59.598+0000] {fun_page.py:109} INFO - getting another set
[2024-06-25T08:40:08.310+0000] {fun_page.py:109} INFO - getting another set
[2024-06-25T08:40:12.012+0000] {fun_page.py:109} INFO - getting another set
[2024-06-25T08:40:15.565+0000] {fun_page.py:109} INFO - getting another set
[2024-06-25T08:40:41.688+0000] {fun_page.py:109} INFO - getting another set
[2024-06-25T08:40:46.212+0000] {fun_page.py:109} INFO - getting another set
[2024-06-25T08:40:49.709+0000] {fun_page.py:109} INFO - getting another set
[2024-06-25T08:40:53.554+0000] {fun_page.py:109} INFO - getting another set
[2024-06-25T08:41:00.019+0000] {fun_page.py:109} INFO - getting another set
[2024-06-25T08:41:04.553+0000] {fun_page.py:109} INFO - getting another set
[2024-06-25T08:41:39.572+0000] {fun_page.py:109} INFO - getting another set
[2024-06-25T08:41:44.619+0000] {fun_page.py:109} INFO - getting another set
[2024-06-25T08:41:49.317+0000] {fun_page.py:109} INFO - getting another set
[2024-06-25T08:41:52.935+0000] {fun_page.py:109} INFO - getting another set
[2024-06-25T08:42:03.542+0000] {fun_page.py:109} INFO - getting another set
[2024-06-25T08:42:35.537+0000] {fun_page.py:109} INFO - getting another set
[2024-06-25T08:42:43.601+0000] {fun_page.py:109} INFO - getting another set
[2024-06-25T08:42:47.112+0000] {fun_page.py:109} INFO - getting another set
[2024-06-25T08:42:51.035+0000] {fun_page.py:109} INFO - getting another set
[2024-06-25T08:43:02.871+0000] {fun_page.py:109} INFO - getting another set
[2024-06-25T08:43:07.494+0000] {fun_page.py:109} INFO - getting another set
[2024-06-25T08:43:53.026+0000] {job.py:226} ERROR - Job heartbeat failed with error. Scheduler is in unhealthy state
[2024-06-25T08:44:42.047+0000] {job.py:226} ERROR - Job heartbeat failed with error. Scheduler is in unhealthy state
[2024-06-25T08:45:52.215+0000] {crawl_minio.py:36} ERROR - Error running Selenium job: Message: unknown error: session deleted because of page crash
from unknown error: cannot determine loading status
from tab crashed
  (Session info: chrome-headless-shell=126.0.6478.114)
Stacktrace:
#0 0x55db589d68ae <unknown>
#1 0x55db586a7966 <unknown>
#2 0x55db58694899 <unknown>
#3 0x55db58693fa6 <unknown>
#4 0x55db5869384b <unknown>
#5 0x55db586936e0 <unknown>
#6 0x55db58691ba0 <unknown>
#7 0x55db586920b9 <unknown>
#8 0x55db5869fa14 <unknown>
#9 0x55db586b2f6f <unknown>
#10 0x55db586b768b <unknown>
#11 0x55db5869265b <unknown>
#12 0x55db586b2b71 <unknown>
#13 0x55db5872eb22 <unknown>
#14 0x55db58711893 <unknown>
#15 0x55db586e22ed <unknown>
#16 0x55db586e3092 <unknown>
#17 0x55db589a6256 <unknown>
#18 0x55db589a95f9 <unknown>
#19 0x55db589a90bf <unknown>
#20 0x55db589a9a75 <unknown>
#21 0x55db5899679f <unknown>
#22 0x55db589a9dc0 <unknown>
#23 0x55db5897f6c6 <unknown>
#24 0x55db589c6fb5 <unknown>
#25 0x55db589c71a2 <unknown>
#26 0x55db589d5d9a <unknown>
#27 0x7f693265f134 <unknown>

[2024-06-25T08:45:52.637+0000] {taskinstance.py:441} INFO - ::group::Post task execution logs
[2024-06-25T08:45:52.640+0000] {taskinstance.py:2905} ERROR - Task failed with exception
Traceback (most recent call last):
  File "/home/airflow/.local/lib/python3.12/site-packages/airflow/models/taskinstance.py", line 465, in _execute_task
    result = _execute_callable(context=context, **execute_callable_kwargs)
             ^^^^^^^^^^^^^^^^^^^^^^^^^^^^^^^^^^^^^^^^^^^^^^^^^^^^^^^^^^^^^
  File "/home/airflow/.local/lib/python3.12/site-packages/airflow/models/taskinstance.py", line 432, in _execute_callable
    return execute_callable(context=context, **execute_callable_kwargs)
           ^^^^^^^^^^^^^^^^^^^^^^^^^^^^^^^^^^^^^^^^^^^^^^^^^^^^^^^^^^^^
  File "/home/airflow/.local/lib/python3.12/site-packages/airflow/models/baseoperator.py", line 401, in wrapper
    return func(self, *args, **kwargs)
           ^^^^^^^^^^^^^^^^^^^^^^^^^^^
  File "/home/airflow/.local/lib/python3.12/site-packages/airflow/operators/python.py", line 235, in execute
    return_value = self.execute_callable()
                   ^^^^^^^^^^^^^^^^^^^^^^^
  File "/home/airflow/.local/lib/python3.12/site-packages/airflow/operators/python.py", line 252, in execute_callable
    return self.python_callable(*self.op_args, **self.op_kwargs)
           ^^^^^^^^^^^^^^^^^^^^^^^^^^^^^^^^^^^^^^^^^^^^^^^^^^^^^
  File "/opt/airflow/dags/crawl_minio.py", line 29, in run_selenium_job
    service = Service(ChromeDriverManager().install())
                 ^^^^^^^^^^^^^^^^^^^^^^^^^^^^^^^^^^^^^^
  File "/opt/airflow/dags/fun/fun_page.py", line 246, in get_all_data
    posts_dict = self.get_posts(driver, user_id, access_token)
                 ^^^^^^^^^^^^^^^^^^^^^^^^^^^^^^^^^^^^^^^^^^^^^
  File "/opt/airflow/dags/fun/fun_page.py", line 94, in get_posts
    driver.get(next_url)
  File "/home/airflow/.local/lib/python3.12/site-packages/selenium/webdriver/remote/webdriver.py", line 356, in get
    self.execute(Command.GET, {"url": url})
  File "/home/airflow/.local/lib/python3.12/site-packages/selenium/webdriver/remote/webdriver.py", line 347, in execute
    self.error_handler.check_response(response)
  File "/home/airflow/.local/lib/python3.12/site-packages/selenium/webdriver/remote/errorhandler.py", line 229, in check_response
    raise exception_class(message, screen, stacktrace)
selenium.common.exceptions.WebDriverException: Message: unknown error: session deleted because of page crash
from unknown error: cannot determine loading status
from tab crashed
  (Session info: chrome-headless-shell=126.0.6478.114)
Stacktrace:
#0 0x55db589d68ae <unknown>
#1 0x55db586a7966 <unknown>
#2 0x55db58694899 <unknown>
#3 0x55db58693fa6 <unknown>
#4 0x55db5869384b <unknown>
#5 0x55db586936e0 <unknown>
#6 0x55db58691ba0 <unknown>
#7 0x55db586920b9 <unknown>
#8 0x55db5869fa14 <unknown>
#9 0x55db586b2f6f <unknown>
#10 0x55db586b768b <unknown>
#11 0x55db5869265b <unknown>
#12 0x55db586b2b71 <unknown>
#13 0x55db5872eb22 <unknown>
#14 0x55db58711893 <unknown>
#15 0x55db586e22ed <unknown>
#16 0x55db586e3092 <unknown>
#17 0x55db589a6256 <unknown>
#18 0x55db589a95f9 <unknown>
#19 0x55db589a90bf <unknown>
#20 0x55db589a9a75 <unknown>
#21 0x55db5899679f <unknown>
#22 0x55db589a9dc0 <unknown>
#23 0x55db5897f6c6 <unknown>
#24 0x55db589c6fb5 <unknown>
#25 0x55db589c71a2 <unknown>
#26 0x55db589d5d9a <unknown>
#27 0x7f693265f134 <unknown>

[2024-06-25T08:45:53.543+0000] {taskinstance.py:562} DEBUG - Task Duration set to 540.870414
[2024-06-25T08:45:53.547+0000] {taskinstance.py:584} DEBUG - Clearing next_method and next_kwargs.
[2024-06-25T08:45:53.550+0000] {taskinstance.py:1206} INFO - Marking task as FAILED. dag_id=selenium_minio, task_id=run_selenium_task, run_id=manual__2024-06-25T08:36:45.173029+00:00, execution_date=20240625T083645, start_date=20240625T083652, end_date=20240625T084553
[2024-06-25T08:45:53.619+0000] {standard_task_runner.py:110} ERROR - Failed to execute job 460 for task run_selenium_task (Message: unknown error: session deleted because of page crash
from unknown error: cannot determine loading status
from tab crashed
  (Session info: chrome-headless-shell=126.0.6478.114)
Stacktrace:
#0 0x55db589d68ae <unknown>
#1 0x55db586a7966 <unknown>
#2 0x55db58694899 <unknown>
#3 0x55db58693fa6 <unknown>
#4 0x55db5869384b <unknown>
#5 0x55db586936e0 <unknown>
#6 0x55db58691ba0 <unknown>
#7 0x55db586920b9 <unknown>
#8 0x55db5869fa14 <unknown>
#9 0x55db586b2f6f <unknown>
#10 0x55db586b768b <unknown>
#11 0x55db5869265b <unknown>
#12 0x55db586b2b71 <unknown>
#13 0x55db5872eb22 <unknown>
#14 0x55db58711893 <unknown>
#15 0x55db586e22ed <unknown>
#16 0x55db586e3092 <unknown>
#17 0x55db589a6256 <unknown>
#18 0x55db589a95f9 <unknown>
#19 0x55db589a90bf <unknown>
#20 0x55db589a9a75 <unknown>
#21 0x55db5899679f <unknown>
#22 0x55db589a9dc0 <unknown>
#23 0x55db5897f6c6 <unknown>
#24 0x55db589c6fb5 <unknown>
#25 0x55db589c71a2 <unknown>
#26 0x55db589d5d9a <unknown>
#27 0x7f693265f134 <unknown>
; 771)
[2024-06-25T08:45:53.700+0000] {local_task_job_runner.py:240} INFO - Task exited with return code 1
[2024-06-25T08:45:53.835+0000] {taskinstance.py:3503} INFO - 0 downstream tasks scheduled from follow-on schedule check
[2024-06-25T08:45:53.851+0000] {local_task_job_runner.py:222} INFO - ::endgroup::
