[2024-06-27T02:15:01.419+0000] {taskinstance.py:1042} DEBUG - previous_execution_date was called
[2024-06-27T02:15:01.454+0000] {taskinstance.py:1042} DEBUG - previous_execution_date was called
[2024-06-27T02:15:01.466+0000] {local_task_job_runner.py:120} INFO - ::group::Pre task execution logs
[2024-06-27T02:15:01.496+0000] {taskinstance.py:2076} INFO - Dependencies all met for dep_context=non-requeueable deps ti=<TaskInstance: test_user1.get_urls_task manual__2024-06-27T02:14:59.154604+00:00 [queued]>
[2024-06-27T02:15:01.506+0000] {taskinstance.py:2076} INFO - Dependencies all met for dep_context=requeueable deps ti=<TaskInstance: test_user1.get_urls_task manual__2024-06-27T02:14:59.154604+00:00 [queued]>
[2024-06-27T02:15:01.508+0000] {taskinstance.py:2306} INFO - Starting attempt 1 of 1
[2024-06-27T02:15:01.526+0000] {taskinstance.py:2330} INFO - Executing <Task(PythonOperator): get_urls_task> on 2024-06-27 02:14:59.154604+00:00
[2024-06-27T02:15:01.532+0000] {warnings.py:112} WARNING - /home/***/.local/lib/python3.12/site-packages/***/task/task_runner/standard_task_runner.py:61: DeprecationWarning: This process (pid=893) is multi-threaded, use of fork() may lead to deadlocks in the child.
  pid = os.fork()

[2024-06-27T02:15:01.534+0000] {standard_task_runner.py:63} INFO - Started process 894 to run task
[2024-06-27T02:15:01.534+0000] {standard_task_runner.py:90} INFO - Running: ['***', 'tasks', 'run', 'test_user1', 'get_urls_task', 'manual__2024-06-27T02:14:59.154604+00:00', '--job-id', '559', '--raw', '--subdir', 'DAGS_FOLDER/first_out.py', '--cfg-path', '/tmp/tmppmm8a0nl']
[2024-06-27T02:15:01.537+0000] {standard_task_runner.py:91} INFO - Job 559: Subtask get_urls_task
[2024-06-27T02:15:01.582+0000] {taskinstance.py:1042} DEBUG - previous_execution_date was called
[2024-06-27T02:15:01.589+0000] {task_command.py:426} INFO - Running <TaskInstance: test_user1.get_urls_task manual__2024-06-27T02:14:59.154604+00:00 [running]> on host ccfa35e0da07
[2024-06-27T02:15:01.590+0000] {settings.py:363} DEBUG - Disposing DB connection pool (PID 894)
[2024-06-27T02:15:01.591+0000] {settings.py:250} DEBUG - Setting up DB connection pool (PID 894)
[2024-06-27T02:15:01.592+0000] {settings.py:298} DEBUG - settings.prepare_engine_args(): Using NullPool
[2024-06-27T02:15:01.645+0000] {taskinstance.py:1042} DEBUG - previous_execution_date was called
[2024-06-27T02:15:01.704+0000] {taskinstance.py:2648} INFO - Exporting env vars: AIRFLOW_CTX_DAG_OWNER='***' AIRFLOW_CTX_DAG_ID='test_user1' AIRFLOW_CTX_TASK_ID='get_urls_task' AIRFLOW_CTX_EXECUTION_DATE='2024-06-27T02:14:59.154604+00:00' AIRFLOW_CTX_TRY_NUMBER='1' AIRFLOW_CTX_DAG_RUN_ID='manual__2024-06-27T02:14:59.154604+00:00'
[2024-06-27T02:15:01.706+0000] {taskinstance.py:430} INFO - ::endgroup::
[2024-06-27T02:15:11.928+0000] {fun_user.py:87} INFO - Found id: 00013963483849,
[2024-06-27T02:15:12.907+0000] {taskinstance.py:441} INFO - ::group::Post task execution logs
[2024-06-27T02:15:12.908+0000] {taskinstance.py:2905} ERROR - Task failed with exception
Traceback (most recent call last):
  File "/home/airflow/.local/lib/python3.12/site-packages/airflow/models/taskinstance.py", line 465, in _execute_task
    result = _execute_callable(context=context, **execute_callable_kwargs)
             ^^^^^^^^^^^^^^^^^^^^^^^^^^^^^^^^^^^^^^^^^^^^^^^^^^^^^^^^^^^^^
  File "/home/airflow/.local/lib/python3.12/site-packages/airflow/models/taskinstance.py", line 432, in _execute_callable
    return execute_callable(context=context, **execute_callable_kwargs)
           ^^^^^^^^^^^^^^^^^^^^^^^^^^^^^^^^^^^^^^^^^^^^^^^^^^^^^^^^^^^^
  File "/home/airflow/.local/lib/python3.12/site-packages/airflow/models/baseoperator.py", line 401, in wrapper
    return func(self, *args, **kwargs)
           ^^^^^^^^^^^^^^^^^^^^^^^^^^^
  File "/home/airflow/.local/lib/python3.12/site-packages/airflow/operators/python.py", line 235, in execute
    return_value = self.execute_callable()
                   ^^^^^^^^^^^^^^^^^^^^^^^
  File "/home/airflow/.local/lib/python3.12/site-packages/airflow/operators/python.py", line 252, in execute_callable
    return self.python_callable(*self.op_args, **self.op_kwargs)
           ^^^^^^^^^^^^^^^^^^^^^^^^^^^^^^^^^^^^^^^^^^^^^^^^^^^^^
  File "/opt/airflow/dags/first_out.py", line 31, in run_selenium_job
    result = functions_instance.get_all_data(page_id, access_token)
             ^^^^^^^^^^^^^^^^^^^^^^^^^^^^^^^^^^^^^^^^^^^^^^^^^^^^^^
  File "/opt/airflow/dags/fun/fun_user.py", line 259, in get_all_data
    result['fb_family'] = self.get_family(user_id, access_token)
                          ^^^^^^^^^^^^^^^^^^^^^^^^^^^^^^^^^^^^^^
  File "/opt/airflow/dags/fun/fun_user.py", line 153, in get_family
    family_list = data['data']
                  ~~~~^^^^^^^^
KeyError: 'data'
[2024-06-27T02:15:12.952+0000] {taskinstance.py:562} DEBUG - Task Duration set to 11.454532
[2024-06-27T02:15:12.954+0000] {taskinstance.py:584} DEBUG - Clearing next_method and next_kwargs.
[2024-06-27T02:15:12.956+0000] {taskinstance.py:1206} INFO - Marking task as FAILED. dag_id=test_user1, task_id=get_urls_task, run_id=manual__2024-06-27T02:14:59.154604+00:00, execution_date=20240627T021459, start_date=20240627T021501, end_date=20240627T021512
[2024-06-27T02:15:12.987+0000] {standard_task_runner.py:110} ERROR - Failed to execute job 559 for task get_urls_task ('data'; 894)
[2024-06-27T02:15:13.028+0000] {local_task_job_runner.py:240} INFO - Task exited with return code 1
[2024-06-27T02:15:13.066+0000] {taskinstance.py:3503} INFO - 0 downstream tasks scheduled from follow-on schedule check
[2024-06-27T02:15:13.072+0000] {local_task_job_runner.py:222} INFO - ::endgroup::
