[2024-06-26T06:56:47.467+0000] {taskinstance.py:1042} DEBUG - previous_execution_date was called
[2024-06-26T06:56:47.532+0000] {taskinstance.py:1042} DEBUG - previous_execution_date was called
[2024-06-26T06:56:47.564+0000] {local_task_job_runner.py:120} INFO - ::group::Pre task execution logs
[2024-06-26T06:56:47.659+0000] {taskinstance.py:2076} INFO - Dependencies all met for dep_context=non-requeueable deps ti=<TaskInstance: selenium_minio.run_selenium_task manual__2024-06-26T06:56:44.207597+00:00 [queued]>
[2024-06-26T06:56:47.678+0000] {taskinstance.py:2076} INFO - Dependencies all met for dep_context=requeueable deps ti=<TaskInstance: selenium_minio.run_selenium_task manual__2024-06-26T06:56:44.207597+00:00 [queued]>
[2024-06-26T06:56:47.679+0000] {taskinstance.py:2306} INFO - Starting attempt 1 of 1
[2024-06-26T06:56:47.702+0000] {taskinstance.py:2330} INFO - Executing <Task(PythonOperator): run_selenium_task> on 2024-06-26 06:56:44.207597+00:00
[2024-06-26T06:56:47.711+0000] {warnings.py:112} WARNING - /home/***/.local/lib/python3.12/site-packages/***/task/task_runner/standard_task_runner.py:61: DeprecationWarning: This process (pid=816) is multi-threaded, use of fork() may lead to deadlocks in the child.
  pid = os.fork()

[2024-06-26T06:56:47.714+0000] {standard_task_runner.py:63} INFO - Started process 817 to run task
[2024-06-26T06:56:47.715+0000] {standard_task_runner.py:90} INFO - Running: ['***', 'tasks', 'run', 'selenium_minio', 'run_selenium_task', 'manual__2024-06-26T06:56:44.207597+00:00', '--job-id', '518', '--raw', '--subdir', 'DAGS_FOLDER/crawl_minio.py', '--cfg-path', '/tmp/tmp_px3c9qm']
[2024-06-26T06:56:47.717+0000] {standard_task_runner.py:91} INFO - Job 518: Subtask run_selenium_task
[2024-06-26T06:56:47.786+0000] {taskinstance.py:1042} DEBUG - previous_execution_date was called
[2024-06-26T06:56:47.796+0000] {task_command.py:426} INFO - Running <TaskInstance: selenium_minio.run_selenium_task manual__2024-06-26T06:56:44.207597+00:00 [running]> on host ccfa35e0da07
[2024-06-26T06:56:47.797+0000] {settings.py:363} DEBUG - Disposing DB connection pool (PID 817)
[2024-06-26T06:56:47.798+0000] {settings.py:250} DEBUG - Setting up DB connection pool (PID 817)
[2024-06-26T06:56:47.799+0000] {settings.py:298} DEBUG - settings.prepare_engine_args(): Using NullPool
[2024-06-26T06:56:47.857+0000] {taskinstance.py:1042} DEBUG - previous_execution_date was called
[2024-06-26T06:56:47.935+0000] {taskinstance.py:2648} INFO - Exporting env vars: AIRFLOW_CTX_DAG_OWNER='***' AIRFLOW_CTX_DAG_ID='selenium_minio' AIRFLOW_CTX_TASK_ID='run_selenium_task' AIRFLOW_CTX_EXECUTION_DATE='2024-06-26T06:56:44.207597+00:00' AIRFLOW_CTX_TRY_NUMBER='1' AIRFLOW_CTX_DAG_RUN_ID='manual__2024-06-26T06:56:44.207597+00:00'
[2024-06-26T06:56:47.937+0000] {taskinstance.py:430} INFO - ::endgroup::
[2024-06-26T06:56:52.645+0000] {logging_mixin.py:188} INFO - ok
[2024-06-26T06:57:00.212+0000] {fun_page.py:109} INFO - getting another set
[2024-06-26T06:57:04.489+0000] {fun_page.py:109} INFO - getting another set
[2024-06-26T06:57:07.115+0000] {fun_page.py:109} INFO - getting another set
[2024-06-26T06:57:10.907+0000] {fun_page.py:109} INFO - getting another set
[2024-06-26T06:57:14.981+0000] {fun_page.py:109} INFO - getting another set
[2024-06-26T06:57:18.662+0000] {fun_page.py:109} INFO - getting another set
[2024-06-26T06:57:27.283+0000] {fun_page.py:109} INFO - getting another set
[2024-06-26T06:57:30.561+0000] {fun_page.py:109} INFO - getting another set
[2024-06-26T06:57:33.393+0000] {fun_page.py:109} INFO - getting another set
[2024-06-26T06:57:36.015+0000] {fun_page.py:109} INFO - getting another set
[2024-06-26T06:57:39.758+0000] {fun_page.py:109} INFO - getting another set
[2024-06-26T06:57:44.005+0000] {fun_page.py:109} INFO - getting another set
[2024-06-26T06:57:50.296+0000] {fun_page.py:109} INFO - getting another set
[2024-06-26T06:57:55.106+0000] {fun_page.py:109} INFO - getting another set
[2024-06-26T06:57:58.088+0000] {fun_page.py:109} INFO - getting another set
[2024-06-26T06:58:01.897+0000] {fun_page.py:109} INFO - getting another set
[2024-06-26T06:58:04.432+0000] {fun_page.py:109} INFO - getting another set
[2024-06-26T06:58:08.922+0000] {fun_page.py:109} INFO - getting another set
[2024-06-26T06:58:11.761+0000] {fun_page.py:109} INFO - getting another set
[2024-06-26T06:58:15.719+0000] {fun_page.py:109} INFO - getting another set
[2024-06-26T06:58:18.953+0000] {fun_page.py:109} INFO - getting another set
[2024-06-26T06:58:23.023+0000] {fun_page.py:109} INFO - getting another set
[2024-06-26T06:58:25.614+0000] {fun_page.py:109} INFO - getting another set
[2024-06-26T06:58:30.569+0000] {fun_page.py:109} INFO - getting another set
[2024-06-26T06:58:33.236+0000] {fun_page.py:109} INFO - getting another set
[2024-06-26T06:58:40.146+0000] {fun_page.py:109} INFO - getting another set
[2024-06-26T06:58:43.157+0000] {fun_page.py:109} INFO - getting another set
[2024-06-26T06:58:46.225+0000] {fun_page.py:109} INFO - getting another set
[2024-06-26T06:58:48.630+0000] {fun_page.py:109} INFO - getting another set
[2024-06-26T06:58:52.769+0000] {fun_page.py:109} INFO - getting another set
[2024-06-26T06:58:55.453+0000] {fun_page.py:109} INFO - getting another set
[2024-06-26T06:58:58.764+0000] {fun_page.py:109} INFO - getting another set
[2024-06-26T06:59:02.608+0000] {fun_page.py:109} INFO - getting another set
[2024-06-26T06:59:09.779+0000] {fun_page.py:109} INFO - getting another set
[2024-06-26T06:59:13.957+0000] {fun_page.py:109} INFO - getting another set
[2024-06-26T06:59:20.022+0000] {fun_page.py:109} INFO - getting another set
[2024-06-26T06:59:24.443+0000] {fun_page.py:109} INFO - getting another set
[2024-06-26T06:59:28.884+0000] {fun_page.py:109} INFO - getting another set
[2024-06-26T06:59:34.913+0000] {fun_page.py:109} INFO - getting another set
[2024-06-26T06:59:41.625+0000] {fun_page.py:109} INFO - getting another set
[2024-06-26T06:59:43.924+0000] {fun_page.py:109} INFO - getting another set
[2024-06-26T06:59:59.453+0000] {job.py:218} ERROR - Job heartbeat got an exception
Traceback (most recent call last):
  File "/home/airflow/.local/lib/python3.12/site-packages/sqlalchemy/engine/base.py", line 3371, in _wrap_pool_connect
    return fn()
           ^^^^
  File "/home/airflow/.local/lib/python3.12/site-packages/sqlalchemy/pool/base.py", line 327, in connect
    return _ConnectionFairy._checkout(self)
           ^^^^^^^^^^^^^^^^^^^^^^^^^^^^^^^^
  File "/home/airflow/.local/lib/python3.12/site-packages/sqlalchemy/pool/base.py", line 894, in _checkout
    fairy = _ConnectionRecord.checkout(pool)
            ^^^^^^^^^^^^^^^^^^^^^^^^^^^^^^^^
  File "/home/airflow/.local/lib/python3.12/site-packages/sqlalchemy/pool/base.py", line 493, in checkout
    rec = pool._do_get()
          ^^^^^^^^^^^^^^
  File "/home/airflow/.local/lib/python3.12/site-packages/sqlalchemy/pool/impl.py", line 256, in _do_get
    return self._create_connection()
           ^^^^^^^^^^^^^^^^^^^^^^^^^
  File "/home/airflow/.local/lib/python3.12/site-packages/sqlalchemy/pool/base.py", line 273, in _create_connection
    return _ConnectionRecord(self)
           ^^^^^^^^^^^^^^^^^^^^^^^
  File "/home/airflow/.local/lib/python3.12/site-packages/sqlalchemy/pool/base.py", line 388, in __init__
    self.__connect()
  File "/home/airflow/.local/lib/python3.12/site-packages/sqlalchemy/pool/base.py", line 690, in __connect
    with util.safe_reraise():
  File "/home/airflow/.local/lib/python3.12/site-packages/sqlalchemy/util/langhelpers.py", line 70, in __exit__
    compat.raise_(
  File "/home/airflow/.local/lib/python3.12/site-packages/sqlalchemy/util/compat.py", line 211, in raise_
    raise exception
  File "/home/airflow/.local/lib/python3.12/site-packages/sqlalchemy/pool/base.py", line 686, in __connect
    self.dbapi_connection = connection = pool._invoke_creator(self)
                                         ^^^^^^^^^^^^^^^^^^^^^^^^^^
  File "/home/airflow/.local/lib/python3.12/site-packages/sqlalchemy/engine/create.py", line 574, in connect
    return dialect.connect(*cargs, **cparams)
           ^^^^^^^^^^^^^^^^^^^^^^^^^^^^^^^^^^
  File "/home/airflow/.local/lib/python3.12/site-packages/sqlalchemy/engine/default.py", line 598, in connect
    return self.dbapi.connect(*cargs, **cparams)
           ^^^^^^^^^^^^^^^^^^^^^^^^^^^^^^^^^^^^^
  File "/home/airflow/.local/lib/python3.12/site-packages/psycopg2/__init__.py", line 122, in connect
    conn = _connect(dsn, connection_factory=connection_factory, **kwasync)
           ^^^^^^^^^^^^^^^^^^^^^^^^^^^^^^^^^^^^^^^^^^^^^^^^^^^^^^^^^^^^^^^
psycopg2.OperationalError: could not translate host name "postgres" to address: Temporary failure in name resolution


The above exception was the direct cause of the following exception:

Traceback (most recent call last):
  File "/home/airflow/.local/lib/python3.12/site-packages/airflow/jobs/job.py", line 213, in heartbeat
    heartbeat_callback(session)
  File "/home/airflow/.local/lib/python3.12/site-packages/airflow/utils/session.py", line 76, in wrapper
    return func(*args, **kwargs)
           ^^^^^^^^^^^^^^^^^^^^^
  File "/home/airflow/.local/lib/python3.12/site-packages/airflow/jobs/local_task_job_runner.py", line 258, in heartbeat_callback
    self.task_instance.refresh_from_db()
  File "/home/airflow/.local/lib/python3.12/site-packages/airflow/utils/session.py", line 79, in wrapper
    return func(*args, session=session, **kwargs)
           ^^^^^^^^^^^^^^^^^^^^^^^^^^^^^^^^^^^^^^
  File "/home/airflow/.local/lib/python3.12/site-packages/airflow/models/taskinstance.py", line 1821, in refresh_from_db
    _refresh_from_db(task_instance=self, session=session, lock_for_update=lock_for_update)
  File "/home/airflow/.local/lib/python3.12/site-packages/airflow/models/taskinstance.py", line 510, in _refresh_from_db
    ti = TaskInstance.get_task_instance(
         ^^^^^^^^^^^^^^^^^^^^^^^^^^^^^^^
  File "/home/airflow/.local/lib/python3.12/site-packages/airflow/api_internal/internal_api_call.py", line 115, in wrapper
    return func(*args, **kwargs)
           ^^^^^^^^^^^^^^^^^^^^^
  File "/home/airflow/.local/lib/python3.12/site-packages/airflow/utils/session.py", line 76, in wrapper
    return func(*args, **kwargs)
           ^^^^^^^^^^^^^^^^^^^^^
  File "/home/airflow/.local/lib/python3.12/site-packages/airflow/models/taskinstance.py", line 1807, in get_task_instance
    return query.one_or_none()
           ^^^^^^^^^^^^^^^^^^^
  File "/home/airflow/.local/lib/python3.12/site-packages/sqlalchemy/orm/query.py", line 2850, in one_or_none
    return self._iter().one_or_none()
           ^^^^^^^^^^^^
  File "/home/airflow/.local/lib/python3.12/site-packages/sqlalchemy/orm/query.py", line 2916, in _iter
    result = self.session.execute(
             ^^^^^^^^^^^^^^^^^^^^^
  File "/home/airflow/.local/lib/python3.12/site-packages/sqlalchemy/orm/session.py", line 1716, in execute
    conn = self._connection_for_bind(bind)
           ^^^^^^^^^^^^^^^^^^^^^^^^^^^^^^^
  File "/home/airflow/.local/lib/python3.12/site-packages/sqlalchemy/orm/session.py", line 1555, in _connection_for_bind
    return self._transaction._connection_for_bind(
           ^^^^^^^^^^^^^^^^^^^^^^^^^^^^^^^^^^^^^^^
  File "/home/airflow/.local/lib/python3.12/site-packages/sqlalchemy/orm/session.py", line 750, in _connection_for_bind
    conn = bind.connect()
           ^^^^^^^^^^^^^^
  File "/home/airflow/.local/lib/python3.12/site-packages/sqlalchemy/future/engine.py", line 412, in connect
    return super(Engine, self).connect()
           ^^^^^^^^^^^^^^^^^^^^^^^^^^^^^
  File "/home/airflow/.local/lib/python3.12/site-packages/sqlalchemy/engine/base.py", line 3325, in connect
    return self._connection_cls(self, close_with_result=close_with_result)
           ^^^^^^^^^^^^^^^^^^^^^^^^^^^^^^^^^^^^^^^^^^^^^^^^^^^^^^^^^^^^^^^
  File "/home/airflow/.local/lib/python3.12/site-packages/sqlalchemy/engine/base.py", line 96, in __init__
    else engine.raw_connection()
         ^^^^^^^^^^^^^^^^^^^^^^^
  File "/home/airflow/.local/lib/python3.12/site-packages/sqlalchemy/engine/base.py", line 3404, in raw_connection
    return self._wrap_pool_connect(self.pool.connect, _connection)
           ^^^^^^^^^^^^^^^^^^^^^^^^^^^^^^^^^^^^^^^^^^^^^^^^^^^^^^^
  File "/home/airflow/.local/lib/python3.12/site-packages/sqlalchemy/engine/base.py", line 3374, in _wrap_pool_connect
    Connection._handle_dbapi_exception_noconnection(
  File "/home/airflow/.local/lib/python3.12/site-packages/sqlalchemy/engine/base.py", line 2208, in _handle_dbapi_exception_noconnection
    util.raise_(
  File "/home/airflow/.local/lib/python3.12/site-packages/sqlalchemy/util/compat.py", line 211, in raise_
    raise exception
  File "/home/airflow/.local/lib/python3.12/site-packages/sqlalchemy/engine/base.py", line 3371, in _wrap_pool_connect
    return fn()
           ^^^^
  File "/home/airflow/.local/lib/python3.12/site-packages/sqlalchemy/pool/base.py", line 327, in connect
    return _ConnectionFairy._checkout(self)
           ^^^^^^^^^^^^^^^^^^^^^^^^^^^^^^^^
  File "/home/airflow/.local/lib/python3.12/site-packages/sqlalchemy/pool/base.py", line 894, in _checkout
    fairy = _ConnectionRecord.checkout(pool)
            ^^^^^^^^^^^^^^^^^^^^^^^^^^^^^^^^
  File "/home/airflow/.local/lib/python3.12/site-packages/sqlalchemy/pool/base.py", line 493, in checkout
    rec = pool._do_get()
          ^^^^^^^^^^^^^^
  File "/home/airflow/.local/lib/python3.12/site-packages/sqlalchemy/pool/impl.py", line 256, in _do_get
    return self._create_connection()
           ^^^^^^^^^^^^^^^^^^^^^^^^^
  File "/home/airflow/.local/lib/python3.12/site-packages/sqlalchemy/pool/base.py", line 273, in _create_connection
    return _ConnectionRecord(self)
           ^^^^^^^^^^^^^^^^^^^^^^^
  File "/home/airflow/.local/lib/python3.12/site-packages/sqlalchemy/pool/base.py", line 388, in __init__
    self.__connect()
  File "/home/airflow/.local/lib/python3.12/site-packages/sqlalchemy/pool/base.py", line 690, in __connect
    with util.safe_reraise():
  File "/home/airflow/.local/lib/python3.12/site-packages/sqlalchemy/util/langhelpers.py", line 70, in __exit__
    compat.raise_(
  File "/home/airflow/.local/lib/python3.12/site-packages/sqlalchemy/util/compat.py", line 211, in raise_
    raise exception
  File "/home/airflow/.local/lib/python3.12/site-packages/sqlalchemy/pool/base.py", line 686, in __connect
    self.dbapi_connection = connection = pool._invoke_creator(self)
                                         ^^^^^^^^^^^^^^^^^^^^^^^^^^
  File "/home/airflow/.local/lib/python3.12/site-packages/sqlalchemy/engine/create.py", line 574, in connect
    return dialect.connect(*cargs, **cparams)
           ^^^^^^^^^^^^^^^^^^^^^^^^^^^^^^^^^^
  File "/home/airflow/.local/lib/python3.12/site-packages/sqlalchemy/engine/default.py", line 598, in connect
    return self.dbapi.connect(*cargs, **cparams)
           ^^^^^^^^^^^^^^^^^^^^^^^^^^^^^^^^^^^^^
  File "/home/airflow/.local/lib/python3.12/site-packages/psycopg2/__init__.py", line 122, in connect
    conn = _connect(dsn, connection_factory=connection_factory, **kwasync)
           ^^^^^^^^^^^^^^^^^^^^^^^^^^^^^^^^^^^^^^^^^^^^^^^^^^^^^^^^^^^^^^^
sqlalchemy.exc.OperationalError: (psycopg2.OperationalError) could not translate host name "postgres" to address: Temporary failure in name resolution

(Background on this error at: https://sqlalche.me/e/14/e3q8)
[2024-06-26T07:00:02.153+0000] {job.py:226} ERROR - Job heartbeat failed with error. Scheduler is in unhealthy state
[2024-06-26T07:00:27.946+0000] {fun_page.py:109} INFO - getting another set
[2024-06-26T07:00:36.416+0000] {fun_page.py:109} INFO - getting another set
[2024-06-26T07:00:39.559+0000] {fun_page.py:109} INFO - getting another set
[2024-06-26T07:00:50.438+0000] {fun_page.py:109} INFO - getting another set
[2024-06-26T07:00:53.582+0000] {fun_page.py:109} INFO - getting another set
[2024-06-26T07:00:57.036+0000] {fun_page.py:109} INFO - getting another set
[2024-06-26T07:01:00.188+0000] {fun_page.py:109} INFO - getting another set
[2024-06-26T07:01:04.347+0000] {fun_page.py:109} INFO - getting another set
[2024-06-26T07:01:44.329+0000] {job.py:226} ERROR - Job heartbeat failed with error. Scheduler is in unhealthy state
[2024-06-26T07:01:49.516+0000] {crawl_minio.py:48} ERROR - Error running Selenium job: Unterminated string starting at: line 4924 column 30 (char 262054)
[2024-06-26T07:01:49.732+0000] {taskinstance.py:441} INFO - ::group::Post task execution logs
[2024-06-26T07:01:49.735+0000] {taskinstance.py:2905} ERROR - Task failed with exception
Traceback (most recent call last):
  File "/home/airflow/.local/lib/python3.12/site-packages/airflow/models/taskinstance.py", line 465, in _execute_task
    result = _execute_callable(context=context, **execute_callable_kwargs)
             ^^^^^^^^^^^^^^^^^^^^^^^^^^^^^^^^^^^^^^^^^^^^^^^^^^^^^^^^^^^^^
  File "/home/airflow/.local/lib/python3.12/site-packages/airflow/models/taskinstance.py", line 432, in _execute_callable
    return execute_callable(context=context, **execute_callable_kwargs)
           ^^^^^^^^^^^^^^^^^^^^^^^^^^^^^^^^^^^^^^^^^^^^^^^^^^^^^^^^^^^^
  File "/home/airflow/.local/lib/python3.12/site-packages/airflow/models/baseoperator.py", line 401, in wrapper
    return func(self, *args, **kwargs)
           ^^^^^^^^^^^^^^^^^^^^^^^^^^^
  File "/home/airflow/.local/lib/python3.12/site-packages/airflow/operators/python.py", line 235, in execute
    return_value = self.execute_callable()
                   ^^^^^^^^^^^^^^^^^^^^^^^
  File "/home/airflow/.local/lib/python3.12/site-packages/airflow/operators/python.py", line 252, in execute_callable
    return self.python_callable(*self.op_args, **self.op_kwargs)
           ^^^^^^^^^^^^^^^^^^^^^^^^^^^^^^^^^^^^^^^^^^^^^^^^^^^^^
  File "/opt/airflow/dags/crawl_minio.py", line 40, in run_selenium_job
    result = functions_instance.get_all_data(driver, page_id, access_token)
             ^^^^^^^^^^^^^^^^^^^^^^^^^^^^^^^^^^^^^^^^^^^^^^^^^^^^^^^^^^^^^^
  File "/opt/airflow/dags/fun/fun_page.py", line 246, in get_all_data
    posts_dict = self.get_posts(driver, user_id, access_token)
                 ^^^^^^^^^^^^^^^^^^^^^^^^^^^^^^^^^^^^^^^^^^^^^
  File "/opt/airflow/dags/fun/fun_page.py", line 96, in get_posts
    json_dict = json.loads(element.text)
                ^^^^^^^^^^^^^^^^^^^^^^^^
  File "/usr/local/lib/python3.12/json/__init__.py", line 346, in loads
    return _default_decoder.decode(s)
           ^^^^^^^^^^^^^^^^^^^^^^^^^^
  File "/usr/local/lib/python3.12/json/decoder.py", line 337, in decode
    obj, end = self.raw_decode(s, idx=_w(s, 0).end())
               ^^^^^^^^^^^^^^^^^^^^^^^^^^^^^^^^^^^^^^
  File "/usr/local/lib/python3.12/json/decoder.py", line 353, in raw_decode
    obj, end = self.scan_once(s, idx)
               ^^^^^^^^^^^^^^^^^^^^^^
json.decoder.JSONDecodeError: Unterminated string starting at: line 4924 column 30 (char 262054)
[2024-06-26T07:01:50.161+0000] {taskinstance.py:562} DEBUG - Task Duration set to 302.500131
[2024-06-26T07:01:50.164+0000] {taskinstance.py:584} DEBUG - Clearing next_method and next_kwargs.
[2024-06-26T07:01:50.165+0000] {taskinstance.py:1206} INFO - Marking task as FAILED. dag_id=selenium_minio, task_id=run_selenium_task, run_id=manual__2024-06-26T06:56:44.207597+00:00, execution_date=20240626T065644, start_date=20240626T065647, end_date=20240626T070150
[2024-06-26T07:01:50.217+0000] {standard_task_runner.py:110} ERROR - Failed to execute job 518 for task run_selenium_task (Unterminated string starting at: line 4924 column 30 (char 262054); 817)
[2024-06-26T07:01:50.305+0000] {local_task_job_runner.py:240} INFO - Task exited with return code 1
[2024-06-26T07:01:50.504+0000] {taskinstance.py:3503} INFO - 0 downstream tasks scheduled from follow-on schedule check
[2024-06-26T07:01:50.526+0000] {local_task_job_runner.py:222} INFO - ::endgroup::
