[2024-06-27T01:56:51.115+0000] {taskinstance.py:1042} DEBUG - previous_execution_date was called
[2024-06-27T01:56:51.155+0000] {taskinstance.py:1042} DEBUG - previous_execution_date was called
[2024-06-27T01:56:51.174+0000] {local_task_job_runner.py:120} INFO - ::group::Pre task execution logs
[2024-06-27T01:56:51.226+0000] {taskinstance.py:2076} INFO - Dependencies all met for dep_context=non-requeueable deps ti=<TaskInstance: test_user1.get_urls_task manual__2024-06-27T01:56:49.183591+00:00 [queued]>
[2024-06-27T01:56:51.246+0000] {taskinstance.py:2076} INFO - Dependencies all met for dep_context=requeueable deps ti=<TaskInstance: test_user1.get_urls_task manual__2024-06-27T01:56:49.183591+00:00 [queued]>
[2024-06-27T01:56:51.247+0000] {taskinstance.py:2306} INFO - Starting attempt 1 of 1
[2024-06-27T01:56:51.276+0000] {taskinstance.py:2330} INFO - Executing <Task(PythonOperator): get_urls_task> on 2024-06-27 01:56:49.183591+00:00
[2024-06-27T01:56:51.285+0000] {warnings.py:112} WARNING - /home/***/.local/lib/python3.12/site-packages/***/task/task_runner/standard_task_runner.py:61: DeprecationWarning: This process (pid=424) is multi-threaded, use of fork() may lead to deadlocks in the child.
  pid = os.fork()

[2024-06-27T01:56:51.287+0000] {standard_task_runner.py:63} INFO - Started process 426 to run task
[2024-06-27T01:56:51.287+0000] {standard_task_runner.py:90} INFO - Running: ['***', 'tasks', 'run', 'test_user1', 'get_urls_task', 'manual__2024-06-27T01:56:49.183591+00:00', '--job-id', '557', '--raw', '--subdir', 'DAGS_FOLDER/first_out.py', '--cfg-path', '/tmp/tmp6dh2jjdi']
[2024-06-27T01:56:51.292+0000] {standard_task_runner.py:91} INFO - Job 557: Subtask get_urls_task
[2024-06-27T01:56:51.359+0000] {taskinstance.py:1042} DEBUG - previous_execution_date was called
[2024-06-27T01:56:51.367+0000] {task_command.py:426} INFO - Running <TaskInstance: test_user1.get_urls_task manual__2024-06-27T01:56:49.183591+00:00 [running]> on host ccfa35e0da07
[2024-06-27T01:56:51.368+0000] {settings.py:363} DEBUG - Disposing DB connection pool (PID 426)
[2024-06-27T01:56:51.370+0000] {settings.py:250} DEBUG - Setting up DB connection pool (PID 426)
[2024-06-27T01:56:51.370+0000] {settings.py:298} DEBUG - settings.prepare_engine_args(): Using NullPool
[2024-06-27T01:56:51.429+0000] {taskinstance.py:1042} DEBUG - previous_execution_date was called
[2024-06-27T01:56:51.540+0000] {taskinstance.py:2648} INFO - Exporting env vars: AIRFLOW_CTX_DAG_OWNER='***' AIRFLOW_CTX_DAG_ID='test_user1' AIRFLOW_CTX_TASK_ID='get_urls_task' AIRFLOW_CTX_EXECUTION_DATE='2024-06-27T01:56:49.183591+00:00' AIRFLOW_CTX_TRY_NUMBER='1' AIRFLOW_CTX_DAG_RUN_ID='manual__2024-06-27T01:56:49.183591+00:00'
[2024-06-27T01:56:51.542+0000] {taskinstance.py:430} INFO - ::endgroup::
[2024-06-27T01:57:02.641+0000] {fun_user.py:87} INFO - Found id: 100015161496348
[2024-06-27T01:57:04.710+0000] {taskinstance.py:441} INFO - ::group::Post task execution logs
[2024-06-27T01:57:04.711+0000] {taskinstance.py:2905} ERROR - Task failed with exception
Traceback (most recent call last):
  File "/home/airflow/.local/lib/python3.12/site-packages/airflow/models/taskinstance.py", line 465, in _execute_task
    result = _execute_callable(context=context, **execute_callable_kwargs)
             ^^^^^^^^^^^^^^^^^^^^^^^^^^^^^^^^^^^^^^^^^^^^^^^^^^^^^^^^^^^^^
  File "/home/airflow/.local/lib/python3.12/site-packages/airflow/models/taskinstance.py", line 432, in _execute_callable
    return execute_callable(context=context, **execute_callable_kwargs)
           ^^^^^^^^^^^^^^^^^^^^^^^^^^^^^^^^^^^^^^^^^^^^^^^^^^^^^^^^^^^^
  File "/home/airflow/.local/lib/python3.12/site-packages/airflow/models/baseoperator.py", line 401, in wrapper
    return func(self, *args, **kwargs)
           ^^^^^^^^^^^^^^^^^^^^^^^^^^^
  File "/home/airflow/.local/lib/python3.12/site-packages/airflow/operators/python.py", line 235, in execute
    return_value = self.execute_callable()
                   ^^^^^^^^^^^^^^^^^^^^^^^
  File "/home/airflow/.local/lib/python3.12/site-packages/airflow/operators/python.py", line 252, in execute_callable
    return self.python_callable(*self.op_args, **self.op_kwargs)
           ^^^^^^^^^^^^^^^^^^^^^^^^^^^^^^^^^^^^^^^^^^^^^^^^^^^^^
  File "/opt/airflow/dags/first_out.py", line 31, in run_selenium_job
    result = functions_instance.get_all_data(page_id, access_token)
             ^^^^^^^^^^^^^^^^^^^^^^^^^^^^^^^^^^^^^^^^^^^^^^^^^^^^^^
  File "/opt/airflow/dags/fun/fun_user.py", line 255, in get_all_data
    result['fb_friends'] = self.get_friends(user_id, access_token)
                           ^^^^^^^^^^^^^^^^^^^^^^^^^^^^^^^^^^^^^^^
  File "/opt/airflow/dags/fun/fun_user.py", line 100, in get_friends
    next_url, friends = self.data_handling_friends(data)
                        ^^^^^^^^^^^^^^^^^^^^^^^^^^^^^^^^
  File "/opt/airflow/dags/fun/fun_user.py", line 115, in data_handling_friends
    next_page = friends.get('paging', {})
                ^^^^^^^^^^^
AttributeError: 'list' object has no attribute 'get'
[2024-06-27T01:57:04.732+0000] {taskinstance.py:562} DEBUG - Task Duration set to 13.504879
[2024-06-27T01:57:04.734+0000] {taskinstance.py:584} DEBUG - Clearing next_method and next_kwargs.
[2024-06-27T01:57:04.735+0000] {taskinstance.py:1206} INFO - Marking task as FAILED. dag_id=test_user1, task_id=get_urls_task, run_id=manual__2024-06-27T01:56:49.183591+00:00, execution_date=20240627T015649, start_date=20240627T015651, end_date=20240627T015704
[2024-06-27T01:57:04.751+0000] {standard_task_runner.py:110} ERROR - Failed to execute job 557 for task get_urls_task ('list' object has no attribute 'get'; 426)
[2024-06-27T01:57:04.760+0000] {local_task_job_runner.py:240} INFO - Task exited with return code 1
[2024-06-27T01:57:04.777+0000] {taskinstance.py:3503} INFO - 0 downstream tasks scheduled from follow-on schedule check
[2024-06-27T01:57:04.780+0000] {local_task_job_runner.py:222} INFO - ::endgroup::
